Workbook
Name Dist_Qtd_LB: Main_variables!$D$397:$F$398
Name Distributors_Actual_Min_Stock: Distributors_stock_balance!$D$277:$F$278
Name Distributors_Actual_RunOutTime: Distributors_stock_balance!$D$283:$F$284
Name Distributors_Backlog: Distributors_stock_balance!$D$253:$F$254
Name Distributors_Cap_StdDev: Distributors_Cap!$F$9:$H$10
Name Distributors_Capacity_Coefficient: Distributors_stock_balance!$D$265:$F$266
Name Distributors_Coverage_Time: Distributors_stock_balance!$D$28:$F$29
Name Distributors_Delta: Distributors_stock_balance!$D$34:$F$35
Name Distributors_Gamma: Distributors_stock_balance!$D$45:$F$46
Name Distributors_Gross_Base_Stock: Distributors_stock_balance!$D$211:$F$212
Name Distributors_Max_NumberofCycles: Distributors_stock_balance!$D$289:$F$290
Name Distributors_Net_Demand: Distributors_stock_balance!$D$199:$F$200
Name Distributors_Omega: Distributors_stock_balance!$D$57:$F$58
Name Distributors_Omega1: Distributors_stock_balance!$D$110:$F$111
Name Distributors_Omega2: Distributors_stock_balance!$D$116:$F$117
Name Distributors_Omega3: Distributors_stock_balance!$D$122:$F$123
Name Distributors_Omega4: Distributors_stock_balance!$D$140:$F$141
Name Distributors_Omega5: Distributors_stock_balance!$D$146:$F$147
Name Distributors_Omega6: Distributors_stock_balance!$D$152:$F$153
Name Distributors_Replenishment_Time: Distributors_stock_balance!$D$22:$F$23
Name Distributors_Rho: Distributors_stock_balance!$D$51:$F$52
Name Distributors_Runout_Time: Distributors_stock_balance!$D$63:$F$64
Name Distributors_Safety_Stock: Distributors_stock_balance!$D$229:$F$230
Name Distributors_Squared_root: Distributors_stock_balance!$D$181:$F$182
Name Distributors_Stock_Consumption: Distributors_stock_balance!$D$247:$F$248
Name Distributors_Stock_Recovery: Distributors_stock_balance!$D$259:$F$260
Name Distributors_Variance_NetDemand_Rate: Distributors_stock_balance!$D$217:$F$218
Name Distributors_Zeta: Distributors_stock_balance!$D$39:$F$40
Name DistributorsBegStock: Beginning_stock!$AU$25:$AW$26
Name DistributorsCap: Distributors_Cap!$F$14:$H$15
Name DistributorsCost: Distributors!$I$6:$K$7
Name DistributorsDem: Demand!$AU$19:$AW$20
Name DistributorsLeadTime: Distributors!$I$22:$K$23
Name DistributorsLeadTimeStdDev: Distributors!$I$27:$K$28
Name DistributorsNumberBinaryVarY: Distributors_Cap!$F$61:$H$62
Name DistributorsPlanStock: 'Planned_Beginning_stock '!$AU$25:$AW$26
Name DistributorsStdDev: Distributors!$I$17:$K$18
Name DistributorsStdDevVarVar: Dist_Fourth_central_moment_5var!$D$41:$F$42
Name DistributorsUpperBound: Distributors_Cap!$F$50:$H$51
Name Fac_Qtd_LB: Main_variables!$D$248:$F$250
Name Factories_Actual_Min_Stock: Factories_stock_balance!$D$277:$F$279
Name Factories_Actual_RunOutTime: Factories_stock_balance!$D$283:$F$285
Name Factories_Backlog: Factories_stock_balance!$D$253:$F$255
Name Factories_Cap_StdDev: Factories_Cap!$F$9:$H$11
Name Factories_Capacity_Coefficient: Factories_stock_balance!$D$265:$F$267
Name Factories_Coverage_Time: Factories_stock_balance!$D$28:$F$30
Name Factories_Delta: Factories_stock_balance!$D$34:$F$36
Name Factories_Gamma: Factories_stock_balance!$D$45:$F$47
Name Factories_Gross_Base_Stock: Factories_stock_balance!$D$211:$F$213
Name Factories_Max_NumberofCycles: Factories_stock_balance!$D$289:$F$291
Name Factories_Net_Demand: Factories_stock_balance!$D$199:$F$201
Name Factories_Omega: Factories_stock_balance!$D$57:$F$59
Name Factories_Omega1: Factories_stock_balance!$D$110:$F$112
Name Factories_Omega2: Factories_stock_balance!$D$116:$F$118
Name Factories_Omega3: Factories_stock_balance!$D$122:$F$124
Name Factories_Omega4: Factories_stock_balance!$D$140:$F$142
Name Factories_Omega5: Factories_stock_balance!$D$146:$F$148
Name Factories_Omega6: Factories_stock_balance!$D$152:$F$154
Name Factories_Replenishment_Time: Factories_stock_balance!$D$22:$F$24
Name Factories_Rho: Factories_stock_balance!$D$51:$F$53

Sheet Planilha mãe
A1: Planilha mãe | B1: SUPPLIERS | V1: =SUM(V13:V160)
B2: Objective | C2: P(Reorder) | D2: 1 | E2: 2 | F2: 3 | G2: 4 | H2: 5 | I2: 6 | J2: 7 | K2: 8 | L2: 9 | M2: 10 | N2: 11 | O2: 12 | P2: 13 | Q2: 14 | R2: 15 | S2: Objective
B3: =Optimal_solutionw | C3: 1 | S3: 5778156.3
C4: 2 | S4: DIFERENÇA
C5: 3 | S5: =B3-S3
C7: P(Estado da arte) | D7: 1 | E7: 2 | F7: 3 | G7: 4 | H7: 5 | I7: 6 | J7: 7 | K7: 8 | L7: 9 | M7: 10 | N7: 11 | O7: 12 | P7: 13 | Q7: 14 | R7: 15
C8: 1
C9: 2
C10: 3
C12: Reorder | D12: 1 | E12: 2 | F12: 3 | G12: 4 | H12: 5 | I12: 6 | J12: 7 | K12: 8 | L12: 9 | M12: 10 | N12: 11 | O12: 12 | P12: 13 | Q12: 14 | R12: 15
C13: 1 | D13: =Suppliers_stock_balance!D212 | E13: =Suppliers_stock_balance!E212 | F13: =Suppliers_stock_balance!F212 | G13: =Suppliers_stock_balance!G212 | H13: =Suppliers_stock_balance!H212 | I13: =Suppliers_stock_balance!I212 | J13: =Suppliers_stock_balance!J212 | K13: =Suppliers_stock_balance!K212 | ... R13: =Suppliers_stock_balance!R212 | T13: =IF(R12=15,SUM(D13:R15),"") | U13: 39562.042 | V13: =IF(T13="","",T13-U13)
C14: 2 | D14: =Suppliers_stock_balance!D213 | E14: =Suppliers_stock_balance!E213 | F14: =Suppliers_stock_balance!F213 | G14: =Suppliers_stock_balance!G213 | H14: =Suppliers_stock_balance!H213 | I14: =Suppliers_stock_balance!I213 | J14: =Suppliers_stock_balance!J213 | K14: =Suppliers_stock_balance!K213 | ... R14: =Suppliers_stock_balance!R213 | T14: =IF(R13=15,SUM(D14:R16),"") | V14: =IF(T14="","",T14-U14)
C15: 3 | D15: =Suppliers_stock_balance!D214 | E15: =Suppliers_stock_balance!E214 | F15: =Suppliers_stock_balance!F214 | G15: =Suppliers_stock_balance!G214 | H15: =Suppliers_stock_balance!H214 | I15: =Suppliers_stock_balance!I214 | J15: =Suppliers_stock_balance!J214 | K15: =Suppliers_stock_balance!K214 | ... R15: =Suppliers_stock_balance!R214 | T15: =IF(R14=15,SUM(D15:R17),"") | V15: =IF(T15="","",T15-U15)
T16: =IF(R15=15,SUM(D16:R18),"") | V16: =IF(T16="","",T16-U16)
C17: Var(Var(d)) | D17: 1 | E17: 2 | F17: 3 | G17: 4 | H17: 5 | I17: 6 | J17: 7 | K17: 8 | L17: 9 | M17: 10 | N17: 11 | O17: 12 | P17: 13 | Q17: 14 | R17: 15 | T17: =IF(R16=15,SUM(D17:R19),"") | V17: =IF(T17="","",T17-U17)
C18: 1 | D18: =Supp_Fourth_central_moment_5var!D18 | E18: =Supp_Fourth_central_moment_5var!E18 | F18: =Supp_Fourth_central_moment_5var!F18 | G18: =Supp_Fourth_central_moment_5var!G18 | H18: =Supp_Fourth_central_moment_5var!H18 | I18: =Supp_Fourth_central_moment_5var!I18 | J18: =Supp_Fourth_central_moment_5var!J18 | K18: =Supp_Fourth_central_moment_5var!K18 | ... R18: =Supp_Fourth_central_moment_5var!R18 | T18: =IF(R17=15,SUM(D18:R20),"") | U18: 8.9810564e+08 | V18: =IF(T18="","",T18-U18)
C19: 2 | D19: =Supp_Fourth_central_moment_5var!D19 | E19: =Supp_Fourth_central_moment_5var!E19 | F19: =Supp_Fourth_central_moment_5var!F19 | G19: =Supp_Fourth_central_moment_5var!G19 | H19: =Supp_Fourth_central_moment_5var!H19 | I19: =Supp_Fourth_central_moment_5var!I19 | J19: =Supp_Fourth_central_moment_5var!J19 | K19: =Supp_Fourth_central_moment_5var!K19 | ... R19: =Supp_Fourth_central_moment_5var!R19 | T19: =IF(R18=15,SUM(D19:R21),"") | V19: =IF(T19="","",T19-U19)
C20: 3 | D20: =Supp_Fourth_central_moment_5var!D20 | E20: =Supp_Fourth_central_moment_5var!E20 | F20: =Supp_Fourth_central_moment_5var!F20 | G20: =Supp_Fourth_central_moment_5var!G20 | H20: =Supp_Fourth_central_moment_5var!H20 | I20: =Supp_Fourth_central_moment_5var!I20 | J20: =Supp_Fourth_central_moment_5var!J20 | K20: =Supp_Fourth_central_moment_5var!K20 | ... R20: =Supp_Fourth_central_moment_5var!R20 | T20: =IF(R19=15,SUM(D20:R22),"") | V20: =IF(T20="","",T20-U20)
T21: =IF(R20=15,SUM(D21:R23),"") | V21: =IF(T21="","",T21-U21)
C22: Var(Var(Cap)) | D22: 1 | E22: 2 | F22: 3 | G22: 4 | H22: 5 | I22: 6 | J22: 7 | K22: 8 | L22: 9 | M22: 10 | N22: 11 | O22: 12 | P22: 13 | Q22: 14 | R22: 15 | T22: =IF(R21=15,SUM(D22:R24),"") | V22: =IF(T22="","",T22-U22)
C23: 1 | D23: =Supp_Fourth_central_moment_5var!D24 | E23: =Supp_Fourth_central_moment_5var!E24 | F23: =Supp_Fourth_central_moment_5var!F24 | G23: =Supp_Fourth_central_moment_5var!G24 | H23: =Supp_Fourth_central_moment_5var!H24 | I23: =Supp_Fourth_central_moment_5var!I24 | J23: =Supp_Fourth_central_moment_5var!J24 | K23: =Supp_Fourth_central_moment_5var!K24 | ... R23: =Supp_Fourth_central_moment_5var!R24 | T23: =IF(R22=15,SUM(D23:R25),"") | U23: 7.4152942e+08 | V23: =IF(T23="","",T23-U23)
C24: 2 | D24: =Supp_Fourth_central_moment_5var!D25 | E24: =Supp_Fourth_central_moment_5var!E25 | F24: =Supp_Fourth_central_moment_5var!F25 | G24: =Supp_Fourth_central_moment_5var!G25 | H24: =Supp_Fourth_central_moment_5var!H25 | I24: =Supp_Fourth_central_moment_5var!I25 | J24: =Supp_Fourth_central_moment_5var!J25 | K24: =Supp_Fourth_central_moment_5var!K25 | ... R24: =Supp_Fourth_central_moment_5var!R25 | T24: =IF(R23=15,SUM(D24:R26),"") | V24: =IF(T24="","",T24-U24)
C25: 3 | D25: =Supp_Fourth_central_moment_5var!D26 | E25: =Supp_Fourth_central_moment_5var!E26 | F25: =Supp_Fourth_central_moment_5var!F26 | G25: =Supp_Fourth_central_moment_5var!G26 | H25: =Supp_Fourth_central_moment_5var!H26 | I25: =Supp_Fourth_central_moment_5var!I26 | J25: =Supp_Fourth_central_moment_5var!J26 | K25: =Supp_Fourth_central_moment_5var!K26 | ... R25: =Supp_Fourth_central_moment_5var!R26 | T25: =IF(R24=15,SUM(D25:R27),"") | V25: =IF(T25="","",T25-U25)
T26: =IF(R25=15,SUM(D26:R28),"") | V26: =IF(T26="","",T26-U26)
B27: =Data!D27 | C27: CV | D27: 1 | E27: 2 | F27: 3 | G27: 4 | H27: 5 | I27: 6 | J27: 7 | K27: 8 | L27: 9 | M27: 10 | N27: 11 | O27: 12 | P27: 13 | Q27: 14 | R27: 15 | T27: =IF(R26=15,SUM(D27:R29),"") | V27: =IF(T27="","",T27-U27)
C28: 1 | D28: =$B$27 | E28: =$B$27 | F28: =$B$27 | G28: =$B$27 | H28: =$B$27 | I28: =$B$27 | J28: =$B$27 | K28: =$B$27 | ... R28: =$B$27 | T28: =IF(R27=15,SUM(D28:R30),"") | U28: 9 | V28: =IF(T28="","",T28-U28)
C29: 2 | D29: =$B$27 | E29: =$B$27 | F29: =$B$27 | G29: =$B$27 | H29: =$B$27 | I29: =$B$27 | J29: =$B$27 | K29: =$B$27 | ... R29: =$B$27 | T29: =IF(R28=15,SUM(D29:R31),"") | V29: =IF(T29="","",T29-U29)
C30: 3 | D30: =$B$27 | E30: =$B$27 | F30: =$B$27 | G30: =$B$27 | H30: =$B$27 | I30: =$B$27 | J30: =$B$27 | K30: =$B$27 | ... R30: =$B$27 | T30: =IF(R29=15,SUM(D30:R32),"") | V30: =IF(T30="","",T30-U30)
T31: =IF(R30=15,SUM(D31:R33),"") | V31: =IF(T31="","",T31-U31)
B32: =Data!D31 | C32: Planned Stock | D32: 1 | E32: 2 | F32: 3 | G32: 4 | H32: 5 | I32: 6 | J32: 7 | K32: 8 | L32: 9 | M32: 10 | N32: 11 | O32: 12 | P32: 13 | Q32: 14 | R32: 15 | T32: =IF(R31=15,SUM(D32:R34),"") | V32: =IF(T32="","",T32-U32)
C33: 1 | D33: =$B$32 | E33: =$B$32 | F33: =$B$32 | G33: =$B$32 | H33: =$B$32 | I33: =$B$32 | J33: =$B$32 | K33: =$B$32 | ... R33: =$B$32 | T33: =IF(R32=15,SUM(D33:R35),"") | U33: 45 | V33: =IF(T33="","",T33-U33)
C34: 2 | D34: =$B$32 | E34: =$B$32 | F34: =$B$32 | G34: =$B$32 | H34: =$B$32 | I34: =$B$32 | J34: =$B$32 | K34: =$B$32 | ... R34: =$B$32 | T34: =IF(R33=15,SUM(D34:R36),"") | V34: =IF(T34="","",T34-U34)
C35: 3 | D35: =$B$32 | E35: =$B$32 | F35: =$B$32 | G35: =$B$32 | H35: =$B$32 | I35: =$B$32 | J35: =$B$32 | K35: =$B$32 | ... R35: =$B$32 | T35: =IF(R34=15,SUM(D35:R37),"") | V35: =IF(T35="","",T35-U35)
T36: =IF(R35=15,SUM(D36:R38),"") | V36: =IF(T36="","",T36-U36)
B37: =Data!D34 | C37: Variance coeff - z(S2nd) | D37: 1 | E37: 2 | F37: 3 | G37: 4 | H37: 5 | I37: 6 | J37: 7 | K37: 8 | L37: 9 | M37: 10 | N37: 11 | O37: 12 | P37: 13 | Q37: 14 | R37: 15 | T37: =IF(R36=15,SUM(D37:R39),"") | V37: =IF(T37="","",T37-U37)
C38: 1 | D38: =$B$37 | E38: =$B$37 | F38: =$B$37 | G38: =$B$37 | H38: =$B$37 | I38: =$B$37 | J38: =$B$37 | K38: =$B$37 | ... R38: =$B$37 | T38: =IF(R37=15,SUM(D38:R40),"") | U38: 76.758196 | V38: =IF(T38="","",T38-U38)
C39: 2 | D39: =$B$37 | E39: =$B$37 | F39: =$B$37 | G39: =$B$37 | H39: =$B$37 | I39: =$B$37 | J39: =$B$37 | K39: =$B$37 | ... R39: =$B$37 | T39: =IF(R38=15,SUM(D39:R41),"") | V39: =IF(T39="","",T39-U39)
C40: 3 | D40: =$B$37 | E40: =$B$37 | F40: =$B$37 | G40: =$B$37 | H40: =$B$37 | I40: =$B$37 | J40: =$B$37 | K40: =$B$37 | ... R40: =$B$37 | T40: =IF(R39=15,SUM(D40:R42),"") | V40: =IF(T40="","",T40-U40)
T41: =IF(R40=15,SUM(D41:R43),"") | V41: =IF(T41="","",T41-U41)
B42: Parâmetros p/ μx | C42: demand | D42: 1 | E42: 2 | F42: 3 | G42: 4 | H42: 5 | I42: 6 | J42: 7 | K42: 8 | L42: 9 | M42: 10 | N42: 11 | O42: 12 | P42: 13 | Q42: 14 | R42: 15 | T42: =IF(R41=15,SUM(D42:R44),"") | V42: =IF(T42="","",T42-U42)
...

Sheet Main_variables
A1: Planilha filha | B1: SUPPLIERS | V1: TOTAL | W1: 1 | X1: SUPPLIERS | AR1: TOTAL | AS1: 2 | AT1: SUPPLIERS | BN1: TOTAL | BO1: 3 | BP1: SUPPLIERS | CJ1: TOTAL | CK1: 4 | CL1: SUPPLIERS | DF1: TOTAL | DG1: 5 | DH1: SUPPLIERS | EB1: TOTAL | EC1: 6 | ED1: SUPPLIERS | EX1: TOTAL | EY1: 7 | EZ1: SUPPLIERS | FT1: TOTAL | FU1: 8 | FV1: SUPPLIERS | GP1: TOTAL | GQ1: 9 | GR1: SUPPLIERS
B2: Objective | C2: P(Reorder) | D2: 1 | E2: 2 | F2: 3 | G2: 4 | H2: 5 | I2: 6 | J2: 7 | K2: 8 | L2: 9 | M2: 10 | N2: 11 | O2: 12 | P2: 13 | Q2: 14 | R2: 15 | V2: =X3+X168 | X2: Objective | Y2: P(Reorder) | Z2: 1 | AA2: 2 | AB2: 3 | AC2: 4 | AD2: 5 | AE2: 6 | AF2: 7 | AG2: 8 | AH2: 9 | AI2: 10 | AJ2: 11 | AK2: 12 | AL2: 13 | AM2: 14 | AN2: 15 | AR2: =AT3+AT168 | AT2: Objective | AU2: P(Reorder) | AV2: 1 | AW2: 2 | AX2: 3 | AY2: 4 | AZ2: 5 | BA2: 6 | BB2: 7 | BC2: 8 | BD2: 9 | BE2: 10 | BF2: 11 | BG2: 12 | BH2: 13 | BI2: 14 | BJ2: 15 | BN2: =BP3+BP168 | BP2: Objective | BQ2: P(Reorder) | BR2: 1 | BS2: 2 | BT2: 3 | BU2: 4 | BV2: 5 | BW2: 6 | BX2: 7 | BY2: 8 | BZ2: 9 | CA2: 10 | CB2: 11 | CC2: 12 | CD2: 13 | CE2: 14 | CF2: 15 | CJ2: =CL3+CL168 | CL2: Objective | CM2: P(Reorder) | CN2: 1 | CO2: 2 | CP2: 3 | CQ2: 4 | CR2: 5 | CS2: 6 | CT2: 7 | CU2: 8 | CV2: 9 | CW2: 10 | CX2: 11 | CY2: 12 | CZ2: 13 | DA2: 14 | DB2: 15 | DF2: =DH3+DH168 | DH2: Objective | DI2: P(Reorder) | DJ2: 1 | DK2: 2 | DL2: 3 | DM2: 4 | DN2: 5 | DO2: 6 | DP2: 7 | DQ2: 8 | DR2: 9 | DS2: 10 | DT2: 11 | DU2: 12 | DV2: 13 | DW2: 14 | DX2: 15 | EB2: =ED3+ED168 | ED2: Objective | EE2: P(Reorder) | EF2: 1 | EG2: 2 | EH2: 3 | EI2: 4 | EJ2: 5 | EK2: 6 | EL2: 7 | EM2: 8 | EN2: 9 | EO2: 10 | EP2: 11 | EQ2: 12 | ER2: 13 | ES2: 14 | ET2: 15 | EX2: =EZ3+EZ168 | EZ2: Objective | FA2: P(Reorder) | FB2: 1 | FC2: 2 | FD2: 3 | FE2: 4 | FF2: 5 | FG2: 6 | FH2: 7 | FI2: 8 | FJ2: 9 | FK2: 10 | FL2: 11 | FM2: 12 | FN2: 13 | FO2: 14 | FP2: 15 | FT2: =FV3+FV168 | FV2: Objective | FW2: P(Reorder) | FX2: 1 | FY2: 2 | FZ2: 3 | GA2: 4 | GB2: 5 | GC2: 6 | GD2: 7 | GE2: 8 | GF2: 9 | GG2: 10 | GH2: 11 | GI2: 12 | GJ2: 13 | GK2: 14 | GL2: 15 | GP2: =GR3+GR168 | GR2: Objective | GS2: P(Reorder) | GT2: 1 | GU2: 2 | GV2: 3 | GW2: 4 | GX2: 5 | GY2: 6 | GZ2: 7 | HA2: 8 | HB2: 9 | HC2: 10 | HD2: 11 | HE2: 12 | HF2: 13 | HG2: 14 | HH2: 15
B3: =Optimal_solutionw | C3: 1 | X3: 5976372.9 | Y3: 1 | AT3: 5751805.4 | AU3: 1 | BP3: 5764622.9 | BQ3: 1 | CL3: 5978588.3 | CM3: 1 | DH3: 5751969.9 | DI3: 1 | ED3: 5764358.4 | EE3: 1 | EZ3: 5978588.3 | FA3: 1 | FV3: 5751969.9 | FW3: 1 | GR3: 5764358.4 | GS3: 1
C4: 2 | Y4: 2 | AU4: 2 | BQ4: 2 | CM4: 2 | DI4: 2 | EE4: 2 | FA4: 2 | FW4: 2 | GS4: 2
C5: 3 | Y5: 3 | AU5: 3 | BQ5: 3 | CM5: 3 | DI5: 3 | EE5: 3 | FA5: 3 | FW5: 3 | GS5: 3
C7: P(Estado da arte) | D7: 1 | E7: 2 | F7: 3 | G7: 4 | H7: 5 | I7: 6 | J7: 7 | K7: 8 | L7: 9 | M7: 10 | N7: 11 | O7: 12 | P7: 13 | Q7: 14 | R7: 15 | Y7: P(Estado da arte) | Z7: 1 | AA7: 2 | AB7: 3 | AC7: 4 | AD7: 5 | AE7: 6 | AF7: 7 | AG7: 8 | AH7: 9 | AI7: 10 | AJ7: 11 | AK7: 12 | AL7: 13 | AM7: 14 | AN7: 15 | AU7: P(Estado da arte) | AV7: 1 | AW7: 2 | AX7: 3 | AY7: 4 | AZ7: 5 | BA7: 6 | BB7: 7 | BC7: 8 | BD7: 9 | BE7: 10 | BF7: 11 | BG7: 12 | BH7: 13 | BI7: 14 | BJ7: 15 | BQ7: P(Estado da arte) | BR7: 1 | BS7: 2 | BT7: 3 | BU7: 4 | BV7: 5 | BW7: 6 | BX7: 7 | BY7: 8 | BZ7: 9 | CA7: 10 | CB7: 11 | CC7: 12 | CD7: 13 | CE7: 14 | CF7: 15 | CM7: P(Estado da arte) | CN7: 1 | CO7: 2 | CP7: 3 | CQ7: 4 | CR7: 5 | CS7: 6 | CT7: 7 | CU7: 8 | CV7: 9 | CW7: 10 | CX7: 11 | CY7: 12 | CZ7: 13 | DA7: 14 | DB7: 15 | DI7: P(Estado da arte) | DJ7: 1 | DK7: 2 | DL7: 3 | DM7: 4 | DN7: 5 | DO7: 6 | DP7: 7 | DQ7: 8 | DR7: 9 | DS7: 10 | DT7: 11 | DU7: 12 | DV7: 13 | DW7: 14 | DX7: 15 | EE7: P(Estado da arte) | EF7: 1 | EG7: 2 | EH7: 3 | EI7: 4 | EJ7: 5 | EK7: 6 | EL7: 7 | EM7: 8 | EN7: 9 | EO7: 10 | EP7: 11 | EQ7: 12 | ER7: 13 | ES7: 14 | ET7: 15 | FA7: P(Estado da arte) | FB7: 1 | FC7: 2 | FD7: 3 | FE7: 4 | FF7: 5 | FG7: 6 | FH7: 7 | FI7: 8 | FJ7: 9 | FK7: 10 | FL7: 11 | FM7: 12 | FN7: 13 | FO7: 14 | FP7: 15 | FW7: P(Estado da arte) | FX7: 1 | FY7: 2 | FZ7: 3 | GA7: 4 | GB7: 5 | GC7: 6 | GD7: 7 | GE7: 8 | GF7: 9 | GG7: 10 | GH7: 11 | GI7: 12 | GJ7: 13 | GK7: 14 | GL7: 15 | GS7: P(Estado da arte) | GT7: 1 | GU7: 2 | GV7: 3 | GW7: 4 | GX7: 5 | GY7: 6 | GZ7: 7 | HA7: 8 | HB7: 9 | HC7: 10 | HD7: 11 | HE7: 12 | HF7: 13 | HG7: 14 | HH7: 15
C8: 1 | Y8: 1 | AU8: 1 | BQ8: 1 | CM8: 1 | DI8: 1 | EE8: 1 | FA8: 1 | FW8: 1 | GS8: 1
C9: 2 | Y9: 2 | AU9: 2 | BQ9: 2 | CM9: 2 | DI9: 2 | EE9: 2 | FA9: 2 | FW9: 2 | GS9: 2
C10: 3 | Y10: 3 | AU10: 3 | BQ10: 3 | CM10: 3 | DI10: 3 | EE10: 3 | FA10: 3 | FW10: 3 | GS10: 3
C12: Reorder | D12: 1 | E12: 2 | F12: 3 | G12: 4 | H12: 5 | I12: 6 | J12: 7 | K12: 8 | L12: 9 | M12: 10 | N12: 11 | O12: 12 | P12: 13 | Q12: 14 | R12: 15 | Y12: Reorder | Z12: 1 | AA12: 2 | AB12: 3 | AC12: 4 | AD12: 5 | AE12: 6 | AF12: 7 | AG12: 8 | AH12: 9 | AI12: 10 | AJ12: 11 | AK12: 12 | AL12: 13 | AM12: 14 | AN12: 15 | AU12: Reorder | AV12: 1 | AW12: 2 | AX12: 3 | AY12: 4 | AZ12: 5 | BA12: 6 | BB12: 7 | BC12: 8 | BD12: 9 | BE12: 10 | BF12: 11 | BG12: 12 | BH12: 13 | BI12: 14 | BJ12: 15 | BQ12: Reorder | BR12: 1 | BS12: 2 | BT12: 3 | BU12: 4 | BV12: 5 | BW12: 6 | BX12: 7 | BY12: 8 | BZ12: 9 | CA12: 10 | CB12: 11 | CC12: 12 | CD12: 13 | CE12: 14 | CF12: 15 | CM12: Reorder | CN12: 1 | CO12: 2 | CP12: 3 | CQ12: 4 | CR12: 5 | CS12: 6 | CT12: 7 | CU12: 8 | CV12: 9 | CW12: 10 | CX12: 11 | CY12: 12 | CZ12: 13 | DA12: 14 | DB12: 15 | DI12: Reorder | DJ12: 1 | DK12: 2 | DL12: 3 | DM12: 4 | DN12: 5 | DO12: 6 | DP12: 7 | DQ12: 8 | DR12: 9 | DS12: 10 | DT12: 11 | DU12: 12 | DV12: 13 | DW12: 14 | DX12: 15 | EE12: Reorder | EF12: 1 | EG12: 2 | EH12: 3 | EI12: 4 | EJ12: 5 | EK12: 6 | EL12: 7 | EM12: 8 | EN12: 9 | EO12: 10 | EP12: 11 | EQ12: 12 | ER12: 13 | ES12: 14 | ET12: 15 | FA12: Reorder | FB12: 1 | FC12: 2 | FD12: 3 | FE12: 4 | FF12: 5 | FG12: 6 | FH12: 7 | FI12: 8 | FJ12: 9 | FK12: 10 | FL12: 11 | FM12: 12 | FN12: 13 | FO12: 14 | FP12: 15 | FW12: Reorder | FX12: 1 | FY12: 2 | FZ12: 3 | GA12: 4 | GB12: 5 | GC12: 6 | GD12: 7 | GE12: 8 | GF12: 9 | GG12: 10 | GH12: 11 | GI12: 12 | GJ12: 13 | GK12: 14 | GL12: 15 | GS12: Reorder | GT12: 1 | GU12: 2 | GV12: 3 | GW12: 4 | GX12: 5 | GY12: 6 | GZ12: 7 | HA12: 8 | HB12: 9 | HC12: 10 | HD12: 11 | HE12: 12 | HF12: 13 | HG12: 14 | HH12: 15
C13: 1 | D13: =Suppliers_stock_balance!D212 | E13: =Suppliers_stock_balance!E212 | F13: =Suppliers_stock_balance!F212 | G13: =Suppliers_stock_balance!G212 | H13: =Suppliers_stock_balance!H212 | I13: =Suppliers_stock_balance!I212 | J13: =Suppliers_stock_balance!J212 | K13: =Suppliers_stock_balance!K212 | ... R13: =Suppliers_stock_balance!R212 | Y13: 1 | Z13: 0 | AA13: 0 | AB13: 0 | AC13: 0 | AD13: 1169.693 | AE13: 1823.2927 | AF13: 0 | AG13: 2446.7585 | AH13: 1635.9004 | AI13: 0 | AJ13: 0 | AK13: 0 | AL13: 1216.203 | AM13: 1558.7788 | AN13: 3005.2428 | AU13: 1 | AV13: 0 | AW13: 0 | AX13: 0 | AY13: 0 | AZ13: 1168.693 | BA13: 1817.2927 | BB13: 0 | BC13: 2446.7585 | BD13: 1635.9004 | BE13: 0 | BF13: 0 | BG13: 0 | BH13: 1216.203 | BI13: 1558.7788 | BJ13: 3005.2428 | BQ13: 1 | BR13: 0 | BS13: 0 | BT13: 0 | BU13: 0 | BV13: 1222.693 | BW13: 1852.2927 | BX13: 0 | BY13: 2498.7585 | BZ13: 1677.9004 | CA13: 0 | CB13: 0 | CC13: 0 | CD13: 1252.203 | CE13: 1594.7788 | CF13: 3070.2428 | CM13: 1 | CN13: 0 | CO13: 0 | CP13: 0 | CQ13: 0 | CR13: 1168.693 | CS13: 1879.2927 | CT13: 0 | CU13: 2446.7585 | CV13: 1635.9004 | CW13: 0 | CX13: 0 | CY13: 0 | CZ13: 1216.203 | DA13: 1558.7788 | DB13: 3005.2428 | DI13: 1 | DJ13: 0 | DK13: 0 | DL13: 0 | DM13: 0 | DN13: 1170.693 | DO13: 1817.2927 | DP13: 0 | DQ13: 2446.7585 | DR13: 1635.9004 | DS13: 0 | DT13: 0 | DU13: 0 | DV13: 1216.203 | DW13: 1558.7788 | DX13: 3005.2428 | EE13: 1 | EF13: 0 | EG13: 0 | EH13: 0 | EI13: 0 | EJ13: 1222.693 | EK13: 1852.2927 | EL13: 0 | EM13: 2498.7585 | EN13: 1677.9004 | EO13: 0 | EP13: 0 | EQ13: 0 | ER13: 1252.203 | ES13: 1592.7788 | ET13: 3071.2428 | FA13: 1 | FB13: 0 | FC13: 0 | FD13: 0 | FE13: 0 | FF13: 1168.693 | FG13: 1879.2927 | FH13: 0 | FI13: 2446.7585 | FJ13: 1635.9004 | FK13: 0 | FL13: 0 | FM13: 0 | FN13: 1216.203 | FO13: 1558.7788 | FP13: 3005.2428 | FW13: 1 | FX13: 0 | FY13: 0 | FZ13: 0 | GA13: 0 | GB13: 1170.693 | GC13: 1817.2927 | GD13: 0 | GE13: 2446.7585 | GF13: 1635.9004 | GG13: 0 | GH13: 0 | GI13: 0 | GJ13: 1216.203 | GK13: 1558.7788 | GL13: 3005.2428 | GS13: 1 | GT13: 0 | GU13: 0 | GV13: 0 | GW13: 0 | GX13: 1222.693 | GY13: 1852.2927 | GZ13: 0 | HA13: 2498.7585 | HB13: 1677.9004 | HC13: 0 | HD13: 0 | HE13: 0 | HF13: 1252.203 | HG13: 1592.7788 | HH13: 3071.2428
C14: 2 | D14: =Suppliers_stock_balance!D213 | E14: =Suppliers_stock_balance!E213 | F14: =Suppliers_stock_balance!F213 | G14: =Suppliers_stock_balance!G213 | H14: =Suppliers_stock_balance!H213 | I14: =Suppliers_stock_balance!I213 | J14: =Suppliers_stock_balance!J213 | K14: =Suppliers_stock_balance!K213 | ... R14: =Suppliers_stock_balance!R213 | Y14: 2 | Z14: 1262.2397 | AA14: 1303.4396 | AB14: 0 | AC14: 0 | AD14: 0 | AE14: 1632.304 | AF14: 0 | AG14: 0 | AH14: 0 | AI14: 1215.6016 | AJ14: 0 | AK14: 1583.4977 | AL14: 1579.2148 | AM14: 1508.936 | AN14: 1603.2428 | AU14: 2 | AV14: 1262.2397 | AW14: 1303.4396 | AX14: 0 | AY14: 0 | AZ14: 0 | BA14: 1632.304 | BB14: 0 | BC14: 0 | BD14: 0 | BE14: 1215.6016 | BF14: 0 | BG14: 1583.4977 | BH14: 1579.2148 | BI14: 1508.936 | BJ14: 1603.2428 | BQ14: 2 | BR14: 1302.2397 | BS14: 1342.4396 | BT14: 0 | BU14: 0 | BV14: 0 | BW14: 1685.304 | BX14: 0 | BY14: 0 | BZ14: 0 | CA14: 1248.6016 | CB14: 0 | CC14: 1632.4977 | CD14: 1623.2148 | CE14: 1569.936 | CF14: 1653.2428 | CM14: 2 | CN14: 1262.2397 | CO14: 1303.4396 | CP14: 0 | CQ14: 0 | CR14: 0 | CS14: 1632.304 | CT14: 0 | CU14: 0 | CV14: 0 | CW14: 1215.6016 | CX14: 0 | CY14: 1583.4977 | CZ14: 1579.2148 | DA14: 1508.936 | DB14: 1603.2428 | DI14: 2 | DJ14: 1262.2397 | DK14: 1303.4396 | DL14: 0 | DM14: 0 | DN14: 0 | DO14: 1632.304 | DP14: 0 | DQ14: 0 | DR14: 0 | DS14: 1215.6016 | DT14: 0 | DU14: 1583.4977 | DV14: 1579.2148 | DW14: 1508.936 | DX14: 1603.2428 | EE14: 2 | EF14: 1302.2397 | EG14: 1342.4396 | EH14: 0 | EI14: 0 | EJ14: 0 | EK14: 1685.304 | EL14: 0 | EM14: 0 | EN14: 0 | EO14: 1248.6016 | EP14: 0 | EQ14: 1631.4977 | ER14: 1623.2148 | ES14: 1569.936 | ET14: 1653.2428 | FA14: 2 | FB14: 1262.2397 | FC14: 1303.4396 | FD14: 0 | FE14: 0 | FF14: 0 | FG14: 1632.304 | FH14: 0 | FI14: 0 | FJ14: 0 | FK14: 1215.6016 | FL14: 0 | FM14: 1583.4977 | FN14: 1579.2148 | FO14: 1508.936 | FP14: 1603.2428 | FW14: 2 | FX14: 1262.2397 | FY14: 1303.4396 | FZ14: 0 | GA14: 0 | GB14: 0 | GC14: 1632.304 | GD14: 0 | GE14: 0 | GF14: 0 | GG14: 1215.6016 | GH14: 0 | GI14: 1583.4977 | GJ14: 1579.2148 | GK14: 1508.936 | GL14: 1603.2428 | GS14: 2 | GT14: 1302.2397 | GU14: 1342.4396 | GV14: 0 | GW14: 0 | GX14: 0 | GY14: 1685.304 | GZ14: 0 | HA14: 0 | HB14: 0 | HC14: 1248.6016 | HD14: 0 | HE14: 1631.4977 | HF14: 1623.2148 | HG14: 1569.936 | HH14: 1653.2428
C15: 3 | D15: =Suppliers_stock_balance!D214 | E15: =Suppliers_stock_balance!E214 | F15: =Suppliers_stock_balance!F214 | G15: =Suppliers_stock_balance!G214 | H15: =Suppliers_stock_balance!H214 | I15: =Suppliers_stock_balance!I214 | J15: =Suppliers_stock_balance!J214 | K15: =Suppliers_stock_balance!K214 | ... R15: =Suppliers_stock_balance!R214 | Y15: 3 | Z15: 3540.7346 | AA15: 0 | AB15: 0 | AC15: 1883.1626 | AD15: 0 | AE15: 4031.312 | AF15: 2527.3066 | AG15: 0 | AH15: 0 | AI15: 0 | AJ15: 1655.4375 | AK15: 0 | AL15: 0 | AM15: 0 | AN15: 1385.7436 | AU15: 3 | AV15: 3540.7346 | AW15: 0 | AX15: 0 | AY15: 1883.1626 | AZ15: 0 | BA15: 4031.312 | BB15: 2527.3066 | BC15: 0 | BD15: 0 | BE15: 0 | BF15: 1655.4375 | BG15: 0 | BH15: 0 | BI15: 0 | BJ15: 1385.7436 | BQ15: 3 | BR15: 3602.7346 | BS15: 0 | BT15: 0 | BU15: 1941.1626 | BV15: 0 | BW15: 4093.312 | BX15: 2568.3066 | BY15: 0 | BZ15: 0 | CA15: 0 | CB15: 1690.4375 | CC15: 0 | CD15: 0 | CE15: 0 | CF15: 1429.7436 | CM15: 3 | CN15: 3540.7346 | CO15: 0 | CP15: 0 | CQ15: 1883.1626 | CR15: 0 | CS15: 4031.312 | CT15: 2527.3066 | CU15: 0 | CV15: 0 | CW15: 0 | CX15: 1655.4375 | CY15: 0 | CZ15: 0 | DA15: 0 | DB15: 1385.7436 | DI15: 3 | DJ15: 3540.7346 | DK15: 0 | DL15: 0 | DM15: 1883.1626 | DN15: 0 | DO15: 4031.312 | DP15: 2527.3066 | DQ15: 0 | DR15: 0 | DS15: 0 | DT15: 1655.4375 | DU15: 0 | DV15: 0 | DW15: 0 | DX15: 1385.7436 | EE15: 3 | EF15: 3602.7346 | EG15: 0 | EH15: 0 | EI15: 1941.1626 | EJ15: 0 | EK15: 4093.312 | EL15: 2568.3066 | EM15: 0 | EN15: 0 | EO15: 0 | EP15: 1690.4375 | EQ15: 0 | ER15: 0 | ES15: 0 | ET15: 1429.7436 | FA15: 3 | FB15: 3540.7346 | FC15: 0 | FD15: 0 | FE15: 1883.1626 | FF15: 0 | FG15: 4031.312 | FH15: 2527.3066 | FI15: 0 | FJ15: 0 | FK15: 0 | FL15: 1655.4375 | FM15: 0 | FN15: 0 | FO15: 0 | FP15: 1385.7436 | FW15: 3 | FX15: 3540.7346 | FY15: 0 | FZ15: 0 | GA15: 1883.1626 | GB15: 0 | GC15: 4031.312 | GD15: 2527.3066 | GE15: 0 | GF15: 0 | GG15: 0 | GH15: 1655.4375 | GI15: 0 | GJ15: 0 | GK15: 0 | GL15: 1385.7436 | GS15: 3 | GT15: 3602.7346 | GU15: 0 | GV15: 0 | GW15: 1941.1626 | GX15: 0 | GY15: 4093.312 | GZ15: 2568.3066 | HA15: 0 | HB15: 0 | HC15: 0 | HD15: 1690.4375 | HE15: 0 | HF15: 0 | HG15: 0 | HH15: 1429.7436
C17: Var(Var(d)) | D17: 1 | E17: 2 | F17: 3 | G17: 4 | H17: 5 | I17: 6 | J17: 7 | K17: 8 | L17: 9 | M17: 10 | N17: 11 | O17: 12 | P17: 13 | Q17: 14 | R17: 15 | Y17: Var(Var(d)) | Z17: 1 | AA17: 2 | AB17: 3 | AC17: 4 | AD17: 5 | AE17: 6 | AF17: 7 | AG17: 8 | AH17: 9 | AI17: 10 | AJ17: 11 | AK17: 12 | AL17: 13 | AM17: 14 | AN17: 15 | AU17: Var(Var(d)) | AV17: 1 | AW17: 2 | AX17: 3 | AY17: 4 | AZ17: 5 | BA17: 6 | BB17: 7 | BC17: 8 | BD17: 9 | BE17: 10 | BF17: 11 | BG17: 12 | BH17: 13 | BI17: 14 | BJ17: 15 | BQ17: Var(Var(d)) | BR17: 1 | BS17: 2 | BT17: 3 | BU17: 4 | BV17: 5 | BW17: 6 | BX17: 7 | BY17: 8 | BZ17: 9 | CA17: 10 | CB17: 11 | CC17: 12 | CD17: 13 | CE17: 14 | CF17: 15 | CM17: Var(Var(d)) | CN17: 1 | CO17: 2 | CP17: 3 | CQ17: 4 | CR17: 5 | CS17: 6 | CT17: 7 | CU17: 8 | CV17: 9 | CW17: 10 | CX17: 11 | CY17: 12 | CZ17: 13 | DA17: 14 | DB17: 15 | DI17: Var(Var(d)) | DJ17: 1 | DK17: 2 | DL17: 3 | DM17: 4 | DN17: 5 | DO17: 6 | DP17: 7 | DQ17: 8 | DR17: 9 | DS17: 10 | DT17: 11 | DU17: 12 | DV17: 13 | DW17: 14 | DX17: 15 | EE17: Var(Var(d)) | EF17: 1 | EG17: 2 | EH17: 3 | EI17: 4 | EJ17: 5 | EK17: 6 | EL17: 7 | EM17: 8 | EN17: 9 | EO17: 10 | EP17: 11 | EQ17: 12 | ER17: 13 | ES17: 14 | ET17: 15 | FA17: Var(Var(d)) | FB17: 1 | FC17: 2 | FD17: 3 | FE17: 4 | FF17: 5 | FG17: 6 | FH17: 7 | FI17: 8 | FJ17: 9 | FK17: 10 | FL17: 11 | FM17: 12 | FN17: 13 | FO17: 14 | FP17: 15 | FW17: Var(Var(d)) | FX17: 1 | FY17: 2 | FZ17: 3 | GA17: 4 | GB17: 5 | GC17: 6 | GD17: 7 | GE17: 8 | GF17: 9 | GG17: 10 | GH17: 11 | GI17: 12 | GJ17: 13 | GK17: 14 | GL17: 15 | GS17: Var(Var(d)) | GT17: 1 | GU17: 2 | GV17: 3 | GW17: 4 | GX17: 5 | GY17: 6 | GZ17: 7 | HA17: 8 | HB17: 9 | HC17: 10 | HD17: 11 | HE17: 12 | HF17: 13 | HG17: 14 | HH17: 15
C18: 1 | D18: =Supp_Fourth_central_moment_5var!D18 | E18: =Supp_Fourth_central_moment_5var!E18 | F18: =Supp_Fourth_central_moment_5var!F18 | G18: =Supp_Fourth_central_moment_5var!G18 | H18: =Supp_Fourth_central_moment_5var!H18 | I18: =Supp_Fourth_central_moment_5var!I18 | J18: =Supp_Fourth_central_moment_5var!J18 | K18: =Supp_Fourth_central_moment_5var!K18 | ... R18: =Supp_Fourth_central_moment_5var!R18 | Y18: 1 | Z18: 2844775.6 | AA18: 7742075.2 | AB18: 2229641.4 | AC18: 2432768.1 | AD18: 42027317 | AE18: 9873756.6 | AF18: 2163246.7 | AG18: 45899044 | AH18: 26555973 | AI18: 12428393 | AJ18: 37330296 | AK18: 2556127.9 | AL18: 9749356.5 | AM18: 8597118.3 | AN18: 85374523 | AU18: 1 | AV18: 2844775.6 | AW18: 7742075.2 | AX18: 2229641.4 | AY18: 2432768.1 | AZ18: 42027317 | BA18: 9873756.6 | BB18: 2163246.7 | BC18: 45899044 | BD18: 26555973 | BE18: 12428393 | BF18: 37330296 | BG18: 2556127.9 | BH18: 9749356.5 | BI18: 8597118.3 | BJ18: 85374523 | BQ18: 1 | BR18: 2844775.6 | BS18: 7742075.2 | BT18: 2229641.4 | BU18: 2432768.1 | BV18: 42027317 | BW18: 9873756.6 | BX18: 2163246.7 | BY18: 45899044 | BZ18: 26555973 | CA18: 12428393 | CB18: 37330296 | CC18: 2556127.9 | CD18: 9749356.5 | CE18: 8597118.3 | CF18: 85374523 | CM18: 1 | CN18: 2844775.6 | CO18: 7742075.2 | CP18: 2229641.4 | CQ18: 2432768.1 | CR18: 42027317 | CS18: 9873756.6 | CT18: 2163246.7 | CU18: 45899044 | CV18: 26555973 | CW18: 12428393 | CX18: 37330296 | CY18: 2556127.9 | CZ18: 9749356.5 | DA18: 8597118.3 | DB18: 85374523 | DI18: 1 | DJ18: 2844775.6 | DK18: 7742075.2 | DL18: 2229641.4 | DM18: 2432768.1 | DN18: 42027317 | DO18: 9873756.6 | DP18: 2163246.7 | DQ18: 45899044 | DR18: 26555973 | DS18: 12428393 | DT18: 37330296 | DU18: 2556127.9 | DV18: 9749356.5 | DW18: 8597118.3 | DX18: 85374523 | EE18: 1 | EF18: 2844775.6 | EG18: 7742075.2 | EH18: 2229641.4 | EI18: 2432768.1 | EJ18: 42027317 | EK18: 9873756.6 | EL18: 2163246.7 | EM18: 45899044 | EN18: 26555973 | EO18: 12428393 | EP18: 37330296 | EQ18: 2556127.9 | ER18: 9749356.5 | ES18: 8597118.3 | ET18: 85374523 | FA18: 1 | FB18: 2844775.6 | FC18: 7742075.2 | FD18: 2229641.4 | FE18: 2432768.1 | FF18: 42027317 | FG18: 9873756.6 | FH18: 2163246.7 | FI18: 45899044 | FJ18: 26555973 | FK18: 12428393 | FL18: 37330296 | FM18: 2556127.9 | FN18: 9749356.5 | FO18: 8597118.3 | FP18: 85374523 | FW18: 1 | FX18: 2844775.6 | FY18: 7742075.2 | FZ18: 2229641.4 | GA18: 2432768.1 | GB18: 42027317 | GC18: 9873756.6 | GD18: 2163246.7 | GE18: 45899044 | GF18: 26555973 | GG18: 12428393 | GH18: 37330296 | GI18: 2556127.9 | GJ18: 9749356.5 | GK18: 8597118.3 | GL18: 85374523 | GS18: 1 | GT18: 2844775.6 | GU18: 7742075.2 | GV18: 2229641.4 | GW18: 2432768.1 | GX18: 42027317 | GY18: 9873756.6 | GZ18: 2163246.7 | HA18: 45899044 | HB18: 26555973 | HC18: 12428393 | HD18: 37330296 | HE18: 2556127.9 | HF18: 9749356.5 | HG18: 8597118.3 | HH18: 85374523
C19: 2 | D19: =Supp_Fourth_central_moment_5var!D19 | E19: =Supp_Fourth_central_moment_5var!E19 | F19: =Supp_Fourth_central_moment_5var!F19 | G19: =Supp_Fourth_central_moment_5var!G19 | H19: =Supp_Fourth_central_moment_5var!H19 | I19: =Supp_Fourth_central_moment_5var!I19 | J19: =Supp_Fourth_central_moment_5var!J19 | K19: =Supp_Fourth_central_moment_5var!K19 | ... R19: =Supp_Fourth_central_moment_5var!R19 | Y19: 2 | Z19: 16442955 | AA19: 9026290 | AB19: 4855892.1 | AC19: 13808858 | AD19: 25179163 | AE19: 34894600 | AF19: 9244423.7 | AG19: 2977286.9 | AH19: 8318899.5 | AI19: 8485006.6 | AJ19: 5997213.4 | AK19: 26367470 | AL19: 11445921 | AM19: 45386782 | AN19: 38903315 | AU19: 2 | AV19: 16442955 | AW19: 9026290 | AX19: 4855892.1 | AY19: 13808858 | AZ19: 25179163 | BA19: 34894600 | BB19: 9244423.7 | BC19: 2977286.9 | BD19: 8318899.5 | BE19: 8485006.6 | BF19: 5997213.4 | BG19: 26367470 | BH19: 11445921 | BI19: 45386782 | BJ19: 38903315 | BQ19: 2 | BR19: 16442955 | BS19: 9026290 | BT19: 4855892.1 | BU19: 13808858 | BV19: 25179163 | BW19: 34894600 | BX19: 9244423.7 | BY19: 2977286.9 | BZ19: 8318899.5 | CA19: 8485006.6 | CB19: 5997213.4 | CC19: 26367470 | CD19: 11445921 | CE19: 45386782 | CF19: 38903315 | CM19: 2 | CN19: 16442955 | CO19: 9026290 | CP19: 4855892.1 | CQ19: 13808858 | CR19: 25179163 | CS19: 34894600 | CT19: 9244423.7 | CU19: 2977286.9 | CV19: 8318899.5 | CW19: 8485006.6 | CX19: 5997213.4 | CY19: 26367470 | CZ19: 11445921 | DA19: 45386782 | DB19: 38903315 | DI19: 2 | DJ19: 16442955 | DK19: 9026290 | DL19: 4855892.1 | DM19: 13808858 | DN19: 25179163 | DO19: 34894600 | DP19: 9244423.7 | DQ19: 2977286.9 | DR19: 8318899.5 | DS19: 8485006.6 | DT19: 5997213.4 | DU19: 26367470 | DV19: 11445921 | DW19: 45386782 | DX19: 38903315 | EE19: 2 | EF19: 16442955 | EG19: 9026290 | EH19: 4855892.1 | EI19: 13808858 | EJ19: 25179163 | EK19: 34894600 | EL19: 9244423.7 | EM19: 2977286.9 | EN19: 8318899.5 | EO19: 8485006.6 | EP19: 5997213.4 | EQ19: 26367470 | ER19: 11445921 | ES19: 45386782 | ET19: 38903315 | FA19: 2 | FB19: 16442955 | FC19: 9026290 | FD19: 4855892.1 | FE19: 13808858 | FF19: 25179163 | FG19: 34894600 | FH19: 9244423.7 | FI19: 2977286.9 | FJ19: 8318899.5 | FK19: 8485006.6 | FL19: 5997213.4 | FM19: 26367470 | FN19: 11445921 | FO19: 45386782 | FP19: 38903315 | FW19: 2 | FX19: 16442955 | FY19: 9026290 | FZ19: 4855892.1 | GA19: 13808858 | GB19: 25179163 | GC19: 34894600 | GD19: 9244423.7 | GE19: 2977286.9 | GF19: 8318899.5 | GG19: 8485006.6 | GH19: 5997213.4 | GI19: 26367470 | GJ19: 11445921 | GK19: 45386782 | GL19: 38903315 | GS19: 2 | GT19: 16442955 | GU19: 9026290 | GV19: 4855892.1 | GW19: 13808858 | GX19: 25179163 | GY19: 34894600 | GZ19: 9244423.7 | HA19: 2977286.9 | HB19: 8318899.5 | HC19: 8485006.6 | HD19: 5997213.4 | HE19: 26367470 | HF19: 11445921 | HG19: 45386782 | HH19: 38903315
C20: 3 | D20: =Supp_Fourth_central_moment_5var!D20 | E20: =Supp_Fourth_central_moment_5var!E20 | F20: =Supp_Fourth_central_moment_5var!F20 | G20: =Supp_Fourth_central_moment_5var!G20 | H20: =Supp_Fourth_central_moment_5var!H20 | I20: =Supp_Fourth_central_moment_5var!I20 | J20: =Supp_Fourth_central_moment_5var!J20 | K20: =Supp_Fourth_central_moment_5var!K20 | ... R20: =Supp_Fourth_central_moment_5var!R20 | Y20: 3 | Z20: 58453271 | AA20: 4551358.7 | AB20: 2885793.1 | AC20: 69307093 | AD20: 5392062.9 | AE20: 65012269 | AF20: 23677849 | AG20: 14290849 | AH20: 5095842.9 | AI20: 5486371 | AJ20: 19131440 | AK20: 11275128 | AL20: 12931980 | AM20: 14603460 | AN20: 26872387 | AU20: 3 | AV20: 58453271 | AW20: 4551358.7 | AX20: 2885793.1 | AY20: 69307093 | AZ20: 5392062.9 | BA20: 65012269 | BB20: 23677849 | BC20: 14290849 | BD20: 5095842.9 | BE20: 5486371 | BF20: 19131440 | BG20: 11275128 | BH20: 12931980 | BI20: 14603460 | BJ20: 26872387 | BQ20: 3 | BR20: 58453271 | BS20: 4551358.7 | BT20: 2885793.1 | BU20: 69307093 | BV20: 5392062.9 | BW20: 65012269 | BX20: 23677849 | BY20: 14290849 | BZ20: 5095842.9 | CA20: 5486371 | CB20: 19131440 | CC20: 11275128 | CD20: 12931980 | CE20: 14603460 | CF20: 26872387 | CM20: 3 | CN20: 58453271 | CO20: 4551358.7 | CP20: 2885793.1 | CQ20: 69307093 | CR20: 5392062.9 | CS20: 65012269 | CT20: 23677849 | CU20: 14290849 | CV20: 5095842.9 | CW20: 5486371 | CX20: 19131440 | CY20: 11275128 | CZ20: 12931980 | DA20: 14603460 | DB20: 26872387 | DI20: 3 | DJ20: 58453271 | DK20: 4551358.7 | DL20: 2885793.1 | DM20: 69307093 | DN20: 5392062.9 | DO20: 65012269 | DP20: 23677849 | DQ20: 14290849 | DR20: 5095842.9 | DS20: 5486371 | DT20: 19131440 | DU20: 11275128 | DV20: 12931980 | DW20: 14603460 | DX20: 26872387 | EE20: 3 | EF20: 58453271 | EG20: 4551358.7 | EH20: 2885793.1 | EI20: 69307093 | EJ20: 5392062.9 | EK20: 65012269 | EL20: 23677849 | EM20: 14290849 | EN20: 5095842.9 | EO20: 5486371 | EP20: 19131440 | EQ20: 11275128 | ER20: 12931980 | ES20: 14603460 | ET20: 26872387 | FA20: 3 | FB20: 58453271 | FC20: 4551358.7 | FD20: 2885793.1 | FE20: 69307093 | FF20: 5392062.9 | FG20: 65012269 | FH20: 23677849 | FI20: 14290849 | FJ20: 5095842.9 | FK20: 5486371 | FL20: 19131440 | FM20: 11275128 | FN20: 12931980 | FO20: 14603460 | FP20: 26872387 | FW20: 3 | FX20: 58453271 | FY20: 4551358.7 | FZ20: 2885793.1 | GA20: 69307093 | GB20: 5392062.9 | GC20: 65012269 | GD20: 23677849 | GE20: 14290849 | GF20: 5095842.9 | GG20: 5486371 | GH20: 19131440 | GI20: 11275128 | GJ20: 12931980 | GK20: 14603460 | GL20: 26872387 | GS20: 3 | GT20: 58453271 | GU20: 4551358.7 | GV20: 2885793.1 | GW20: 69307093 | GX20: 5392062.9 | GY20: 65012269 | GZ20: 23677849 | HA20: 14290849 | HB20: 5095842.9 | HC20: 5486371 | HD20: 19131440 | HE20: 11275128 | HF20: 12931980 | HG20: 14603460 | HH20: 26872387
C22: Var(Var(Cap)) | D22: 1 | E22: 2 | F22: 3 | G22: 4 | H22: 5 | I22: 6 | J22: 7 | K22: 8 | L22: 9 | M22: 10 | N22: 11 | O22: 12 | P22: 13 | Q22: 14 | R22: 15 | Y22: Var(Var(Cap)) | Z22: 1 | AA22: 2 | AB22: 3 | AC22: 4 | AD22: 5 | AE22: 6 | AF22: 7 | AG22: 8 | AH22: 9 | AI22: 10 | AJ22: 11 | AK22: 12 | AL22: 13 | AM22: 14 | AN22: 15 | AU22: Var(Var(Cap)) | AV22: 1 | AW22: 2 | AX22: 3 | AY22: 4 | AZ22: 5 | BA22: 6 | BB22: 7 | BC22: 8 | BD22: 9 | BE22: 10 | BF22: 11 | BG22: 12 | BH22: 13 | BI22: 14 | BJ22: 15 | BQ22: Var(Var(Cap)) | BR22: 1 | BS22: 2 | BT22: 3 | BU22: 4 | BV22: 5 | BW22: 6 | BX22: 7 | BY22: 8 | BZ22: 9 | CA22: 10 | CB22: 11 | CC22: 12 | CD22: 13 | CE22: 14 | CF22: 15 | CM22: Var(Var(Cap)) | CN22: 1 | CO22: 2 | CP22: 3 | CQ22: 4 | CR22: 5 | CS22: 6 | CT22: 7 | CU22: 8 | CV22: 9 | CW22: 10 | CX22: 11 | CY22: 12 | CZ22: 13 | DA22: 14 | DB22: 15 | DI22: Var(Var(Cap)) | DJ22: 1 | DK22: 2 | DL22: 3 | DM22: 4 | DN22: 5 | DO22: 6 | DP22: 7 | DQ22: 8 | DR22: 9 | DS22: 10 | DT22: 11 | DU22: 12 | DV22: 13 | DW22: 14 | DX22: 15 | EE22: Var(Var(Cap)) | EF22: 1 | EG22: 2 | EH22: 3 | EI22: 4 | EJ22: 5 | EK22: 6 | EL22: 7 | EM22: 8 | EN22: 9 | EO22: 10 | EP22: 11 | EQ22: 12 | ER22: 13 | ES22: 14 | ET22: 15 | FA22: Var(Var(Cap)) | FB22: 1 | FC22: 2 | FD22: 3 | FE22: 4 | FF22: 5 | FG22: 6 | FH22: 7 | FI22: 8 | FJ22: 9 | FK22: 10 | FL22: 11 | FM22: 12 | FN22: 13 | FO22: 14 | FP22: 15 | FW22: Var(Var(Cap)) | FX22: 1 | FY22: 2 | FZ22: 3 | GA22: 4 | GB22: 5 | GC22: 6 | GD22: 7 | GE22: 8 | GF22: 9 | GG22: 10 | GH22: 11 | GI22: 12 | GJ22: 13 | GK22: 14 | GL22: 15 | GS22: Var(Var(Cap)) | GT22: 1 | GU22: 2 | GV22: 3 | GW22: 4 | GX22: 5 | GY22: 6 | GZ22: 7 | HA22: 8 | HB22: 9 | HC22: 10 | HD22: 11 | HE22: 12 | HF22: 13 | HG22: 14 | HH22: 15
C23: 1 | D23: =Supp_Fourth_central_moment_5var!D24 | E23: =Supp_Fourth_central_moment_5var!E24 | F23: =Supp_Fourth_central_moment_5var!F24 | G23: =Supp_Fourth_central_moment_5var!G24 | H23: =Supp_Fourth_central_moment_5var!H24 | I23: =Supp_Fourth_central_moment_5var!I24 | J23: =Supp_Fourth_central_moment_5var!J24 | K23: =Supp_Fourth_central_moment_5var!K24 | ... R23: =Supp_Fourth_central_moment_5var!R24 | Y23: 1 | Z23: 8526359.4 | AA23: 12657216 | AB23: 18040924 | AC23: 11831926 | AD23: 27221024 | AE23: 1919326 | AF23: 15405680 | AG23: 11110350 | AH23: 8390576.7 | AI23: 17370807 | AJ23: 31963314 | AK23: 3912563.3 | AL23: 4076126.2 | AM23: 2176888.1 | AN23: 22626377 | AU23: 1 | AV23: 8526359.4 | AW23: 12657216 | AX23: 18040924 | AY23: 11831926 | AZ23: 27221024 | BA23: 1919326 | BB23: 15405680 | BC23: 11110350 | BD23: 8390576.7 | BE23: 17370807 | BF23: 31963314 | BG23: 3912563.3 | BH23: 4076126.2 | BI23: 2176888.1 | BJ23: 22626377 | BQ23: 1 | BR23: 8526359.4 | BS23: 12657216 | BT23: 18040924 | BU23: 11831926 | BV23: 27221024 | BW23: 1919326 | BX23: 15405680 | BY23: 11110350 | BZ23: 8390576.7 | CA23: 17370807 | CB23: 31963314 | CC23: 3912563.3 | CD23: 4076126.2 | CE23: 2176888.1 | CF23: 22626377 | CM23: 1 | CN23: 8526359.4 | CO23: 12657216 | CP23: 18040924 | CQ23: 11831926 | CR23: 27221024 | CS23: 1919326 | CT23: 15405680 | CU23: 11110350 | CV23: 8390576.7 | CW23: 17370807 | CX23: 31963314 | CY23: 3912563.3 | CZ23: 4076126.2 | DA23: 2176888.1 | DB23: 22626377 | DI23: 1 | DJ23: 8526359.4 | DK23: 12657216 | DL23: 18040924 | DM23: 11831926 | DN23: 27221024 | DO23: 1919326 | DP23: 15405680 | DQ23: 11110350 | DR23: 8390576.7 | DS23: 17370807 | DT23: 31963314 | DU23: 3912563.3 | DV23: 4076126.2 | DW23: 2176888.1 | DX23: 22626377 | EE23: 1 | EF23: 8526359.4 | EG23: 12657216 | EH23: 18040924 | EI23: 11831926 | EJ23: 27221024 | EK23: 1919326 | EL23: 15405680 | EM23: 11110350 | EN23: 8390576.7 | EO23: 17370807 | EP23: 31963314 | EQ23: 3912563.3 | ER23: 4076126.2 | ES23: 2176888.1 | ET23: 22626377 | FA23: 1 | FB23: 8526359.4 | FC23: 12657216 | FD23: 18040924 | FE23: 11831926 | FF23: 27221024 | FG23: 1919326 | FH23: 15405680 | FI23: 11110350 | FJ23: 8390576.7 | FK23: 17370807 | FL23: 31963314 | FM23: 3912563.3 | FN23: 4076126.2 | FO23: 2176888.1 | FP23: 22626377 | FW23: 1 | FX23: 8526359.4 | FY23: 12657216 | FZ23: 18040924 | GA23: 11831926 | GB23: 27221024 | GC23: 1919326 | GD23: 15405680 | GE23: 11110350 | GF23: 8390576.7 | GG23: 17370807 | GH23: 31963314 | GI23: 3912563.3 | GJ23: 4076126.2 | GK23: 2176888.1 | GL23: 22626377 | GS23: 1 | GT23: 8526359.4 | GU23: 12657216 | GV23: 18040924 | GW23: 11831926 | GX23: 27221024 | GY23: 1919326 | GZ23: 15405680 | HA23: 11110350 | HB23: 8390576.7 | HC23: 17370807 | HD23: 31963314 | HE23: 3912563.3 | HF23: 4076126.2 | HG23: 2176888.1 | HH23: 22626377
C24: 2 | D24: =Supp_Fourth_central_moment_5var!D25 | E24: =Supp_Fourth_central_moment_5var!E25 | F24: =Supp_Fourth_central_moment_5var!F25 | G24: =Supp_Fourth_central_moment_5var!G25 | H24: =Supp_Fourth_central_moment_5var!H25 | I24: =Supp_Fourth_central_moment_5var!I25 | J24: =Supp_Fourth_central_moment_5var!J25 | K24: =Supp_Fourth_central_moment_5var!K25 | ... R24: =Supp_Fourth_central_moment_5var!R25 | Y24: 2 | Z24: 6878770.2 | AA24: 4160458.1 | AB24: 12301143 | AC24: 1.0452533e+08 | AD24: 17313597 | AE24: 16551330 | AF24: 8533079.4 | AG24: 9406080.4 | AH24: 20459970 | AI24: 2934289.7 | AJ24: 22429145 | AK24: 11754810 | AL24: 4985629.9 | AM24: 27519080 | AN24: 16282301 | AU24: 2 | AV24: 6878770.2 | AW24: 4160458.1 | AX24: 12301143 | AY24: 1.0452533e+08 | AZ24: 17313597 | BA24: 16551330 | BB24: 8533079.4 | BC24: 9406080.4 | BD24: 20459970 | BE24: 2934289.7 | BF24: 22429145 | BG24: 11754810 | BH24: 4985629.9 | BI24: 27519080 | BJ24: 16282301 | BQ24: 2 | BR24: 6878770.2 | BS24: 4160458.1 | BT24: 12301143 | BU24: 1.0452533e+08 | BV24: 17313597 | BW24: 16551330 | BX24: 8533079.4 | BY24: 9406080.4 | BZ24: 20459970 | CA24: 2934289.7 | CB24: 22429145 | CC24: 11754810 | CD24: 4985629.9 | CE24: 27519080 | CF24: 16282301 | CM24: 2 | CN24: 6878770.2 | CO24: 4160458.1 | CP24: 12301143 | CQ24: 1.0452533e+08 | CR24: 17313597 | CS24: 16551330 | CT24: 8533079.4 | CU24: 9406080.4 | CV24: 20459970 | CW24: 2934289.7 | CX24: 22429145 | CY24: 11754810 | CZ24: 4985629.9 | DA24: 27519080 | DB24: 16282301 | DI24: 2 | DJ24: 6878770.2 | DK24: 4160458.1 | DL24: 12301143 | DM24: 1.0452533e+08 | DN24: 17313597 | DO24: 16551330 | DP24: 8533079.4 | DQ24: 9406080.4 | DR24: 20459970 | DS24: 2934289.7 | DT24: 22429145 | DU24: 11754810 | DV24: 4985629.9 | DW24: 27519080 | DX24: 16282301 | EE24: 2 | EF24: 6878770.2 | EG24: 4160458.1 | EH24: 12301143 | EI24: 1.0452533e+08 | EJ24: 17313597 | EK24: 16551330 | EL24: 8533079.4 | EM24: 9406080.4 | EN24: 20459970 | EO24: 2934289.7 | EP24: 22429145 | EQ24: 11754810 | ER24: 4985629.9 | ES24: 27519080 | ET24: 16282301 | FA24: 2 | FB24: 6878770.2 | FC24: 4160458.1 | FD24: 12301143 | FE24: 1.0452533e+08 | FF24: 17313597 | FG24: 16551330 | FH24: 8533079.4 | FI24: 9406080.4 | FJ24: 20459970 | FK24: 2934289.7 | FL24: 22429145 | FM24: 11754810 | FN24: 4985629.9 | FO24: 27519080 | FP24: 16282301 | FW24: 2 | FX24: 6878770.2 | FY24: 4160458.1 | FZ24: 12301143 | GA24: 1.0452533e+08 | GB24: 17313597 | GC24: 16551330 | GD24: 8533079.4 | GE24: 9406080.4 | GF24: 20459970 | GG24: 2934289.7 | GH24: 22429145 | GI24: 11754810 | GJ24: 4985629.9 | GK24: 27519080 | GL24: 16282301 | GS24: 2 | GT24: 6878770.2 | GU24: 4160458.1 | GV24: 12301143 | GW24: 1.0452533e+08 | GX24: 17313597 | GY24: 16551330 | GZ24: 8533079.4 | HA24: 9406080.4 | HB24: 20459970 | HC24: 2934289.7 | HD24: 22429145 | HE24: 11754810 | HF24: 4985629.9 | HG24: 27519080 | HH24: 16282301
C25: 3 | D25: =Supp_Fourth_central_moment_5var!D26 | E25: =Supp_Fourth_central_moment_5var!E26 | F25: =Supp_Fourth_central_moment_5var!F26 | G25: =Supp_Fourth_central_moment_5var!G26 | H25: =Supp_Fourth_central_moment_5var!H26 | I25: =Supp_Fourth_central_moment_5var!I26 | J25: =Supp_Fourth_central_moment_5var!J26 | K25: =Supp_Fourth_central_moment_5var!K26 | ... R25: =Supp_Fourth_central_moment_5var!R26 | Y25: 3 | Z25: 11418019 | AA25: 16496157 | AB25: 26265785 | AC25: 29589068 | AD25: 18192654 | AE25: 8745661 | AF25: 2328698.7 | AG25: 27459813 | AH25: 24860351 | AI25: 8627578.1 | AJ25: 3371880.8 | AK25: 9817630 | AL25: 36082173 | AM25: 23660993 | AN25: 11348486 | AU25: 3 | AV25: 11418019 | AW25: 16496157 | AX25: 26265785 | AY25: 29589068 | AZ25: 18192654 | BA25: 8745661 | BB25: 2328698.7 | BC25: 27459813 | BD25: 24860351 | BE25: 8627578.1 | BF25: 3371880.8 | BG25: 9817630 | BH25: 36082173 | BI25: 23660993 | BJ25: 11348486 | BQ25: 3 | BR25: 11418019 | BS25: 16496157 | BT25: 26265785 | BU25: 29589068 | BV25: 18192654 | BW25: 8745661 | BX25: 2328698.7 | BY25: 27459813 | BZ25: 24860351 | CA25: 8627578.1 | CB25: 3371880.8 | CC25: 9817630 | CD25: 36082173 | CE25: 23660993 | CF25: 11348486 | CM25: 3 | CN25: 11418019 | CO25: 16496157 | CP25: 26265785 | CQ25: 29589068 | CR25: 18192654 | CS25: 8745661 | CT25: 2328698.7 | CU25: 27459813 | CV25: 24860351 | CW25: 8627578.1 | CX25: 3371880.8 | CY25: 9817630 | CZ25: 36082173 | DA25: 23660993 | DB25: 11348486 | DI25: 3 | DJ25: 11418019 | DK25: 16496157 | DL25: 26265785 | DM25: 29589068 | DN25: 18192654 | DO25: 8745661 | DP25: 2328698.7 | DQ25: 27459813 | DR25: 24860351 | DS25: 8627578.1 | DT25: 3371880.8 | DU25: 9817630 | DV25: 36082173 | DW25: 23660993 | DX25: 11348486 | EE25: 3 | EF25: 11418019 | EG25: 16496157 | EH25: 26265785 | EI25: 29589068 | EJ25: 18192654 | EK25: 8745661 | EL25: 2328698.7 | EM25: 27459813 | EN25: 24860351 | EO25: 8627578.1 | EP25: 3371880.8 | EQ25: 9817630 | ER25: 36082173 | ES25: 23660993 | ET25: 11348486 | FA25: 3 | FB25: 11418019 | FC25: 16496157 | FD25: 26265785 | FE25: 29589068 | FF25: 18192654 | FG25: 8745661 | FH25: 2328698.7 | FI25: 27459813 | FJ25: 24860351 | FK25: 8627578.1 | FL25: 3371880.8 | FM25: 9817630 | FN25: 36082173 | FO25: 23660993 | FP25: 11348486 | FW25: 3 | FX25: 11418019 | FY25: 16496157 | FZ25: 26265785 | GA25: 29589068 | GB25: 18192654 | GC25: 8745661 | GD25: 2328698.7 | GE25: 27459813 | GF25: 24860351 | GG25: 8627578.1 | GH25: 3371880.8 | GI25: 9817630 | GJ25: 36082173 | GK25: 23660993 | GL25: 11348486 | GS25: 3 | GT25: 11418019 | GU25: 16496157 | GV25: 26265785 | GW25: 29589068 | GX25: 18192654 | GY25: 8745661 | GZ25: 2328698.7 | HA25: 27459813 | HB25: 24860351 | HC25: 8627578.1 | HD25: 3371880.8 | HE25: 9817630 | HF25: 36082173 | HG25: 23660993 | HH25: 11348486
B27: =Data!D27 | C27: CV | D27: 1 | E27: 2 | F27: 3 | G27: 4 | H27: 5 | I27: 6 | J27: 7 | K27: 8 | L27: 9 | M27: 10 | N27: 11 | O27: 12 | P27: 13 | Q27: 14 | R27: 15 | Y27: CV | Z27: 1 | AA27: 2 | AB27: 3 | AC27: 4 | AD27: 5 | AE27: 6 | AF27: 7 | AG27: 8 | AH27: 9 | AI27: 10 | AJ27: 11 | AK27: 12 | AL27: 13 | AM27: 14 | AN27: 15 | AU27: CV | AV27: 1 | AW27: 2 | AX27: 3 | AY27: 4 | AZ27: 5 | BA27: 6 | BB27: 7 | BC27: 8 | BD27: 9 | BE27: 10 | BF27: 11 | BG27: 12 | BH27: 13 | BI27: 14 | BJ27: 15 | BQ27: CV | BR27: 1 | BS27: 2 | BT27: 3 | BU27: 4 | BV27: 5 | BW27: 6 | BX27: 7 | BY27: 8 | BZ27: 9 | CA27: 10 | CB27: 11 | CC27: 12 | CD27: 13 | CE27: 14 | CF27: 15 | CM27: CV | CN27: 1 | CO27: 2 | CP27: 3 | CQ27: 4 | CR27: 5 | CS27: 6 | CT27: 7 | CU27: 8 | CV27: 9 | CW27: 10 | CX27: 11 | CY27: 12 | CZ27: 13 | DA27: 14 | DB27: 15 | DI27: CV | DJ27: 1 | DK27: 2 | DL27: 3 | DM27: 4 | DN27: 5 | DO27: 6 | DP27: 7 | DQ27: 8 | DR27: 9 | DS27: 10 | DT27: 11 | DU27: 12 | DV27: 13 | DW27: 14 | DX27: 15 | EE27: CV | EF27: 1 | EG27: 2 | EH27: 3 | EI27: 4 | EJ27: 5 | EK27: 6 | EL27: 7 | EM27: 8 | EN27: 9 | EO27: 10 | EP27: 11 | EQ27: 12 | ER27: 13 | ES27: 14 | ET27: 15 | FA27: CV | FB27: 1 | FC27: 2 | FD27: 3 | FE27: 4 | FF27: 5 | FG27: 6 | FH27: 7 | FI27: 8 | FJ27: 9 | FK27: 10 | FL27: 11 | FM27: 12 | FN27: 13 | FO27: 14 | FP27: 15 | FW27: CV | FX27: 1 | FY27: 2 | FZ27: 3 | GA27: 4 | GB27: 5 | GC27: 6 | GD27: 7 | GE27: 8 | GF27: 9 | GG27: 10 | GH27: 11 | GI27: 12 | GJ27: 13 | GK27: 14 | GL27: 15 | GS27: CV | GT27: 1 | GU27: 2 | GV27: 3 | GW27: 4 | GX27: 5 | GY27: 6 | GZ27: 7 | HA27: 8 | HB27: 9 | HC27: 10 | HD27: 11 | HE27: 12 | HF27: 13 | HG27: 14 | HH27: 15
C28: 1 | D28: =$B$27 | E28: =$B$27 | F28: =$B$27 | G28: =$B$27 | H28: =$B$27 | I28: =$B$27 | J28: =$B$27 | K28: =$B$27 | ... R28: =$B$27 | Y28: 1 | Z28: 0.2 | AA28: 0.2 | AB28: 0.2 | AC28: 0.2 | AD28: 0.2 | AE28: 0.2 | AF28: 0.2 | AG28: 0.2 | AH28: 0.2 | AI28: 0.2 | AJ28: 0.2 | AK28: 0.2 | AL28: 0.2 | AM28: 0.2 | AN28: 0.2 | AU28: 1 | AV28: 0.2 | AW28: 0.2 | AX28: 0.2 | AY28: 0.2 | AZ28: 0.2 | BA28: 0.2 | BB28: 0.2 | BC28: 0.2 | BD28: 0.2 | BE28: 0.2 | BF28: 0.2 | BG28: 0.2 | BH28: 0.2 | BI28: 0.2 | BJ28: 0.2 | BQ28: 1 | BR28: 0.2 | BS28: 0.2 | BT28: 0.2 | BU28: 0.2 | BV28: 0.2 | BW28: 0.2 | BX28: 0.2 | BY28: 0.2 | BZ28: 0.2 | CA28: 0.2 | CB28: 0.2 | CC28: 0.2 | CD28: 0.2 | CE28: 0.2 | CF28: 0.2 | CM28: 1 | CN28: 0.2 | CO28: 0.2 | CP28: 0.2 | CQ28: 0.2 | CR28: 0.2 | CS28: 0.2 | CT28: 0.2 | CU28: 0.2 | CV28: 0.2 | CW28: 0.2 | CX28: 0.2 | CY28: 0.2 | CZ28: 0.2 | DA28: 0.2 | DB28: 0.2 | DI28: 1 | DJ28: 0.2 | DK28: 0.2 | DL28: 0.2 | DM28: 0.2 | DN28: 0.2 | DO28: 0.2 | DP28: 0.2 | DQ28: 0.2 | DR28: 0.2 | DS28: 0.2 | DT28: 0.2 | DU28: 0.2 | DV28: 0.2 | DW28: 0.2 | DX28: 0.2 | EE28: 1 | EF28: 0.2 | EG28: 0.2 | EH28: 0.2 | EI28: 0.2 | EJ28: 0.2 | EK28: 0.2 | EL28: 0.2 | EM28: 0.2 | EN28: 0.2 | EO28: 0.2 | EP28: 0.2 | EQ28: 0.2 | ER28: 0.2 | ES28: 0.2 | ET28: 0.2 | FA28: 1 | FB28: 0.2 | FC28: 0.2 | FD28: 0.2 | FE28: 0.2 | FF28: 0.2 | FG28: 0.2 | FH28: 0.2 | FI28: 0.2 | FJ28: 0.2 | FK28: 0.2 | FL28: 0.2 | FM28: 0.2 | FN28: 0.2 | FO28: 0.2 | FP28: 0.2 | FW28: 1 | FX28: 0.2 | FY28: 0.2 | FZ28: 0.2 | GA28: 0.2 | GB28: 0.2 | GC28: 0.2 | GD28: 0.2 | GE28: 0.2 | GF28: 0.2 | GG28: 0.2 | GH28: 0.2 | GI28: 0.2 | GJ28: 0.2 | GK28: 0.2 | GL28: 0.2 | GS28: 1 | GT28: 0.2 | GU28: 0.2 | GV28: 0.2 | GW28: 0.2 | GX28: 0.2 | GY28: 0.2 | GZ28: 0.2 | HA28: 0.2 | HB28: 0.2 | HC28: 0.2 | HD28: 0.2 | HE28: 0.2 | HF28: 0.2 | HG28: 0.2 | HH28: 0.2
C29: 2 | D29: =$B$27 | E29: =$B$27 | F29: =$B$27 | G29: =$B$27 | H29: =$B$27 | I29: =$B$27 | J29: =$B$27 | K29: =$B$27 | ... R29: =$B$27 | Y29: 2 | Z29: 0.2 | AA29: 0.2 | AB29: 0.2 | AC29: 0.2 | AD29: 0.2 | AE29: 0.2 | AF29: 0.2 | AG29: 0.2 | AH29: 0.2 | AI29: 0.2 | AJ29: 0.2 | AK29: 0.2 | AL29: 0.2 | AM29: 0.2 | AN29: 0.2 | AU29: 2 | AV29: 0.2 | AW29: 0.2 | AX29: 0.2 | AY29: 0.2 | AZ29: 0.2 | BA29: 0.2 | BB29: 0.2 | BC29: 0.2 | BD29: 0.2 | BE29: 0.2 | BF29: 0.2 | BG29: 0.2 | BH29: 0.2 | BI29: 0.2 | BJ29: 0.2 | BQ29: 2 | BR29: 0.2 | BS29: 0.2 | BT29: 0.2 | BU29: 0.2 | BV29: 0.2 | BW29: 0.2 | BX29: 0.2 | BY29: 0.2 | BZ29: 0.2 | CA29: 0.2 | CB29: 0.2 | CC29: 0.2 | CD29: 0.2 | CE29: 0.2 | CF29: 0.2 | CM29: 2 | CN29: 0.2 | CO29: 0.2 | CP29: 0.2 | CQ29: 0.2 | CR29: 0.2 | CS29: 0.2 | CT29: 0.2 | CU29: 0.2 | CV29: 0.2 | CW29: 0.2 | CX29: 0.2 | CY29: 0.2 | CZ29: 0.2 | DA29: 0.2 | DB29: 0.2 | DI29: 2 | DJ29: 0.2 | DK29: 0.2 | DL29: 0.2 | DM29: 0.2 | DN29: 0.2 | DO29: 0.2 | DP29: 0.2 | DQ29: 0.2 | DR29: 0.2 | DS29: 0.2 | DT29: 0.2 | DU29: 0.2 | DV29: 0.2 | DW29: 0.2 | DX29: 0.2 | EE29: 2 | EF29: 0.2 | EG29: 0.2 | EH29: 0.2 | EI29: 0.2 | EJ29: 0.2 | EK29: 0.2 | EL29: 0.2 | EM29: 0.2 | EN29: 0.2 | EO29: 0.2 | EP29: 0.2 | EQ29: 0.2 | ER29: 0.2 | ES29: 0.2 | ET29: 0.2 | FA29: 2 | FB29: 0.2 | FC29: 0.2 | FD29: 0.2 | FE29: 0.2 | FF29: 0.2 | FG29: 0.2 | FH29: 0.2 | FI29: 0.2 | FJ29: 0.2 | FK29: 0.2 | FL29: 0.2 | FM29: 0.2 | FN29: 0.2 | FO29: 0.2 | FP29: 0.2 | FW29: 2 | FX29: 0.2 | FY29: 0.2 | FZ29: 0.2 | GA29: 0.2 | GB29: 0.2 | GC29: 0.2 | GD29: 0.2 | GE29: 0.2 | GF29: 0.2 | GG29: 0.2 | GH29: 0.2 | GI29: 0.2 | GJ29: 0.2 | GK29: 0.2 | GL29: 0.2 | GS29: 2 | GT29: 0.2 | GU29: 0.2 | GV29: 0.2 | GW29: 0.2 | GX29: 0.2 | GY29: 0.2 | GZ29: 0.2 | HA29: 0.2 | HB29: 0.2 | HC29: 0.2 | HD29: 0.2 | HE29: 0.2 | HF29: 0.2 | HG29: 0.2 | HH29: 0.2
C30: 3 | D30: =$B$27 | E30: =$B$27 | F30: =$B$27 | G30: =$B$27 | H30: =$B$27 | I30: =$B$27 | J30: =$B$27 | K30: =$B$27 | ... R30: =$B$27 | Y30: 3 | Z30: 0.2 | AA30: 0.2 | AB30: 0.2 | AC30: 0.2 | AD30: 0.2 | AE30: 0.2 | AF30: 0.2 | AG30: 0.2 | AH30: 0.2 | AI30: 0.2 | AJ30: 0.2 | AK30: 0.2 | AL30: 0.2 | AM30: 0.2 | AN30: 0.2 | AU30: 3 | AV30: 0.2 | AW30: 0.2 | AX30: 0.2 | AY30: 0.2 | AZ30: 0.2 | BA30: 0.2 | BB30: 0.2 | BC30: 0.2 | BD30: 0.2 | BE30: 0.2 | BF30: 0.2 | BG30: 0.2 | BH30: 0.2 | BI30: 0.2 | BJ30: 0.2 | BQ30: 3 | BR30: 0.2 | BS30: 0.2 | BT30: 0.2 | BU30: 0.2 | BV30: 0.2 | BW30: 0.2 | BX30: 0.2 | BY30: 0.2 | BZ30: 0.2 | CA30: 0.2 | CB30: 0.2 | CC30: 0.2 | CD30: 0.2 | CE30: 0.2 | CF30: 0.2 | CM30: 3 | CN30: 0.2 | CO30: 0.2 | CP30: 0.2 | CQ30: 0.2 | CR30: 0.2 | CS30: 0.2 | CT30: 0.2 | CU30: 0.2 | CV30: 0.2 | CW30: 0.2 | CX30: 0.2 | CY30: 0.2 | CZ30: 0.2 | DA30: 0.2 | DB30: 0.2 | DI30: 3 | DJ30: 0.2 | DK30: 0.2 | DL30: 0.2 | DM30: 0.2 | DN30: 0.2 | DO30: 0.2 | DP30: 0.2 | DQ30: 0.2 | DR30: 0.2 | DS30: 0.2 | DT30: 0.2 | DU30: 0.2 | DV30: 0.2 | DW30: 0.2 | DX30: 0.2 | EE30: 3 | EF30: 0.2 | EG30: 0.2 | EH30: 0.2 | EI30: 0.2 | EJ30: 0.2 | EK30: 0.2 | EL30: 0.2 | EM30: 0.2 | EN30: 0.2 | EO30: 0.2 | EP30: 0.2 | EQ30: 0.2 | ER30: 0.2 | ES30: 0.2 | ET30: 0.2 | FA30: 3 | FB30: 0.2 | FC30: 0.2 | FD30: 0.2 | FE30: 0.2 | FF30: 0.2 | FG30: 0.2 | FH30: 0.2 | FI30: 0.2 | FJ30: 0.2 | FK30: 0.2 | FL30: 0.2 | FM30: 0.2 | FN30: 0.2 | FO30: 0.2 | FP30: 0.2 | FW30: 3 | FX30: 0.2 | FY30: 0.2 | FZ30: 0.2 | GA30: 0.2 | GB30: 0.2 | GC30: 0.2 | GD30: 0.2 | GE30: 0.2 | GF30: 0.2 | GG30: 0.2 | GH30: 0.2 | GI30: 0.2 | GJ30: 0.2 | GK30: 0.2 | GL30: 0.2 | GS30: 3 | GT30: 0.2 | GU30: 0.2 | GV30: 0.2 | GW30: 0.2 | GX30: 0.2 | GY30: 0.2 | GZ30: 0.2 | HA30: 0.2 | HB30: 0.2 | HC30: 0.2 | HD30: 0.2 | HE30: 0.2 | HF30: 0.2 | HG30: 0.2 | HH30: 0.2
B32: =Data!D31 | C32: Planned Stock | D32: 1 | E32: 2 | F32: 3 | G32: 4 | H32: 5 | I32: 6 | J32: 7 | K32: 8 | L32: 9 | M32: 10 | N32: 11 | O32: 12 | P32: 13 | Q32: 14 | R32: 15 | Y32: Planned Stock | Z32: 1 | AA32: 2 | AB32: 3 | AC32: 4 | AD32: 5 | AE32: 6 | AF32: 7 | AG32: 8 | AH32: 9 | AI32: 10 | AJ32: 11 | AK32: 12 | AL32: 13 | AM32: 14 | AN32: 15 | AU32: Planned Stock | AV32: 1 | AW32: 2 | AX32: 3 | AY32: 4 | AZ32: 5 | BA32: 6 | BB32: 7 | BC32: 8 | BD32: 9 | BE32: 10 | BF32: 11 | BG32: 12 | BH32: 13 | BI32: 14 | BJ32: 15 | BQ32: Planned Stock | BR32: 1 | BS32: 2 | BT32: 3 | BU32: 4 | BV32: 5 | BW32: 6 | BX32: 7 | BY32: 8 | BZ32: 9 | CA32: 10 | CB32: 11 | CC32: 12 | CD32: 13 | CE32: 14 | CF32: 15 | CM32: Planned Stock | CN32: 1 | CO32: 2 | CP32: 3 | CQ32: 4 | CR32: 5 | CS32: 6 | CT32: 7 | CU32: 8 | CV32: 9 | CW32: 10 | CX32: 11 | CY32: 12 | CZ32: 13 | DA32: 14 | DB32: 15 | DI32: Planned Stock | DJ32: 1 | DK32: 2 | DL32: 3 | DM32: 4 | DN32: 5 | DO32: 6 | DP32: 7 | DQ32: 8 | DR32: 9 | DS32: 10 | DT32: 11 | DU32: 12 | DV32: 13 | DW32: 14 | DX32: 15 | EE32: Planned Stock | EF32: 1 | EG32: 2 | EH32: 3 | EI32: 4 | EJ32: 5 | EK32: 6 | EL32: 7 | EM32: 8 | EN32: 9 | EO32: 10 | EP32: 11 | EQ32: 12 | ER32: 13 | ES32: 14 | ET32: 15 | FA32: Planned Stock | FB32: 1 | FC32: 2 | FD32: 3 | FE32: 4 | FF32: 5 | FG32: 6 | FH32: 7 | FI32: 8 | FJ32: 9 | FK32: 10 | FL32: 11 | FM32: 12 | FN32: 13 | FO32: 14 | FP32: 15 | FW32: Planned Stock | FX32: 1 | FY32: 2 | FZ32: 3 | GA32: 4 | GB32: 5 | GC32: 6 | GD32: 7 | GE32: 8 | GF32: 9 | GG32: 10 | GH32: 11 | GI32: 12 | GJ32: 13 | GK32: 14 | GL32: 15 | GS32: Planned Stock | GT32: 1 | GU32: 2 | GV32: 3 | GW32: 4 | GX32: 5 | GY32: 6 | GZ32: 7 | HA32: 8 | HB32: 9 | HC32: 10 | HD32: 11 | HE32: 12 | HF32: 13 | HG32: 14 | HH32: 15
C33: 1 | D33: =$B$32 | E33: =$B$32 | F33: =$B$32 | G33: =$B$32 | H33: =$B$32 | I33: =$B$32 | J33: =$B$32 | K33: =$B$32 | ... R33: =$B$32 | Y33: 1 | Z33: 1 | AA33: 1 | AB33: 1 | AC33: 1 | AD33: 1 | AE33: 1 | AF33: 1 | AG33: 1 | AH33: 1 | AI33: 1 | AJ33: 1 | AK33: 1 | AL33: 1 | AM33: 1 | AN33: 1 | AU33: 1 | AV33: 1 | AW33: 1 | AX33: 1 | AY33: 1 | AZ33: 1 | BA33: 1 | BB33: 1 | BC33: 1 | BD33: 1 | BE33: 1 | BF33: 1 | BG33: 1 | BH33: 1 | BI33: 1 | BJ33: 1 | BQ33: 1 | BR33: 1 | BS33: 1 | BT33: 1 | BU33: 1 | BV33: 1 | BW33: 1 | BX33: 1 | BY33: 1 | BZ33: 1 | CA33: 1 | CB33: 1 | CC33: 1 | CD33: 1 | CE33: 1 | CF33: 1 | CM33: 1 | CN33: 0.7 | CO33: 0.7 | CP33: 0.7 | CQ33: 0.7 | CR33: 0.7 | CS33: 0.7 | CT33: 0.7 | CU33: 0.7 | CV33: 0.7 | CW33: 0.7 | CX33: 0.7 | CY33: 0.7 | CZ33: 0.7 | DA33: 0.7 | DB33: 0.7 | DI33: 1 | DJ33: 0.7 | DK33: 0.7 | DL33: 0.7 | DM33: 0.7 | DN33: 0.7 | DO33: 0.7 | DP33: 0.7 | DQ33: 0.7 | DR33: 0.7 | DS33: 0.7 | DT33: 0.7 | DU33: 0.7 | DV33: 0.7 | DW33: 0.7 | DX33: 0.7 | EE33: 1 | EF33: 0.7 | EG33: 0.7 | EH33: 0.7 | EI33: 0.7 | EJ33: 0.7 | EK33: 0.7 | EL33: 0.7 | EM33: 0.7 | EN33: 0.7 | EO33: 0.7 | EP33: 0.7 | EQ33: 0.7 | ER33: 0.7 | ES33: 0.7 | ET33: 0.7 | FA33: 1 | FB33: 0.4 | FC33: 0.4 | FD33: 0.4 | FE33: 0.4 | FF33: 0.4 | FG33: 0.4 | FH33: 0.4 | FI33: 0.4 | FJ33: 0.4 | FK33: 0.4 | FL33: 0.4 | FM33: 0.4 | FN33: 0.4 | FO33: 0.4 | FP33: 0.4 | FW33: 1 | FX33: 0.4 | FY33: 0.4 | FZ33: 0.4 | GA33: 0.4 | GB33: 0.4 | GC33: 0.4 | GD33: 0.4 | GE33: 0.4 | GF33: 0.4 | GG33: 0.4 | GH33: 0.4 | GI33: 0.4 | GJ33: 0.4 | GK33: 0.4 | GL33: 0.4 | GS33: 1 | GT33: 0.4 | GU33: 0.4 | GV33: 0.4 | GW33: 0.4 | GX33: 0.4 | GY33: 0.4 | GZ33: 0.4 | HA33: 0.4 | HB33: 0.4 | HC33: 0.4 | HD33: 0.4 | HE33: 0.4 | HF33: 0.4 | HG33: 0.4 | HH33: 0.4
C34: 2 | D34: =$B$32 | E34: =$B$32 | F34: =$B$32 | G34: =$B$32 | H34: =$B$32 | I34: =$B$32 | J34: =$B$32 | K34: =$B$32 | ... R34: =$B$32 | Y34: 2 | Z34: 1 | AA34: 1 | AB34: 1 | AC34: 1 | AD34: 1 | AE34: 1 | AF34: 1 | AG34: 1 | AH34: 1 | AI34: 1 | AJ34: 1 | AK34: 1 | AL34: 1 | AM34: 1 | AN34: 1 | AU34: 2 | AV34: 1 | AW34: 1 | AX34: 1 | AY34: 1 | AZ34: 1 | BA34: 1 | BB34: 1 | BC34: 1 | BD34: 1 | BE34: 1 | BF34: 1 | BG34: 1 | BH34: 1 | BI34: 1 | BJ34: 1 | BQ34: 2 | BR34: 1 | BS34: 1 | BT34: 1 | BU34: 1 | BV34: 1 | BW34: 1 | BX34: 1 | BY34: 1 | BZ34: 1 | CA34: 1 | CB34: 1 | CC34: 1 | CD34: 1 | CE34: 1 | CF34: 1 | CM34: 2 | CN34: 0.7 | CO34: 0.7 | CP34: 0.7 | CQ34: 0.7 | CR34: 0.7 | CS34: 0.7 | CT34: 0.7 | CU34: 0.7 | CV34: 0.7 | CW34: 0.7 | CX34: 0.7 | CY34: 0.7 | CZ34: 0.7 | DA34: 0.7 | DB34: 0.7 | DI34: 2 | DJ34: 0.7 | DK34: 0.7 | DL34: 0.7 | DM34: 0.7 | DN34: 0.7 | DO34: 0.7 | DP34: 0.7 | DQ34: 0.7 | DR34: 0.7 | DS34: 0.7 | DT34: 0.7 | DU34: 0.7 | DV34: 0.7 | DW34: 0.7 | DX34: 0.7 | EE34: 2 | EF34: 0.7 | EG34: 0.7 | EH34: 0.7 | EI34: 0.7 | EJ34: 0.7 | EK34: 0.7 | EL34: 0.7 | EM34: 0.7 | EN34: 0.7 | EO34: 0.7 | EP34: 0.7 | EQ34: 0.7 | ER34: 0.7 | ES34: 0.7 | ET34: 0.7 | FA34: 2 | FB34: 0.4 | FC34: 0.4 | FD34: 0.4 | FE34: 0.4 | FF34: 0.4 | FG34: 0.4 | FH34: 0.4 | FI34: 0.4 | FJ34: 0.4 | FK34: 0.4 | FL34: 0.4 | FM34: 0.4 | FN34: 0.4 | FO34: 0.4 | FP34: 0.4 | FW34: 2 | FX34: 0.4 | FY34: 0.4 | FZ34: 0.4 | GA34: 0.4 | GB34: 0.4 | GC34: 0.4 | GD34: 0.4 | GE34: 0.4 | GF34: 0.4 | GG34: 0.4 | GH34: 0.4 | GI34: 0.4 | GJ34: 0.4 | GK34: 0.4 | GL34: 0.4 | GS34: 2 | GT34: 0.4 | GU34: 0.4 | GV34: 0.4 | GW34: 0.4 | GX34: 0.4 | GY34: 0.4 | GZ34: 0.4 | HA34: 0.4 | HB34: 0.4 | HC34: 0.4 | HD34: 0.4 | HE34: 0.4 | HF34: 0.4 | HG34: 0.4 | HH34: 0.4
