Workbook
Name Distributors_Stock_Begining: Distributors_stock_balance!$D$10:$F$11
Name Distributors_Stock_Demand: Distributors_stock_balance!$D$16:$F$17
Name Distributors_Stock_Replenishment: Distributors_stock_balance!$D$5:$F$6
Name DistributorsBegStock: Beginning_stock!$AT$25:$AV$26
Name DistributorsCap: Distributors_Cap!$D$13:$F$14
Name DistributorsCost: Distributors!$P$6:$R$7
Name DistributorsDem: Demand!$AU$19:$AW$20
Name DistributorsLeadTime: Distributors!$P$16:$R$17
Name DistributorsNumberBinaryVarY: Distributors_Cap!$D$29:$F$30
Name DistributorsSafetyFactor: Distributors!$P$21:$R$22
Name DistributorsStdDev: Distributors!$P$11:$R$12
Name DistributorsUpperBound: Distributors_Cap!$D$22:$F$23
Name Fac_Qtd_LB: Matlab_Data!$D$98:$F$100
Name Factories_Coverage_Time: Factories_stock_balance!$D$28:$F$30
Name Factories_Delta: Factories_stock_balance!$D$34:$F$36
Name Factories_Gamma: Factories_stock_balance!$D$45:$F$47
Name Factories_Gross_Base_Stock: Factories_stock_balance!$D$212:$F$214
Name Factories_Net_Demand: Factories_stock_balance!$D$200:$F$202
Name Factories_Omega: Factories_stock_balance!$D$57:$F$59
Name Factories_Omega1: Factories_stock_balance!$D$110:$F$112
Name Factories_Omega2: Factories_stock_balance!$D$116:$F$118
Name Factories_Omega3: Factories_stock_balance!$D$122:$F$124
Name Factories_Omega4: Factories_stock_balance!$D$140:$F$142
Name Factories_Omega5: Factories_stock_balance!$D$146:$F$148
Name Factories_Omega6: Factories_stock_balance!$D$152:$F$154
Name Factories_Replenishment_Time: Factories_stock_balance!$D$22:$F$24
Name Factories_Rho: Factories_stock_balance!$D$51:$F$53
Name Factories_Runout_Time: Factories_stock_balance!$D$63:$F$65
Name Factories_Safety_Stock: Factories_stock_balance!$D$230:$F$232
Name Factories_Squared_root: Factories_stock_balance!$D$182:$F$184
Name Factories_Variance_NetDemand_Rate: Factories_stock_balance!$D$218:$F$220
Name Factories_Work_in_process: Factories_WIP!$D$8:$F$10
Name Factories_Zeta: Factories_stock_balance!$D$39:$F$41
Name FactoriesBegStock: Beginning_stock!$AT$15:$AV$17
Name FactoriesCap: Factories_Cap!$D$8:$F$10
Name FactoriesCost: Factories!$I$6:$K$8
Name FactoriesDem: Demand!$AU$11:$AW$13
Name FactoriesLeadTime: Factories!$I$22:$K$24
Name FactoriesLeadTimeStdDev: Factories!$I$27:$K$29
Name FactoriesNumberBinaryVarY: Factories_Cap!$D$55:$F$57
Name FactoriesStdDev: Factories!$I$17:$K$19
Name FactoriesStdDevVarVar: Fac_Fourth_central_moment_5var!$D$41:$F$43
Name FactoriesUpperBound: Factories_Cap!#REF!
Name InboundServiceTimef: Factories_Cap!$D$33:$F$35
Name InboundServiceTimew: Suppliers_Cap!$D$33:$R$35
Name Maxd: Distributors_Cap!$D$35
Name Maxf: Factories_Cap!#REF!
Name Maxr: Retailers_Cap!$AN$9
Name MaxStkOutd: Distributors_Cap!$R$47
Name MaxStkOutf: Factories_Cap!#REF!
Name MaxStkOutr: Retailers_Cap!$CQ$7
Name MaxStkOutw: Suppliers_Cap!$V$25
Name MaxStkOutw1: Suppliers_Cap!$V$19
Name MaxStkOutw2: Suppliers_Cap!$V$20
Name MaxStkOutw3: Suppliers_Cap!$V$21
Name Maxw: Suppliers_Cap!$D$61
Name Mind: Distributors_Cap!$D$36
Name Minf: Factories_Cap!#REF!
Name Minr: Retailers_Cap!$AN$10
Name Minw: Suppliers_Cap!$D$62

Sheet Matlab_Data
C1: SUPPLIERS
C2: demand | D2: 1 | E2: 2 | F2: 3 | G2: 4 | H2: 5 | I2: 6 | J2: 7 | K2: 8 | L2: 9 | M2: 10 | N2: 11 | O2: 12 | P2: 13 | Q2: 14 | R2: 15
C3: 1 | D3: =Demand!AU5 | E3: =Demand!AV5 | F3: =Demand!AW5 | G3: =Demand!AX5 | H3: =Demand!AY5 | I3: =Demand!AZ5 | J3: =Demand!BA5 | K3: =Demand!BB5 | ... R3: =Demand!BI5
C4: 2 | D4: =Demand!AU6 | E4: =Demand!AV6 | F4: =Demand!AW6 | G4: =Demand!AX6 | H4: =Demand!AY6 | I4: =Demand!AZ6 | J4: =Demand!BA6 | K4: =Demand!BB6 | ... R4: =Demand!BI6
C5: 3 | D5: =Demand!AU7 | E5: =Demand!AV7 | F5: =Demand!AW7 | G5: =Demand!AX7 | H5: =Demand!AY7 | I5: =Demand!AZ7 | J5: =Demand!BA7 | K5: =Demand!BB7 | ... R5: =Demand!BI7
B7: Parâmetro p/ | C7: Média(E(RLT)) | D7: 1 | E7: 2 | F7: 3 | G7: 4 | H7: 5 | I7: 6 | J7: 7 | K7: 8 | L7: 9 | M7: 10 | N7: 11 | O7: 12 | P7: 13 | Q7: 14 | R7: 15
B8: LBw e DesvPad(ND*RLT)w | C8: 1 | D8: =Suppliers!I22 | E8: =Suppliers!J22 | F8: =Suppliers!K22 | G8: =Suppliers!L22 | H8: =Suppliers!M22 | I8: =Suppliers!N22 | J8: =Suppliers!O22 | K8: =Suppliers!P22 | ... R8: =Suppliers!W22
B9: LBw e DesvPad(ND*RLT)w | C9: 2 | D9: =Suppliers!I23 | E9: =Suppliers!J23 | F9: =Suppliers!K23 | G9: =Suppliers!L23 | H9: =Suppliers!M23 | I9: =Suppliers!N23 | J9: =Suppliers!O23 | K9: =Suppliers!P23 | ... R9: =Suppliers!W23
B10: LBw e DesvPad(ND*RLT)w | C10: 3 | D10: =Suppliers!I24 | E10: =Suppliers!J24 | F10: =Suppliers!K24 | G10: =Suppliers!L24 | H10: =Suppliers!M24 | I10: =Suppliers!N24 | J10: =Suppliers!O24 | K10: =Suppliers!P24 | ... R10: =Suppliers!W24
C12: Cap | D12: 1 | E12: 2 | F12: 3 | G12: 4 | H12: 5 | I12: 6 | J12: 7 | K12: 8 | L12: 9 | M12: 10 | N12: 11 | O12: 12 | P12: 13 | Q12: 14 | R12: 15
C13: 1 | D13: =Suppliers_Cap!D8 | E13: =Suppliers_Cap!E8 | F13: =Suppliers_Cap!F8 | G13: =Suppliers_Cap!G8 | H13: =Suppliers_Cap!H8 | I13: =Suppliers_Cap!I8 | J13: =Suppliers_Cap!J8 | K13: =Suppliers_Cap!K8 | ... R13: =Suppliers_Cap!R8
C14: 2 | D14: =Suppliers_Cap!D9 | E14: =Suppliers_Cap!E9 | F14: =Suppliers_Cap!F9 | G14: =Suppliers_Cap!G9 | H14: =Suppliers_Cap!H9 | I14: =Suppliers_Cap!I9 | J14: =Suppliers_Cap!J9 | K14: =Suppliers_Cap!K9 | ... R14: =Suppliers_Cap!R9
C15: 3 | D15: =Suppliers_Cap!D10 | E15: =Suppliers_Cap!E10 | F15: =Suppliers_Cap!F10 | G15: =Suppliers_Cap!G10 | H15: =Suppliers_Cap!H10 | I15: =Suppliers_Cap!I10 | J15: =Suppliers_Cap!J10 | K15: =Suppliers_Cap!K10 | ... R15: =Suppliers_Cap!R10
B17: Parâmetro p/ | C17: Var(d-cap) | D17: 1 | E17: 2 | F17: 3 | G17: 4 | H17: 5 | I17: 6 | J17: 7 | K17: 8 | L17: 9 | M17: 10 | N17: 11 | O17: 12 | P17: 13 | Q17: 14 | R17: 15
B18: LBw | C18: 1 | H18: 495,6908 | I18: 191.8181 | K18: 428.2391 | L18: 341.0413 | N18: 498.37 | P18: 217.8175 | Q18: 186.7283 | R18: 592.9769
B19: LBw | C19: 2 | D19: 282,9083 | E19: 213,6979 | H19: 388,8702 | I19: 422.6212 | J19: 252.569 | M19: 195.9797 | O19: 362.7987 | P19: 237.9285 | Q19: 507.6638 | R19: 435.1991
B20: LBw | C20: 3 | D20: 467,0644 | G20: 583,1530 | I20: 466.8862 | J20: 270.8028 | N20: 263.1016 | O20: 275.0038 | R20: 362.3392
B22: Parâmetro p/ | C22: Desvpad(Var(S2nd)) | D22: 1 | E22: 2 | F22: 3 | G22: 4 | H22: 5 | I22: 6 | J22: 7 | K22: 8 | L22: 9 | M22: 10 | N22: 11 | O22: 12 | P22: 13 | Q22: 14 | R22: 15
B23: LBw | C23: 1 | H23: 277.3852 | I23: 114.4701 | K23: 251.6818 | L23: 197.052 | N23: 277.4759 | P23: 123.9421 | Q23: 109.4126 | R23: 346.4116
B24: LBw | C24: 2 | D24: 160.9752 | E24: 121.0452 | H24: 217.2882 | I24: 239.086 | J24: 140.5445 | M24: 112.6414 | O24: 205.8108 | P24: 135.1195 | Q24: 284.6164 | R24: 247.6234
B25: LBw | C25: 3 | D25: 278.6301 | G25: 331.4884 | I25: 286.2747 | J25: 169.9887 | N25: 158.1255 | O25: 153.0895 | R25: 206.0767
B27: Parâmetro p/ | C27: DesvPad(Var(E(RLT))) | D27: 1 | E27: 2 | F27: 3 | G27: 4 | H27: 5 | I27: 6 | J27: 7 | K27: 8 | L27: 9 | M27: 10 | N27: 11 | O27: 12 | P27: 13 | Q27: 14 | R27: 15
B28: LBw e DesvPad(ND*RLT)w | C28: 1 | D28: =Suppliers!I27 | E28: =Suppliers!J27 | F28: =Suppliers!K27 | G28: =Suppliers!L27 | H28: =Suppliers!M27 | I28: =Suppliers!N27 | J28: =Suppliers!O27 | K28: =Suppliers!P27 | ... R28: =Suppliers!W27
B29: LBw e DesvPad(ND*RLT)w | C29: 2 | D29: =Suppliers!I28 | E29: =Suppliers!J28 | F29: =Suppliers!K28 | G29: =Suppliers!L28 | H29: =Suppliers!M28 | I29: =Suppliers!N28 | J29: =Suppliers!O28 | K29: =Suppliers!P28 | ... R29: =Suppliers!W28
B30: LBw e DesvPad(ND*RLT)w | C30: 3 | D30: =Suppliers!I29 | E30: =Suppliers!J29 | F30: =Suppliers!K29 | G30: =Suppliers!L29 | H30: =Suppliers!M29 | I30: =Suppliers!N29 | J30: =Suppliers!O29 | K30: =Suppliers!P29 | ... R30: =Suppliers!W29
B32: Parâmetro p/ | C32: Média(d-Cap) | D32: 1 | E32: 2 | F32: 3 | G32: 4 | H32: 5 | I32: 6 | J32: 7 | K32: 8 | L32: 9 | M32: 10 | N32: 11 | O32: 12 | P32: 13 | Q32: 14 | R32: 15
B33: DesvPad(ND*RLT)w | C33: 1 | D33: -73.1 | E33: -38.88 | F33: -149.55 | G33: -107.98 | H33: 46.7 | I33: 106.17 | J33: -136.97 | K33: 138.53 | L33: 101.27 | M33: -29.22 | N33: 16.77 | O33: -25.31 | P33: 61.7 | Q33: 88.71 | R33: 153.07
B34: DesvPad(ND*RLT)w | C34: 2 | D34: 70.27 | E34: 54.39 | F34: -69.22 | G34: -226.34 | H34: 35.69 | I34: 73.7 | J34: 6.16 | K34: -78.02 | L34: -76.38 | M34: 70.93 | N34: -108.97 | O34: 73.87 | P34: 61.51 | Q34: 54.4 | R34: 87.11
B35: DesvPad(ND*RLT)w | C35: 3 | D35: 165.21 | E35: -98.88 | F35: -171.21 | G35: 98.58 | H35: -96.51 | I35: 199.62 | J35: 173.01 | K35: -61.47 | L35: -130.21 | M35: -32.69 | N35: 131.25 | O35: 11.11 | P35: -98.85 | Q35: -44.68 | R35: 78.68
B37: Parâmetro p/ | C37: DesvPad(Var(d-cap)) | D37: 1 | E37: 2 | F37: 3 | G37: 4 | H37: 5 | I37: 6 | J37: 7 | K37: 8 | L37: 9 | M37: 10 | N37: 11 | O37: 12 | P37: 13 | Q37: 14 | R37: 15
B38: DesvPad(ND*RLT)w | C38: 1 | D38: =D18^0.5 | E38: =E18^0.5 | F38: =F18^0.5 | G38: =G18^0.5 | H38: =H18^0.5 | I38: =I18^0.5 | J38: =J18^0.5 | K38: =K18^0.5 | ... R38: =R18^0.5
B39: DesvPad(ND*RLT)w | C39: 2 | D39: =D19^0.5 | E39: =E19^0.5 | F39: =F19^0.5 | G39: =G19^0.5 | H39: =H19^0.5 | I39: =I19^0.5 | J39: =J19^0.5 | K39: =K19^0.5 | ... R39: =R19^0.5
B40: DesvPad(ND*RLT)w | C40: 3 | D40: =D20^0.5 | E40: =E20^0.5 | F40: =F20^0.5 | G40: =G20^0.5 | H40: =H20^0.5 | I40: =I20^0.5 | J40: =J20^0.5 | K40: =K20^0.5 | ... R40: =R20^0.5
C42: Prob1 | D42: 0.98
C44: LBw | D44: 1 | E44: 2 | F44: 3 | G44: 4 | H44: 5 | I44: 6 | J44: 7 | K44: 8 | L44: 9 | M44: 10 | N44: 11 | O44: 12 | P44: 13 | Q44: 14 | R44: 15
C45: 1 | D45: -1000 | E45: 0 | F45: 0 | G45: 0 | H45: 15818.302 | I45: 6132.0093 | J45: 0 | K45: 13708.849 | L45: 9372.3396 | M45: 0 | N45: 14327.465 | O45: 0 | P45: 6918.3969 | Q45: 5897.5627 | R45: 21002.39
C46: 2 | D46: 8074.1812 | E46: 8186.4463 | F46: 0 | G46: 0 | H46: 9834.2635 | I46: 14601.568 | J46: 6563.4316 | K46: 0 | L46: 0 | M46: 5627.9126 | N46: 0 | O46: 12387.656 | P46: 10079.393 | Q46: 19670.323 | R46: 12770.938
C47: 3 | D47: 19048.847 | E47: 0 | F47: 0 | G47: 17725.552 | H47: 0 | I47: 18633.411 | J47: 7876.7163 | K47: 0 | L47: 0 | M47: 0 | N47: 6106.9843 | O47: 8295.8778 | P47: 0 | Q47: 0 | R47: 10070.459
C49: DesvPad(ND*RLT)w | D49: 1 | E49: 2 | F49: 3 | G49: 4 | H49: 5 | I49: 6 | J49: 7 | K49: 8 | L49: 9 | M49: 10 | N49: 11 | O49: 12 | P49: 13 | Q49: 14 | R49: 15
C50: 1 | D50: 0 | E50: 0 | F50: 0 | G50: 0 | H50: 89.3519 | I50: 58.127 | J50: 0 | K50: 86.0169 | L50: 70.3036 | M50: 0 | N50: 84.7408 | O50: 0 | P50: 59.7737 | Q50: 56.3029 | R50: 106.0337
...

Sheet Estado da arte
C1: SUPPLIERS
B2: Parâmetros p/ | C2: demand | D2: 1 | E2: 2 | F2: 3 | G2: 4 | H2: 5 | I2: 6 | J2: 7 | K2: 8 | L2: 9 | M2: 10 | N2: 11 | O2: 12 | P2: 13 | Q2: 14 | R2: 15
B3: Prob(D*RLT) | C3: 1 | D3: =Demand!AU5 | E3: =Demand!AV5 | F3: =Demand!AW5 | G3: =Demand!AX5 | H3: =Demand!AY5 | I3: =Demand!AZ5 | J3: =Demand!BA5 | K3: =Demand!BB5 | ... R3: =Demand!BI5
B4: Prob(D*RLT) | C4: 2 | D4: =Demand!AU6 | E4: =Demand!AV6 | F4: =Demand!AW6 | G4: =Demand!AX6 | H4: =Demand!AY6 | I4: =Demand!AZ6 | J4: =Demand!BA6 | K4: =Demand!BB6 | ... R4: =Demand!BI6
B5: Prob(D*RLT) | C5: 3 | D5: =Demand!AU7 | E5: =Demand!AV7 | F5: =Demand!AW7 | G5: =Demand!AX7 | H5: =Demand!AY7 | I5: =Demand!AZ7 | J5: =Demand!BA7 | K5: =Demand!BB7 | ... R5: =Demand!BI7
A6: CV
A7: 0.2 | B7: Parâmetros | C7: DesvPad(demand) | D7: 1 | E7: 2 | F7: 3 | G7: 4 | H7: 5 | I7: 6 | J7: 7 | K7: 8 | L7: 9 | M7: 10 | N7: 11 | O7: 12 | P7: 13 | Q7: 14 | R7: 15
B8: Prob(D*RLT) | C8: 1 | D8: =D3*0.2 | E8: =E3*0.2 | F8: =F3*0.2 | G8: =G3*0.2 | H8: =H3*0.2 | I8: =I3*0.2 | J8: =J3*0.2 | K8: =K3*0.2 | ... R8: =R3*0.2
B9: Prob(D*RLT) | C9: 2 | D9: =D4*0.2 | E9: =E4*0.2 | F9: =F4*0.2 | G9: =G4*0.2 | H9: =H4*0.2 | I9: =I4*0.2 | J9: =J4*0.2 | K9: =K4*0.2 | ... R9: =R4*0.2
B10: Prob(D*RLT) | C10: 3 | D10: =D5*0.2 | E10: =E5*0.2 | F10: =F5*0.2 | G10: =G5*0.2 | H10: =H5*0.2 | I10: =I5*0.2 | J10: =J5*0.2 | K10: =K5*0.2 | ... R10: =R5*0.2
B12: Parâmetros | C12: Média(E(RLT)) | D12: 1 | E12: 2 | F12: 3 | G12: 4 | H12: 5 | I12: 6 | J12: 7 | K12: 8 | L12: 9 | M12: 10 | N12: 11 | O12: 12 | P12: 13 | Q12: 14 | R12: 15
B13: Prob(D*RLT) | C13: 1 | D13: =Suppliers!I22 | E13: =Suppliers!J22 | F13: =Suppliers!K22 | G13: =Suppliers!L22 | H13: =Suppliers!M22 | I13: =Suppliers!N22 | J13: =Suppliers!O22 | K13: =Suppliers!P22 | ... R13: =Suppliers!W22
B14: Prob(D*RLT) | C14: 2 | D14: =Suppliers!I23 | E14: =Suppliers!J23 | F14: =Suppliers!K23 | G14: =Suppliers!L23 | H14: =Suppliers!M23 | I14: =Suppliers!N23 | J14: =Suppliers!O23 | K14: =Suppliers!P23 | ... R14: =Suppliers!W23
B15: Prob(D*RLT) | C15: 3 | D15: =Suppliers!I24 | E15: =Suppliers!J24 | F15: =Suppliers!K24 | G15: =Suppliers!L24 | H15: =Suppliers!M24 | I15: =Suppliers!N24 | J15: =Suppliers!O24 | K15: =Suppliers!P24 | ... R15: =Suppliers!W24
A17: CV | B17: Parâmetros | C17: DesvPad(Média(RLT)) | D17: 1 | E17: 2 | F17: 3 | G17: 4 | H17: 5 | I17: 6 | J17: 7 | K17: 8 | L17: 9 | M17: 10 | N17: 11 | O17: 12 | P17: 13 | Q17: 14 | R17: 15
A18: 0.2 | B18: Prob(D*RLT) | C18: 1 | D18: =D13*0.2 | E18: =E13*0.2 | F18: =F13*0.2 | G18: =G13*0.2 | H18: =H13*0.2 | I18: =I13*0.2 | J18: =J13*0.2 | K18: =K13*0.2 | ... R18: =R13*0.2
B19: Prob(D*RLT) | C19: 2 | D19: =D14*0.2 | E19: =E14*0.2 | F19: =F14*0.2 | G19: =G14*0.2 | H19: =H14*0.2 | I19: =I14*0.2 | J19: =J14*0.2 | K19: =K14*0.2 | ... R19: =R14*0.2
B20: Prob(D*RLT) | C20: 3 | D20: =D15*0.2 | E20: =E15*0.2 | F20: =F15*0.2 | G20: =G15*0.2 | H20: =H15*0.2 | I20: =I15*0.2 | J20: =J15*0.2 | K20: =K15*0.2 | ... R20: =R15*0.2
C23: z | D23: 2.06
C25: DesvPad | D25: 1 | E25: 2 | F25: 3 | G25: 4 | H25: 5 | I25: 6 | J25: 7 | K25: 8 | L25: 9 | M25: 10 | N25: 11 | O25: 12 | P25: 13 | Q25: 14 | R25: 15
C26: 1 | D26: =(D13*(D8^2)+(D3^2)*(D18^2))^0.5 | E26: =(E13*(E8^2)+(E3^2)*(E18^2))^0.5 | F26: =(F13*(F8^2)+(F3^2)*(F18^2))^0.5 | G26: =(G13*(G8^2)+(G3^2)*(G18^2))^0.5 | H26: =(H13*(H8^2)+(H3^2)*(H18^2))^0.5 | I26: =(I13*(I8^2)+(I3^2)*(I18^2))^0.5 | J26: =(J13*(J8^2)+(J3^2)*(J18^2))^0.5 | K26: =(K13*(K8^2)+(K3^2)*(K18^2))^0.5 | ... R26: =(R13*(R8^2)+(R3^2)*(R18^2))^0.5
C27: 2 | D27: =(D14*(D9^2)+(D4^2)*(D19^2))^0.5 | E27: =(E14*(E9^2)+(E4^2)*(E19^2))^0.5 | F27: =(F14*(F9^2)+(F4^2)*(F19^2))^0.5 | G27: =(G14*(G9^2)+(G4^2)*(G19^2))^0.5 | H27: =(H14*(H9^2)+(H4^2)*(H19^2))^0.5 | I27: =(I14*(I9^2)+(I4^2)*(I19^2))^0.5 | J27: =(J14*(J9^2)+(J4^2)*(J19^2))^0.5 | K27: =(K14*(K9^2)+(K4^2)*(K19^2))^0.5 | ... R27: =(R14*(R9^2)+(R4^2)*(R19^2))^0.5
C28: 3 | D28: =(D15*(D10^2)+(D5^2)*(D20^2))^0.5 | E28: =(E15*(E10^2)+(E5^2)*(E20^2))^0.5 | F28: =(F15*(F10^2)+(F5^2)*(F20^2))^0.5 | G28: =(G15*(G10^2)+(G5^2)*(G20^2))^0.5 | H28: =(H15*(H10^2)+(H5^2)*(H20^2))^0.5 | I28: =(I15*(I10^2)+(I5^2)*(I20^2))^0.5 | J28: =(J15*(J10^2)+(J5^2)*(J20^2))^0.5 | K28: =(K15*(K10^2)+(K5^2)*(K20^2))^0.5 | ... R28: =(R15*(R10^2)+(R5^2)*(R20^2))^0.5
C30: Média(Demand*RLT) | D30: 1 | E30: 2 | F30: 3 | G30: 4 | H30: 5 | I30: 6 | J30: 7 | K30: 8 | L30: 9 | M30: 10 | N30: 11 | O30: 12 | P30: 13 | Q30: 14 | R30: 15
C31: 1 | D31: =D3*D13 | E31: =E3*E13 | F31: =F3*F13 | G31: =G3*G13 | H31: =H3*H13 | I31: =I3*I13 | J31: =J3*J13 | K31: =K3*K13 | ... R31: =R3*R13
C32: 2 | D32: =D4*D14 | E32: =E4*E14 | F32: =F4*F14 | G32: =G4*G14 | H32: =H4*H14 | I32: =I4*I14 | J32: =J4*J14 | K32: =K4*K14 | ... R32: =R4*R14
C33: 3 | D33: =D5*D15 | E33: =E5*E15 | F33: =F5*F15 | G33: =G5*G15 | H33: =H5*H15 | I33: =I5*I15 | J33: =J5*J15 | K33: =K5*K15 | ... R33: =R5*R15
B35: Parâmetro p/ c | C35: Reposição | D35: 1 | E35: 2 | F35: 3 | G35: 4 | H35: 5 | I35: 6 | J35: 7 | K35: 8 | L35: 9 | M35: 10 | N35: 11 | O35: 12 | P35: 13 | Q35: 14 | R35: 15
B36: Prob(D*RLT) | C36: 1 | D36: =D31+$D$23*D26 | E36: =E31+$D$23*E26 | F36: =F31+$D$23*F26 | G36: =G31+$D$23*G26 | H36: =H31+$D$23*H26 | I36: =I31+$D$23*I26 | J36: =J31+$D$23*J26 | K36: =K31+$D$23*K26 | ... R36: =R31+$D$23*R26
B37: Prob(D*RLT) | C37: 2 | D37: =D32+$D$23*D27 | E37: =E32+$D$23*E27 | F37: =F32+$D$23*F27 | G37: =G32+$D$23*G27 | H37: =H32+$D$23*H27 | I37: =I32+$D$23*I27 | J37: =J32+$D$23*J27 | K37: =K32+$D$23*K27 | ... R37: =R32+$D$23*R27
B38: Prob(D*RLT) | C38: 3 | D38: =D33+$D$23*D28 | E38: =E33+$D$23*E28 | F38: =F33+$D$23*F28 | G38: =G33+$D$23*G28 | H38: =H33+$D$23*H28 | I38: =I33+$D$23*I28 | J38: =J33+$D$23*J28 | K38: =K33+$D$23*K28 | ... R38: =R33+$D$23*R28
C40: Factories
B41: Parâmetros p/ | C41: demand | D41: 16 | E41: 17 | F41: 18
B42: Prob(D*RLT) | C42: 4 | D42: =Demand!AU11 | E42: =Demand!AV11 | F42: =Demand!AW11
B43: Prob(D*RLT) | C43: 5 | D43: =Demand!AU12 | E43: =Demand!AV12 | F43: =Demand!AW12
B44: Prob(D*RLT) | C44: 6 | D44: =Demand!AU13 | E44: =Demand!AV13 | F44: =Demand!AW13
B46: Parâmetros | C46: DesvPad(demand) | D46: 16 | E46: 17 | F46: 18
B47: Prob(D*RLT) | C47: 4 | D47: =D42*0.2 | E47: =E42*0.2 | F47: =F42*0.2
B48: Prob(D*RLT) | C48: 5 | D48: =D43*0.2 | E48: =E43*0.2 | F48: =F43*0.2
B49: Prob(D*RLT) | C49: 6 | D49: =D44*0.2 | E49: =E44*0.2 | F49: =F44*0.2
...

Sheet Factories_WIP
C2: Wipf | D2: 1 | E2: 2 | F2: 3
C3: 1 | D3: =Factories!I22 | E3: =Factories!J22 | F3: =Factories!K22
C4: 2 | D4: =Factories!I23 | E4: =Factories!J23 | F4: =Factories!K23
C5: 3 | D5: =Factories!I24 | E5: =Factories!J24 | F5: =Factories!K24
C7: Wipf | D7: 1 | E7: 2 | F7: 3
C8: 1 | D8: 4.889 | E8: 6.521 | F8: 4.091
C9: 2 | D9: 3.548 | E9: 6.734 | F9: 4.237
C10: 3 | D10: 4.35 | E10: 5.496 | F10: 4.967

Sheet Supp_Fourth_central_moment_5var
D3: 1 | E3: 2 | F3: 3 | G3: 4 | H3: 5 | I3: 6 | J3: 7 | K3: 8 | L3: 9 | M3: 10 | N3: 11 | O3: 12 | P3: 13 | Q3: 14 | R3: 15
B4: Var(d) | C4: 1 | D4: =TRUNC(((Demand!AU5*0.2)^2),4) | E4: =TRUNC(((Demand!AV5*0.2)^2),4) | F4: =TRUNC(((Demand!AW5*0.2)^2),4) | G4: =TRUNC(((Demand!AX5*0.2)^2),4) | H4: =TRUNC(((Demand!AY5*0.2)^2),4) | I4: =TRUNC(((Demand!AZ5*0.2)^2),4) | J4: =TRUNC(((Demand!BA5*0.2)^2),4) | K4: =TRUNC(((Demand!BB5*0.2)^2),4) | ... R4: =TRUNC(((Demand!BI5*0.2)^2),4)
C5: 2 | D5: =TRUNC(((Demand!AU6*0.2)^2),4) | E5: =TRUNC(((Demand!AV6*0.2)^2),4) | F5: =TRUNC(((Demand!AW6*0.2)^2),4) | G5: =TRUNC(((Demand!AX6*0.2)^2),4) | H5: =TRUNC(((Demand!AY6*0.2)^2),4) | I5: =TRUNC(((Demand!AZ6*0.2)^2),4) | J5: =TRUNC(((Demand!BA6*0.2)^2),4) | K5: =TRUNC(((Demand!BB6*0.2)^2),4) | ... R5: =TRUNC(((Demand!BI6*0.2)^2),4)
C6: 3 | D6: =TRUNC(((Demand!AU7*0.2)^2),4) | E6: =TRUNC(((Demand!AV7*0.2)^2),4) | F6: =TRUNC(((Demand!AW7*0.2)^2),4) | G6: =TRUNC(((Demand!AX7*0.2)^2),4) | H6: =TRUNC(((Demand!AY7*0.2)^2),4) | I6: =TRUNC(((Demand!AZ7*0.2)^2),4) | J6: =TRUNC(((Demand!BA7*0.2)^2),4) | K6: =TRUNC(((Demand!BB7*0.2)^2),4) | ... R6: =TRUNC(((Demand!BI7*0.2)^2),4)
D9: 1 | E9: 2 | F9: 3 | G9: 4 | H9: 5 | I9: 6 | J9: 7 | K9: 8 | L9: 9 | M9: 10 | N9: 11 | O9: 12 | P9: 13 | Q9: 14 | R9: 15
B10: Var(Cap) | C10: 1 | D10: =TRUNC(((Suppliers_Cap!D8*0.2)^2),4) | E10: =TRUNC(((Suppliers_Cap!E8*0.2)^2),4) | F10: =TRUNC(((Suppliers_Cap!F8*0.2)^2),4) | G10: =TRUNC(((Suppliers_Cap!G8*0.2)^2),4) | H10: =TRUNC(((Suppliers_Cap!H8*0.2)^2),4) | I10: =TRUNC(((Suppliers_Cap!I8*0.2)^2),4) | J10: =TRUNC(((Suppliers_Cap!J8*0.2)^2),4) | K10: =TRUNC(((Suppliers_Cap!K8*0.2)^2),4) | ... R10: =TRUNC(((Suppliers_Cap!R8*0.2)^2),4)
C11: 2 | D11: =TRUNC(((Suppliers_Cap!D9*0.2)^2),4) | E11: =TRUNC(((Suppliers_Cap!E9*0.2)^2),4) | F11: =TRUNC(((Suppliers_Cap!F9*0.2)^2),4) | G11: =TRUNC(((Suppliers_Cap!G9*0.2)^2),4) | H11: =TRUNC(((Suppliers_Cap!H9*0.2)^2),4) | I11: =TRUNC(((Suppliers_Cap!I9*0.2)^2),4) | J11: =TRUNC(((Suppliers_Cap!J9*0.2)^2),4) | K11: =TRUNC(((Suppliers_Cap!K9*0.2)^2),4) | ... R11: =TRUNC(((Suppliers_Cap!R9*0.2)^2),4)
C12: 3 | D12: =TRUNC(((Suppliers_Cap!D10*0.2)^2),4) | E12: =TRUNC(((Suppliers_Cap!E10*0.2)^2),4) | F12: =TRUNC(((Suppliers_Cap!F10*0.2)^2),4) | G12: =TRUNC(((Suppliers_Cap!G10*0.2)^2),4) | H12: =TRUNC(((Suppliers_Cap!H10*0.2)^2),4) | I12: =TRUNC(((Suppliers_Cap!I10*0.2)^2),4) | J12: =TRUNC(((Suppliers_Cap!J10*0.2)^2),4) | K12: =TRUNC(((Suppliers_Cap!K10*0.2)^2),4) | ... R12: =TRUNC(((Suppliers_Cap!R10*0.2)^2),4)
B14: n | C14: 7
B15: m | C15: 30
D17: 1 | E17: 2 | F17: 3 | G17: 4 | H17: 5 | I17: 6 | J17: 7 | K17: 8 | L17: 9 | M17: 10 | N17: 11 | O17: 12 | P17: 13 | Q17: 14 | R17: 15
B18: Var(Var(d)) | C18: 1 | D18: =TRUNC((1/$C$14)*(5*(D4^2)-((($C$14-3)/($C$14-1))*D4^2)),4) | E18: =TRUNC((1/$C$14)*(5*(E4^2)-((($C$14-3)/($C$14-1))*E4^2)),4) | F18: =TRUNC((1/$C$14)*(5*(F4^2)-((($C$14-3)/($C$14-1))*F4^2)),4) | G18: =TRUNC((1/$C$14)*(5*(G4^2)-((($C$14-3)/($C$14-1))*G4^2)),4) | H18: =TRUNC((1/$C$14)*(5*(H4^2)-((($C$14-3)/($C$14-1))*H4^2)),4) | I18: =TRUNC((1/$C$14)*(5*(I4^2)-((($C$14-3)/($C$14-1))*I4^2)),4) | J18: =TRUNC((1/$C$14)*(5*(J4^2)-((($C$14-3)/($C$14-1))*J4^2)),4) | K18: =TRUNC((1/$C$14)*(5*(K4^2)-((($C$14-3)/($C$14-1))*K4^2)),4) | ... R18: =TRUNC((1/$C$14)*(5*(R4^2)-((($C$14-3)/($C$14-1))*R4^2)),4)
C19: 2 | D19: =TRUNC((1/$C$14)*(5*(D5^2)-((($C$14-3)/($C$14-1))*D5^2)),4) | E19: =TRUNC((1/$C$14)*(5*(E5^2)-((($C$14-3)/($C$14-1))*E5^2)),4) | F19: =TRUNC((1/$C$14)*(5*(F5^2)-((($C$14-3)/($C$14-1))*F5^2)),4) | G19: =TRUNC((1/$C$14)*(5*(G5^2)-((($C$14-3)/($C$14-1))*G5^2)),4) | H19: =TRUNC((1/$C$14)*(5*(H5^2)-((($C$14-3)/($C$14-1))*H5^2)),4) | I19: =TRUNC((1/$C$14)*(5*(I5^2)-((($C$14-3)/($C$14-1))*I5^2)),4) | J19: =TRUNC((1/$C$14)*(5*(J5^2)-((($C$14-3)/($C$14-1))*J5^2)),4) | K19: =TRUNC((1/$C$14)*(5*(K5^2)-((($C$14-3)/($C$14-1))*K5^2)),4) | ... R19: =TRUNC((1/$C$14)*(5*(R5^2)-((($C$14-3)/($C$14-1))*R5^2)),4)
C20: 3 | D20: =TRUNC((1/$C$14)*(5*(D6^2)-((($C$14-3)/($C$14-1))*D6^2)),4) | E20: =TRUNC((1/$C$14)*(5*(E6^2)-((($C$14-3)/($C$14-1))*E6^2)),4) | F20: =TRUNC((1/$C$14)*(5*(F6^2)-((($C$14-3)/($C$14-1))*F6^2)),4) | G20: =TRUNC((1/$C$14)*(5*(G6^2)-((($C$14-3)/($C$14-1))*G6^2)),4) | H20: =TRUNC((1/$C$14)*(5*(H6^2)-((($C$14-3)/($C$14-1))*H6^2)),4) | I20: =TRUNC((1/$C$14)*(5*(I6^2)-((($C$14-3)/($C$14-1))*I6^2)),4) | J20: =TRUNC((1/$C$14)*(5*(J6^2)-((($C$14-3)/($C$14-1))*J6^2)),4) | K20: =TRUNC((1/$C$14)*(5*(K6^2)-((($C$14-3)/($C$14-1))*K6^2)),4) | ... R20: =TRUNC((1/$C$14)*(5*(R6^2)-((($C$14-3)/($C$14-1))*R6^2)),4)
D23: 1 | E23: 2 | F23: 3 | G23: 4 | H23: 5 | I23: 6 | J23: 7 | K23: 8 | L23: 9 | M23: 10 | N23: 11 | O23: 12 | P23: 13 | Q23: 14 | R23: 15
B24: Var(Var(Cap)) | C24: 1 | D24: =TRUNC((1/$C$14)*(5*(D10^2)-((($C$14-3)/($C$14-1))*D10^2)),4) | E24: =TRUNC((1/$C$14)*(5*(E10^2)-((($C$14-3)/($C$14-1))*E10^2)),4) | F24: =TRUNC((1/$C$14)*(5*(F10^2)-((($C$14-3)/($C$14-1))*F10^2)),4) | G24: =TRUNC((1/$C$14)*(5*(G10^2)-((($C$14-3)/($C$14-1))*G10^2)),4) | H24: =TRUNC((1/$C$14)*(5*(H10^2)-((($C$14-3)/($C$14-1))*H10^2)),4) | I24: =TRUNC((1/$C$14)*(5*(I10^2)-((($C$14-3)/($C$14-1))*I10^2)),4) | J24: =TRUNC((1/$C$14)*(5*(J10^2)-((($C$14-3)/($C$14-1))*J10^2)),4) | K24: =TRUNC((1/$C$14)*(5*(K10^2)-((($C$14-3)/($C$14-1))*K10^2)),4) | ... R24: =TRUNC((1/$C$14)*(5*(R10^2)-((($C$14-3)/($C$14-1))*R10^2)),4)
C25: 2 | D25: =TRUNC((1/$C$14)*(5*(D11^2)-((($C$14-3)/($C$14-1))*D11^2)),4) | E25: =TRUNC((1/$C$14)*(5*(E11^2)-((($C$14-3)/($C$14-1))*E11^2)),4) | F25: =TRUNC((1/$C$14)*(5*(F11^2)-((($C$14-3)/($C$14-1))*F11^2)),4) | G25: =TRUNC((1/$C$14)*(5*(G11^2)-((($C$14-3)/($C$14-1))*G11^2)),4) | H25: =TRUNC((1/$C$14)*(5*(H11^2)-((($C$14-3)/($C$14-1))*H11^2)),4) | I25: =TRUNC((1/$C$14)*(5*(I11^2)-((($C$14-3)/($C$14-1))*I11^2)),4) | J25: =TRUNC((1/$C$14)*(5*(J11^2)-((($C$14-3)/($C$14-1))*J11^2)),4) | K25: =TRUNC((1/$C$14)*(5*(K11^2)-((($C$14-3)/($C$14-1))*K11^2)),4) | ... R25: =TRUNC((1/$C$14)*(5*(R11^2)-((($C$14-3)/($C$14-1))*R11^2)),4)
C26: 3 | D26: =TRUNC((1/$C$14)*(5*(D12^2)-((($C$14-3)/($C$14-1))*D12^2)),4) | E26: =TRUNC((1/$C$14)*(5*(E12^2)-((($C$14-3)/($C$14-1))*E12^2)),4) | F26: =TRUNC((1/$C$14)*(5*(F12^2)-((($C$14-3)/($C$14-1))*F12^2)),4) | G26: =TRUNC((1/$C$14)*(5*(G12^2)-((($C$14-3)/($C$14-1))*G12^2)),4) | H26: =TRUNC((1/$C$14)*(5*(H12^2)-((($C$14-3)/($C$14-1))*H12^2)),4) | I26: =TRUNC((1/$C$14)*(5*(I12^2)-((($C$14-3)/($C$14-1))*I12^2)),4) | J26: =TRUNC((1/$C$14)*(5*(J12^2)-((($C$14-3)/($C$14-1))*J12^2)),4) | K26: =TRUNC((1/$C$14)*(5*(K12^2)-((($C$14-3)/($C$14-1))*K12^2)),4) | ... R26: =TRUNC((1/$C$14)*(5*(R12^2)-((($C$14-3)/($C$14-1))*R12^2)),4)
D28: 1 | E28: 2 | F28: 3 | G28: 4 | H28: 5 | I28: 6 | J28: 7 | K28: 8 | L28: 9 | M28: 10 | N28: 11 | O28: 12 | P28: 13 | Q28: 14 | R28: 15
B29: Var(soma das Var) | C29: 1 | D29: =TRUNC((D18+D24)*((1/$C$15)^2),4) | E29: =TRUNC((E18+E24)*((1/$C$15)^2),4) | F29: =TRUNC((F18+F24)*((1/$C$15)^2),4) | G29: =TRUNC((G18+G24)*((1/$C$15)^2),4) | H29: =TRUNC((H18+H24)*((1/$C$15)^2),4) | I29: =TRUNC((I18+I24)*((1/$C$15)^2),4) | J29: =TRUNC((J18+J24)*((1/$C$15)^2),4) | K29: =TRUNC((K18+K24)*((1/$C$15)^2),4) | ... R29: =TRUNC((R18+R24)*((1/$C$15)^2),4)
C30: 2 | D30: =TRUNC((D19+D25)*((1/$C$15)^2),4) | E30: =TRUNC((E19+E25)*((1/$C$15)^2),4) | F30: =TRUNC((F19+F25)*((1/$C$15)^2),4) | G30: =TRUNC((G19+G25)*((1/$C$15)^2),4) | H30: =TRUNC((H19+H25)*((1/$C$15)^2),4) | I30: =TRUNC((I19+I25)*((1/$C$15)^2),4) | J30: =TRUNC((J19+J25)*((1/$C$15)^2),4) | K30: =TRUNC((K19+K25)*((1/$C$15)^2),4) | ... R30: =TRUNC((R19+R25)*((1/$C$15)^2),4)
C31: 3 | D31: =TRUNC((D20+D26)*((1/$C$15)^2),4) | E31: =TRUNC((E20+E26)*((1/$C$15)^2),4) | F31: =TRUNC((F20+F26)*((1/$C$15)^2),4) | G31: =TRUNC((G20+G26)*((1/$C$15)^2),4) | H31: =TRUNC((H20+H26)*((1/$C$15)^2),4) | I31: =TRUNC((I20+I26)*((1/$C$15)^2),4) | J31: =TRUNC((J20+J26)*((1/$C$15)^2),4) | K31: =TRUNC((K20+K26)*((1/$C$15)^2),4) | ... R31: =TRUNC((R20+R26)*((1/$C$15)^2),4)
D34: 1 | E34: 2 | F34: 3 | G34: 4 | H34: 5 | I34: 6 | J34: 7 | K34: 8 | L34: 9 | M34: 10 | N34: 11 | O34: 12 | P34: 13 | Q34: 14 | R34: 15
C35: 1 | D35: =TRUNC(D29^0.5,4) | E35: =TRUNC(E29^0.5,4) | F35: =TRUNC(F29^0.5,4) | G35: =TRUNC(G29^0.5,4) | H35: =TRUNC(H29^0.5,4) | I35: =TRUNC(I29^0.5,4) | J35: =TRUNC(J29^0.5,4) | K35: =TRUNC(K29^0.5,4) | ... R35: =TRUNC(R29^0.5,4)
C36: 2 | D36: =TRUNC(D30^0.5,4) | E36: =TRUNC(E30^0.5,4) | F36: =TRUNC(F30^0.5,4) | G36: =TRUNC(G30^0.5,4) | H36: =TRUNC(H30^0.5,4) | I36: =TRUNC(I30^0.5,4) | J36: =TRUNC(J30^0.5,4) | K36: =TRUNC(K30^0.5,4) | ... R36: =TRUNC(R30^0.5,4)
C37: 3 | D37: =TRUNC(D31^0.5,4) | E37: =TRUNC(E31^0.5,4) | F37: =TRUNC(F31^0.5,4) | G37: =TRUNC(G31^0.5,4) | H37: =TRUNC(H31^0.5,4) | I37: =TRUNC(I31^0.5,4) | J37: =TRUNC(J31^0.5,4) | K37: =TRUNC(K31^0.5,4) | ... R37: =TRUNC(R31^0.5,4)
D40: 1 | E40: 2 | F40: 3 | G40: 4 | H40: 5 | I40: 6 | J40: 7 | K40: 8 | L40: 9 | M40: 10 | N40: 11 | O40: 12 | P40: 13 | Q40: 14 | R40: 15
B41: Desvpad(Var(soma das Var)) | C41: 1 | D41: 112.4037 | E41: 150.5519 | F41: 150.0761 | G41: 125.8954 | H41: 277.3852 | I41: 114.4701 | J41: 139.7176 | K41: 251.6818 | L41: 197.052 | M41: 181.9621 | N41: 277.4759 | O41: 84.7787 | P41: 123.9421 | Q41: 109.4126 | R41: 346.4116
C42: 2 | D42: 160.9752 | E42: 121.0452 | F42: 138.0701 | G42: 362.605 | H42: 217.2882 | I42: 239.086 | J42: 140.5445 | K42: 117.3 | L42: 178.8198 | M42: 112.6414 | N42: 177.7212 | O42: 205.8108 | P42: 135.1194 | Q42: 284.6164 | R42: 247.6234
C43: 3 | D43: 278.6301 | E43: 152.9252 | F43: 179.974 | G43: 331.4884 | H43: 161.8803 | I43: 286.2747 | J43: 169.9887 | K43: 215.3825 | L43: 182.4408 | M43: 125.2284 | N43: 158.1255 | O43: 153.0895 | P43: 233.367 | Q43: 206.1942 | R43: 206.0767

Sheet Fac_Fourth_central_moment_5var
D3: 1 | E3: 2 | F3: 3
B4: Var(d) | C4: 1 | D4: =TRUNC(((Demand!AU11*0.2)^2),2) | E4: =TRUNC(((Demand!AV11*0.2)^2),2) | F4: =TRUNC(((Demand!AW11*0.2)^2),2)
C5: 2 | D5: =TRUNC(((Demand!AU12*0.2)^2),2) | E5: =TRUNC(((Demand!AV12*0.2)^2),2) | F5: =TRUNC(((Demand!AW12*0.2)^2),2)
C6: 3 | D6: =TRUNC(((Demand!AU13*0.2)^2),2) | E6: =TRUNC(((Demand!AV13*0.2)^2),2) | F6: =TRUNC(((Demand!AW13*0.2)^2),2)
D9: 1 | E9: 2 | F9: 3
B10: Var(Cap) | C10: 1 | D10: =TRUNC(((Factories_Cap!D8*0.2)^2),2) | E10: =TRUNC(((Factories_Cap!E8*0.2)^2),2) | F10: =TRUNC(((Factories_Cap!F8*0.2)^2),2)
C11: 2 | D11: =TRUNC(((Factories_Cap!D9*0.2)^2),2) | E11: =TRUNC(((Factories_Cap!E9*0.2)^2),2) | F11: =TRUNC(((Factories_Cap!F9*0.2)^2),2)
C12: 3 | D12: =TRUNC(((Factories_Cap!D10*0.2)^2),2) | E12: =TRUNC(((Factories_Cap!E10*0.2)^2),2) | F12: =TRUNC(((Factories_Cap!F10*0.2)^2),2)
B14: n | C14: 7
B15: m | C15: 30
D17: 1 | E17: 2 | F17: 3
B18: Var(Var(d)) | C18: 1 | D18: =TRUNC((1/$C$14)*(5*(D4^2)-((($C$14-3)/($C$14-1))*D4^2)),2) | E18: =TRUNC((1/$C$14)*(5*(E4^2)-((($C$14-3)/($C$14-1))*E4^2)),2) | F18: =TRUNC((1/$C$14)*(5*(F4^2)-((($C$14-3)/($C$14-1))*F4^2)),2)
C19: 2 | D19: =TRUNC((1/$C$14)*(5*(D5^2)-((($C$14-3)/($C$14-1))*D5^2)),2) | E19: =TRUNC((1/$C$14)*(5*(E5^2)-((($C$14-3)/($C$14-1))*E5^2)),2) | F19: =TRUNC((1/$C$14)*(5*(F5^2)-((($C$14-3)/($C$14-1))*F5^2)),2)
C20: 3 | D20: =TRUNC((1/$C$14)*(5*(D6^2)-((($C$14-3)/($C$14-1))*D6^2)),2) | E20: =TRUNC((1/$C$14)*(5*(E6^2)-((($C$14-3)/($C$14-1))*E6^2)),2) | F20: =TRUNC((1/$C$14)*(5*(F6^2)-((($C$14-3)/($C$14-1))*F6^2)),2)
D23: 1 | E23: 2 | F23: 3
B24: Var(Var(Cap)) | C24: 1 | D24: =TRUNC((1/$C$14)*(5*(D10^2)-((($C$14-3)/($C$14-1))*D10^2)),2) | E24: =TRUNC((1/$C$14)*(5*(E10^2)-((($C$14-3)/($C$14-1))*E10^2)),2) | F24: =TRUNC((1/$C$14)*(5*(F10^2)-((($C$14-3)/($C$14-1))*F10^2)),2)
C25: 2 | D25: =TRUNC((1/$C$14)*(5*(D11^2)-((($C$14-3)/($C$14-1))*D11^2)),2) | E25: =TRUNC((1/$C$14)*(5*(E11^2)-((($C$14-3)/($C$14-1))*E11^2)),2) | F25: =TRUNC((1/$C$14)*(5*(F11^2)-((($C$14-3)/($C$14-1))*F11^2)),2)
C26: 3 | D26: =TRUNC((1/$C$14)*(5*(D12^2)-((($C$14-3)/($C$14-1))*D12^2)),2) | E26: =TRUNC((1/$C$14)*(5*(E12^2)-((($C$14-3)/($C$14-1))*E12^2)),2) | F26: =TRUNC((1/$C$14)*(5*(F12^2)-((($C$14-3)/($C$14-1))*F12^2)),2)
D28: 1 | E28: 2 | F28: 3
B29: Var(soma das Var) | C29: 1 | D29: =TRUNC((D18+D24)*((1/$C$15)^2),2) | E29: =TRUNC((E18+E24)*((1/$C$15)^2),2) | F29: =TRUNC((F18+F24)*((1/$C$15)^2),2)
C30: 2 | D30: =TRUNC((D19+D25)*((1/$C$15)^2),2) | E30: =TRUNC((E19+E25)*((1/$C$15)^2),2) | F30: =TRUNC((F19+F25)*((1/$C$15)^2),2)
C31: 3 | D31: =TRUNC((D20+D26)*((1/$C$15)^2),2) | E31: =TRUNC((E20+E26)*((1/$C$15)^2),2) | F31: =TRUNC((F20+F26)*((1/$C$15)^2),2)
D34: 1 | E34: 2 | F34: 3
C35: 1 | D35: =TRUNC(D29^0.5,2) | E35: =TRUNC(E29^0.5,2) | F35: =TRUNC(F29^0.5,2)
C36: 2 | D36: =TRUNC(D30^0.5,2) | E36: =TRUNC(E30^0.5,2) | F36: =TRUNC(F30^0.5,2)
C37: 3 | D37: =TRUNC(D31^0.5,2) | E37: =TRUNC(E31^0.5,2) | F37: =TRUNC(F31^0.5,2)
D40: 1 | E40: 2 | F40: 3
B41: Desvpad(Var(soma das Var)) | C41: 1 | D41: 4277.77 | E41: 3472.13 | F41: 4613.14
C42: 2 | D42: 2964.88 | E42: 2903.21 | F42: 6033.67
C43: 3 | D43: 3655.82 | E43: 2818.21 | F43: 5710.71

Sheet Results
C4: vSw | D4: 1 | E4: 2 | F4: 3 | G4: 4 | H4: 5 | I4: 6 | J4: 7 | K4: 8 | L4: 9 | M4: 10 | N4: 11 | O4: 12 | P4: 13 | Q4: 14 | R4: 15 | T4: Processamento atual
C5: 1 | D5: 0 | E5: 0 | F5: 0 | G5: 0 | H5: 0.36031306 | I5: 0.61848277 | J5: 0 | K5: 0 | L5: 0 | M5: 0 | N5: -56.04966 | O5: 0 | P5: 0 | Q5: 0.61301092 | R5: 0.68753182 | T5: 3189795.6
B6: MaxStockOutw | C6: 2 | D6: 0 | E6: 0 | F6: 0 | G6: 0 | H6: -36.154562 | I6: 0 | J6: -178.82909 | K6: 0 | L6: 0 | M6: 0 | N6: 0 | O6: 0.66606833 | P6: 0.098308882 | Q6: 0 | R6: 0
B7: =MaxStkOutw | C7: 3 | D7: 0.78899108 | E7: 0 | F7: 0 | G7: 0 | H7: 0 | I7: 0.76830148 | J7: 0.55724378 | K7: 0 | L7: 0 | M7: 0 | N7: 0.4485051 | O7: -103.17172 | P7: 0 | Q7: 0 | R7: 0
C9: vSf | D9: 16 | E9: 17 | F9: 18 | H9: Processamento atual
C10: 4 | D10: 0.2102503 | E10: 0.27443333 | F10: 0.17150194 | H10: 2135426.9
B11: MaxStockOutf | C11: 5 | D11: 0 | E11: 0.28070017 | F11: 0
B12: =MaxStkOutf | C12: 6 | D12: 8.3232882 | E12: 0.23867881 | F12: 9.0390984
C16: Sd | D16: 19 | E16: 20 | F16: 21
C17: 7 | D17: 0 | E17: 30.858508 | F17: 33.243508
B18: MaxStockOutd | C18: 8 | D18: 0 | E18: 29.193508 | F18: 4.2531253
B19: =MaxStkOutd
C20: Sr | D20: 22 | E20: 23 | F20: 24
C21: 9 | D21: 0 | E21: 0 | F21: 0
C22: 10 | D22: 88.906235 | E22: 91.990235 | F22: 1.8097652
C23: 11 | D23: 77.061235 | E23: 94.718235 | F23: 0
C24: 12 | D24: 78.244235 | E24: 81.456235 | F24: 78.675235
C25: 13 | D25: 0 | E25: 81.000235 | F25: 71.417235
C26: 14 | D26: 87.887235 | E26: 85.048235 | F26: 98.407235
C27: 15 | D27: 0 | E27: 71.301235 | F27: 0
C28: 16 | D28: 82.366235 | E28: 0 | F28: 0
C29: 17 | D29: 96.069235 | E29: 75.526235 | F29: 85.083235
C30: 18 | D30: 0 | E30: 85.508235 | F30: 81.738235
C31: 19 | D31: 61.443235 | E31: 93.442235 | F31: 94.468235
C32: 20 | D32: 75.650235 | E32: 62.140235 | F32: 108.86323
... C210: 198 | D210: 0 | E210: 0 | F210: 91.329235

Sheet Demand
D3: CÁLCULOS PARA A GERAÇÃO DOS DADOS DA DEMANDA | AU3: máximo | AV3: =MAX(SuppliersDem) | AX3: mínimo | AY3: =MIN(SuppliersDem)
A4: Mínimo | B4: Máximo | H4: 1 | I4: 2 | J4: 3 | K4: 4 | L4: 5 | M4: 6 | N4: 7 | O4: 8 | P4: 9 | Q4: 10 | R4: 11 | S4: 12 | T4: 13 | U4: 14 | V4: 15 | X4: Soma | AB4: 1 | AC4: 2 | AD4: 3 | AE4: 4 | AF4: 5 | AG4: 6 | AH4: 7 | AI4: 8 | AJ4: 9 | AK4: 10 | AL4: 11 | AM4: 12 | AN4: 13 | AO4: 14 | AP4: 15 | AU4: 1 | AV4: 2 | AW4: 3 | AX4: 4 | AY4: 5 | AZ4: 6 | BA4: 7 | BB4: 8 | BC4: 9 | BD4: 10 | BE4: 11 | BF4: 12 | BG4: 13 | BH4: 14 | BI4: 15
A5: =MIN(H5:V7) | B5: =MAX(H5:V7) | C5: prod/dia | D5: Avarege | E5: =(M24/3)/15 | F5: Dw | G5: 1 | H5: =TRUNC((_xlfn.NORM.INV((RAND()),$E$5,$E$6)),2) | I5: =TRUNC((_xlfn.NORM.INV((RAND()),$E$5,$E$6)),2) | J5: =TRUNC((_xlfn.NORM.INV((RAND()),$E$5,$E$6)),2) | K5: =TRUNC((_xlfn.NORM.INV((RAND()),$E$5,$E$6)),2) | L5: =TRUNC((_xlfn.NORM.INV((RAND()),$E$5,$E$6)),2) | M5: =TRUNC((_xlfn.NORM.INV((RAND()),$E$5,$E$6)),2) | N5: =TRUNC((_xlfn.NORM.INV((RAND()),$E$5,$E$6)),2) | O5: =TRUNC((_xlfn.NORM.INV((RAND()),$E$5,$E$6)),2) | ... V5: =TRUNC((_xlfn.NORM.INV((RAND()),$E$5,$E$6)),2) | X5: =SUM(H5:V7) | Z5: Dw | AA5: 1 | AB5: =IF(H5<0,0,H5) | AC5: =IF(I5<0,0,I5) | AD5: =IF(J5<0,0,J5) | AE5: =IF(K5<0,0,K5) | AF5: =IF(L5<0,0,L5) | AG5: =IF(M5<0,0,M5) | AH5: =IF(N5<0,0,N5) | AI5: =IF(O5<0,0,O5) | ... AP5: =IF(V5<0,0,V5) | AS5: Dw | AT5: 1 | AU5: 231.5 | AV5: 297.34 | AW5: 217.82 | AX5: 222.62 | AY5: 453.86 | AZ5: 315.98 | BA5: 216.18 | BB5: 463.97 | BC5: 404.65 | BD5: 334.69 | BE5: 440.61 | BF5: 225.39 | BG5: 314.98 | BH5: 305.23 | BI5: 541.84 | BK5: 361.01 | BL5: 440.66 | BM5: 451.17 | BN5: 402.32 | BO5: 281.5 | BP5: 339.37 | BQ5: 303.46 | BR5: 314.95 | BS5: 281.92 | BT5: 203.48 | BU5: 353.54 | BV5: 351.74 | BW5: 377.81 | BX5: 356.35 | BY5: 311.94
D6: Std Devition | E6: =E5*0.2 | G6: 2 | H6: =TRUNC((_xlfn.NORM.INV((RAND()),$E$5,$E$6)),2) | I6: =TRUNC((_xlfn.NORM.INV((RAND()),$E$5,$E$6)),2) | J6: =TRUNC((_xlfn.NORM.INV((RAND()),$E$5,$E$6)),2) | K6: =TRUNC((_xlfn.NORM.INV((RAND()),$E$5,$E$6)),2) | L6: =TRUNC((_xlfn.NORM.INV((RAND()),$E$5,$E$6)),2) | M6: =TRUNC((_xlfn.NORM.INV((RAND()),$E$5,$E$6)),2) | N6: =TRUNC((_xlfn.NORM.INV((RAND()),$E$5,$E$6)),2) | O6: =TRUNC((_xlfn.NORM.INV((RAND()),$E$5,$E$6)),2) | ... V6: =TRUNC((_xlfn.NORM.INV((RAND()),$E$5,$E$6)),2) | AA6: 2 | AB6: =IF(H6<0,0,H6) | AC6: =IF(I6<0,0,I6) | AD6: =IF(J6<0,0,J6) | AE6: =IF(K6<0,0,K6) | AF6: =IF(L6<0,0,L6) | AG6: =IF(M6<0,0,M6) | AH6: =IF(N6<0,0,N6) | AI6: =IF(O6<0,0,O6) | ... AP6: =IF(V6<0,0,V6) | AT6: 2 | AU6: 358.95 | AV6: 308.97 | AW6: 264.61 | AX6: 343.62 | AY6: 399.3 | AZ6: 433.24 | BA6: 310.82 | BB6: 234.15 | BC6: 302.73 | BD6: 304.23 | BE6: 278.95 | BF6: 403.93 | BG6: 327.87 | BH6: 462.67 | BI6: 445.18 | BK6: 385.45 | BL6: 425.64 | BM6: 333.38 | BN6: 353.53 | BO6: 376.65 | BP6: 369.96 | BQ6: 423.76 | BR6: 314.98 | BS6: 294.6 | BT6: 331.27 | BU6: 411.45 | BV6: 493.53 | BW6: 280.38 | BX6: 371.76 | BY6: 218.81
G7: 3 | H7: =TRUNC((_xlfn.NORM.INV((RAND()),$E$5,$E$6)),2) | I7: =TRUNC((_xlfn.NORM.INV((RAND()),$E$5,$E$6)),2) | J7: =TRUNC((_xlfn.NORM.INV((RAND()),$E$5,$E$6)),2) | K7: =TRUNC((_xlfn.NORM.INV((RAND()),$E$5,$E$6)),2) | L7: =TRUNC((_xlfn.NORM.INV((RAND()),$E$5,$E$6)),2) | M7: =TRUNC((_xlfn.NORM.INV((RAND()),$E$5,$E$6)),2) | N7: =TRUNC((_xlfn.NORM.INV((RAND()),$E$5,$E$6)),2) | O7: =TRUNC((_xlfn.NORM.INV((RAND()),$E$5,$E$6)),2) | ... V7: =TRUNC((_xlfn.NORM.INV((RAND()),$E$5,$E$6)),2) | AA7: 3 | AB7: =IF(H7<0,0,H7) | AC7: =IF(I7<0,0,I7) | AD7: =IF(J7<0,0,J7) | AE7: =IF(K7<0,0,K7) | AF7: =IF(L7<0,0,L7) | AG7: =IF(M7<0,0,M7) | AH7: =IF(N7<0,0,N7) | AI7: =IF(O7<0,0,O7) | ... AP7: =IF(V7<0,0,V7) | AT7: 3 | AU7: 492.88 | AV7: 260.36 | AW7: 232.33 | AX7: 514.32 | AY7: 271.63 | AZ7: 506.16 | BA7: 393.21 | BB7: 346.58 | BC7: 267.82 | BD7: 272.81 | BE7: 372.8 | BF7: 326.64 | BG7: 338.03 | BH7: 348.46 | BI7: 405.85 | BK7: 338.48 | BL7: 437.06 | BM7: 362.32 | BN7: 289.55 | BO7: 382.33 | BP7: 360.74 | BQ7: 472.64 | BR7: 368.89 | BS7: 340.48 | BT7: 262.16 | BU7: 294.05 | BV7: 342.07 | BW7: 326.48 | BX7: 287.92 | BY7: 496.34
AU9: máximo | AV9: =MAX(FactoriesDem) | AX9: mínimo | AY9: =MIN(FactoriesDem)
H10: 16 | I10: 17 | J10: 18 | L10: Soma | AB10: 16 | AC10: 17 | AD10: 18 | AU10: 16 | AV10: 17 | AW10: 18
A11: =MIN(H11:J15) | B11: =MAX(H11:J15) | C11: prod/dia | D11: Avarege | E11: =M24/9 | F11: df | G11: 4 | H11: =TRUNC((_xlfn.NORM.INV((RAND()),$E$11,$E$12)),2) | I11: =TRUNC((_xlfn.NORM.INV((RAND()),$E$11,$E$12)),2) | J11: =TRUNC((_xlfn.NORM.INV((RAND()),$E$11,$E$12)),2) | L11: =SUM(H11:J13) | Z11: df | AA11: 4 | AB11: =IF(H11<0,0,H11) | AC11: =IF(I11<0,0,I11) | AD11: =IF(J11<0,0,J11) | AS11: df | AT11: 4 | AU11: 1894.6 | AV11: 1607.87 | AW11: 1829.53
D12: Std Devition | E12: =E11*0.2 | G12: 5 | H12: =TRUNC((_xlfn.NORM.INV((RAND()),$E$11,$E$12)),2) | I12: =TRUNC((_xlfn.NORM.INV((RAND()),$E$11,$E$12)),2) | J12: =TRUNC((_xlfn.NORM.INV((RAND()),$E$11,$E$12)),2) | AA12: 5 | AB12: =IF(H12<0,0,H12) | AC12: =IF(I12<0,0,I12) | AD12: =IF(J12<0,0,J12) | AT12: 5 | AU12: 1303.06 | AV12: 1484.38 | AW12: 1783.87
G13: 6 | H13: =TRUNC((_xlfn.NORM.INV((RAND()),$E$11,$E$12)),2) | I13: =TRUNC((_xlfn.NORM.INV((RAND()),$E$11,$E$12)),2) | J13: =TRUNC((_xlfn.NORM.INV((RAND()),$E$11,$E$12)),2) | AA13: 6 | AB13: =IF(H13<0,0,H13) | AC13: =IF(I13<0,0,I13) | AD13: =IF(J13<0,0,J13) | AT13: 6 | AU13: 1377.91 | AV13: 1520.56 | AW13: 1301.6
AU17: máximo | AV17: =MAX(DistributorsDem) | AX17: mínimo | AY17: =MIN(DistributorsDem)
H18: 19 | I18: 20 | J18: 21 | L18: Soma | AB18: 19 | AC18: 20 | AD18: 21 | AU18: 19 | AV18: 20 | AW18: 21
A19: =MIN(H19:J20) | B19: =MAX(H19:J20) | C19: prod/dia | D19: Avarege | E19: =M24/6 | F19: dd | G19: 7 | H19: =TRUNC((_xlfn.NORM.INV((RAND()),$E$19,$E$20)),2) | I19: =TRUNC((_xlfn.NORM.INV((RAND()),$E$19,$E$20)),2) | J19: =TRUNC((_xlfn.NORM.INV((RAND()),$E$19,$E$20)),2) | L19: =SUM(H19:J20) | Z19: dd | AA19: 7 | AB19: =IF(H19<0,0,H19) | AC19: =IF(I19<0,0,I19) | AD19: =IF(J19<0,0,J19) | AS19: dd | AT19: 7 | AU19: 3023.48 | AV19: 2834 | AW19: 1344.56
D20: Std Devition | E20: =E19*0.2 | G20: 8 | H20: =TRUNC((_xlfn.NORM.INV((RAND()),$E$19,$E$20)),2) | I20: =TRUNC((_xlfn.NORM.INV((RAND()),$E$19,$E$20)),2) | J20: =TRUNC((_xlfn.NORM.INV((RAND()),$E$19,$E$20)),2) | AA20: 8 | AB20: =IF(H20<0,0,H20) | AC20: =IF(I20<0,0,I20) | AD20: =IF(J20<0,0,J20) | AT20: 8 | AU20: 2552.14 | AV20: 3550.35 | AW20: 2159.77
AU22: máximo | AV22: =MAX(RetailersDem) | AX22: mínimo | AY22: =MIN(RetailersDem)
H23: 22 | I23: 23 | J23: 24 | L23: Soma | AB23: 22 | AC23: 23 | AD23: 24 | AU23: 22 | AV23: 23 | AW23: 24
A24: =MIN(H24:J213) | B24: =MAX(H24:J213) | C24: prod/dia | D24: Avarege | E24: =(M24/570) | F24: dr | G24: 9 | H24: =TRUNC((_xlfn.NORM.INV((RAND()),$E$24,$E$25)),2) | I24: =TRUNC((_xlfn.NORM.INV((RAND()),$E$24,$E$25)),2) | J24: =TRUNC((_xlfn.NORM.INV((RAND()),$E$24,$E$25)),2) | L24: =SUM(H24:J213) | M24: =TRUNC(N24/365) | N24: 5500000 | Z24: dr | AA24: 9 | AB24: =IF(H24<0,0,H24) | AC24: =IF(I24<0,0,I24) | AD24: =IF(J24<0,0,J24) | AS24: dr | AT24: 9 | AU24: 29.02 | AV24: 33.29 | AW24: 22.61
D25: Std Devition | E25: =E24*0.2 | G25: 10 | H25: =TRUNC((_xlfn.NORM.INV((RAND()),$E$24,$E$25)),2) | I25: =TRUNC((_xlfn.NORM.INV((RAND()),$E$24,$E$25)),2) | J25: =TRUNC((_xlfn.NORM.INV((RAND()),$E$24,$E$25)),2) | AA25: 10 | AB25: =IF(H25<0,0,H25) | AC25: =IF(I25<0,0,I25) | AD25: =IF(J25<0,0,J25) | AT25: 10 | AU25: 24.59 | AV25: 22.04 | AW25: 30.58
G26: 11 | H26: =TRUNC((_xlfn.NORM.INV((RAND()),$E$24,$E$25)),2) | I26: =TRUNC((_xlfn.NORM.INV((RAND()),$E$24,$E$25)),2) | J26: =TRUNC((_xlfn.NORM.INV((RAND()),$E$24,$E$25)),2) | AA26: 11 | AB26: =IF(H26<0,0,H26) | AC26: =IF(I26<0,0,I26) | AD26: =IF(J26<0,0,J26) | AT26: 11 | AU26: 19.89 | AV26: 21.46 | AW26: 28.67
G27: 12 | H27: =TRUNC((_xlfn.NORM.INV((RAND()),$E$24,$E$25)),2) | I27: =TRUNC((_xlfn.NORM.INV((RAND()),$E$24,$E$25)),2) | J27: =TRUNC((_xlfn.NORM.INV((RAND()),$E$24,$E$25)),2) | AA27: 12 | AB27: =IF(H27<0,0,H27) | AC27: =IF(I27<0,0,I27) | AD27: =IF(J27<0,0,J27) | AT27: 12 | AU27: 30.66 | AV27: 29 | AW27: 33.54
G28: 13 | H28: =TRUNC((_xlfn.NORM.INV((RAND()),$E$24,$E$25)),2) | I28: =TRUNC((_xlfn.NORM.INV((RAND()),$E$24,$E$25)),2) | J28: =TRUNC((_xlfn.NORM.INV((RAND()),$E$24,$E$25)),2) | AA28: 13 | AB28: =IF(H28<0,0,H28) | AC28: =IF(I28<0,0,I28) | AD28: =IF(J28<0,0,J28) | AT28: 13 | AU28: 28.98 | AV28: 28.2 | AW28: 28.9
G29: 14 | H29: =TRUNC((_xlfn.NORM.INV((RAND()),$E$24,$E$25)),2) | I29: =TRUNC((_xlfn.NORM.INV((RAND()),$E$24,$E$25)),2) | J29: =TRUNC((_xlfn.NORM.INV((RAND()),$E$24,$E$25)),2) | AA29: 14 | AB29: =IF(H29<0,0,H29) | AC29: =IF(I29<0,0,I29) | AD29: =IF(J29<0,0,J29) | AT29: 14 | AU29: 28.47 | AV29: 28.79 | AW29: 17.89
G30: 15 | H30: =TRUNC((_xlfn.NORM.INV((RAND()),$E$24,$E$25)),2) | I30: =TRUNC((_xlfn.NORM.INV((RAND()),$E$24,$E$25)),2) | J30: =TRUNC((_xlfn.NORM.INV((RAND()),$E$24,$E$25)),2) | AA30: 15 | AB30: =IF(H30<0,0,H30) | AC30: =IF(I30<0,0,I30) | AD30: =IF(J30<0,0,J30) | AT30: 15 | AU30: 28.37 | AV30: 26.62 | AW30: 25.87
G31: 16 | H31: =TRUNC((_xlfn.NORM.INV((RAND()),$E$24,$E$25)),2) | I31: =TRUNC((_xlfn.NORM.INV((RAND()),$E$24,$E$25)),2) | J31: =TRUNC((_xlfn.NORM.INV((RAND()),$E$24,$E$25)),2) | AA31: 16 | AB31: =IF(H31<0,0,H31) | AC31: =IF(I31<0,0,I31) | AD31: =IF(J31<0,0,J31) | AT31: 16 | AU31: 18.59 | AV31: 26.92 | AW31: 39.39
G32: 17 | H32: =TRUNC((_xlfn.NORM.INV((RAND()),$E$24,$E$25)),2) | I32: =TRUNC((_xlfn.NORM.INV((RAND()),$E$24,$E$25)),2) | J32: =TRUNC((_xlfn.NORM.INV((RAND()),$E$24,$E$25)),2) | AA32: 17 | AB32: =IF(H32<0,0,H32) | AC32: =IF(I32<0,0,I32) | AD32: =IF(J32<0,0,J32) | AT32: 17 | AU32: 20.38 | AV32: 21.01 | AW32: 31.36
G33: 18 | H33: =TRUNC((_xlfn.NORM.INV((RAND()),$E$24,$E$25)),2) | I33: =TRUNC((_xlfn.NORM.INV((RAND()),$E$24,$E$25)),2) | J33: =TRUNC((_xlfn.NORM.INV((RAND()),$E$24,$E$25)),2) | AA33: 18 | AB33: =IF(H33<0,0,H33) | AC33: =IF(I33<0,0,I33) | AD33: =IF(J33<0,0,J33) | AT33: 18 | AU33: 24.96 | AV33: 25.72 | AW33: 10.03
G34: 19 | H34: =TRUNC((_xlfn.NORM.INV((RAND()),$E$24,$E$25)),2) | I34: =TRUNC((_xlfn.NORM.INV((RAND()),$E$24,$E$25)),2) | J34: =TRUNC((_xlfn.NORM.INV((RAND()),$E$24,$E$25)),2) | AA34: 19 | AB34: =IF(H34<0,0,H34) | AC34: =IF(I34<0,0,I34) | AD34: =IF(J34<0,0,J34) | AT34: 19 | AU34: 30.41 | AV34: 27.79 | AW34: 36.61
G35: 20 | H35: =TRUNC((_xlfn.NORM.INV((RAND()),$E$24,$E$25)),2) | I35: =TRUNC((_xlfn.NORM.INV((RAND()),$E$24,$E$25)),2) | J35: =TRUNC((_xlfn.NORM.INV((RAND()),$E$24,$E$25)),2) | AA35: 20 | AB35: =IF(H35<0,0,H35) | AC35: =IF(I35<0,0,I35) | AD35: =IF(J35<0,0,J35) | AT35: 20 | AU35: 24.68 | AV35: 13.47 | AW35: 25.93
G36: 21 | H36: =TRUNC((_xlfn.NORM.INV((RAND()),$E$24,$E$25)),2) | I36: =TRUNC((_xlfn.NORM.INV((RAND()),$E$24,$E$25)),2) | J36: =TRUNC((_xlfn.NORM.INV((RAND()),$E$24,$E$25)),2) | AA36: 21 | AB36: =IF(H36<0,0,H36) | AC36: =IF(I36<0,0,I36) | AD36: =IF(J36<0,0,J36) | AT36: 21 | AU36: 25.48 | AV36: 20.12 | AW36: 25.5
G37: 22 | H37: =TRUNC((_xlfn.NORM.INV((RAND()),$E$24,$E$25)),2) | I37: =TRUNC((_xlfn.NORM.INV((RAND()),$E$24,$E$25)),2) | J37: =TRUNC((_xlfn.NORM.INV((RAND()),$E$24,$E$25)),2) | AA37: 22 | AB37: =IF(H37<0,0,H37) | AC37: =IF(I37<0,0,I37) | AD37: =IF(J37<0,0,J37) | AT37: 22 | AU37: 35.44 | AV37: 19.51 | AW37: 34.99
... G213: 198 | H213: =TRUNC((_xlfn.NORM.INV((RAND()),$E$24,$E$25)),2) | I213: =TRUNC((_xlfn.NORM.INV((RAND()),$E$24,$E$25)),2) | J213: =TRUNC((_xlfn.NORM.INV((RAND()),$E$24,$E$25)),2) | AA213: 198 | AB213: =IF(H213<0,0,H213) | AC213: =IF(I213<0,0,I213) | AD213: =IF(J213<0,0,J213) | AT213: 198 | AU213: 28.89 | AV213: 31.66 | AW213: 24.67

Sheet Beginning_stock
H2: CÁLCULOS PARA A GERAÇÃO DOS DADOS DO ESTOQUE INICIAL | AS2: SUPPLIERS
AT3: máximo | AU3: =MAX(SuppliersBegStock) | AW3: mínimo | AX3: =MIN(SuppliersBegStock)
A4: Mínimo | B4: Máximo | H4: 1 | I4: 2 | J4: 3 | K4: 4 | L4: 5 | M4: 6 | N4: 7 | O4: 8 | P4: 9 | Q4: 10 | R4: 11 | S4: 12 | T4: 13 | U4: 14 | V4: 15 | X4: Soma | AA4: 1 | AB4: 2 | AC4: 3 | AD4: 4 | AE4: 5 | AF4: 6 | AG4: 7 | AH4: 8 | AI4: 9 | AJ4: 10 | AK4: 11 | AL4: 12 | AM4: 13 | AN4: 14 | AO4: 15 | AS4: Ei (p) | AT4: 1 | AU4: 2 | AV4: 3 | AW4: 4 | AX4: 5 | AY4: 6 | AZ4: 7 | BA4: 8 | BB4: 9 | BC4: 10 | BD4: 11 | BE4: 12 | BF4: 13 | BG4: 14 | BH4: 15
A5: =MIN(H5:V7) | B5: =MAX(H5:V7) | C5: prod | D5: Avarege | E5: =12.5*Suppliers_stock_balance!S200*Suppliers!E22 | G5: 1 | H5: =TRUNC((_xlfn.NORM.INV((RAND()),$E$5,$E$6)),2) | I5: =TRUNC((_xlfn.NORM.INV((RAND()),$E$5,$E$6)),2) | J5: =TRUNC((_xlfn.NORM.INV((RAND()),$E$5,$E$6)),2) | K5: =TRUNC((_xlfn.NORM.INV((RAND()),$E$5,$E$6)),2) | L5: =TRUNC((_xlfn.NORM.INV((RAND()),$E$5,$E$6)),2) | M5: =TRUNC((_xlfn.NORM.INV((RAND()),$E$5,$E$6)),2) | N5: =TRUNC((_xlfn.NORM.INV((RAND()),$E$5,$E$6)),2) | O5: =TRUNC((_xlfn.NORM.INV((RAND()),$E$5,$E$6)),2) | ... V5: =TRUNC((_xlfn.NORM.INV((RAND()),$E$5,$E$6)),2) | X5: =SUM(H5:V7) | Z5: 1 | AA5: =TRUNC(IF(H5<0,0,H5),0) | AB5: =TRUNC(IF(I5<0,0,I5),0) | AC5: =TRUNC(IF(J5<0,0,J5),0) | AD5: =TRUNC(IF(K5<0,0,K5),0) | AE5: =TRUNC(IF(L5<0,0,L5),0) | AF5: =TRUNC(IF(M5<0,0,M5),0) | AG5: =TRUNC(IF(N5<0,0,N5),0) | AH5: =TRUNC(IF(O5<0,0,O5),0) | ... AO5: =TRUNC(IF(V5<0,0,V5),0) | AR5: SupBegStock | AS5: 1 | AT5: 1202 | AU5: 868 | AV5: 1362 | AW5: 945 | AX5: 703 | AY5: 788 | AZ5: 881 | BA5: 2243 | BB5: 1711 | BC5: 1164 | BD5: 1164 | BE5: 922 | BF5: 1336 | BG5: 697 | BH5: 1565
D6: Std Devition | E6: =E5*0.33 | G6: 2 | H6: =TRUNC((_xlfn.NORM.INV((RAND()),$E$5,$E$6)),2) | I6: =TRUNC((_xlfn.NORM.INV((RAND()),$E$5,$E$6)),2) | J6: =TRUNC((_xlfn.NORM.INV((RAND()),$E$5,$E$6)),2) | K6: =TRUNC((_xlfn.NORM.INV((RAND()),$E$5,$E$6)),2) | L6: =TRUNC((_xlfn.NORM.INV((RAND()),$E$5,$E$6)),2) | M6: =TRUNC((_xlfn.NORM.INV((RAND()),$E$5,$E$6)),2) | N6: =TRUNC((_xlfn.NORM.INV((RAND()),$E$5,$E$6)),2) | O6: =TRUNC((_xlfn.NORM.INV((RAND()),$E$5,$E$6)),2) | ... V6: =TRUNC((_xlfn.NORM.INV((RAND()),$E$5,$E$6)),2) | Z6: 2 | AA6: =TRUNC(IF(H6<0,0,H6),0) | AB6: =TRUNC(IF(I6<0,0,I6),0) | AC6: =TRUNC(IF(J6<0,0,J6),0) | AD6: =TRUNC(IF(K6<0,0,K6),0) | AE6: =TRUNC(IF(L6<0,0,L6),0) | AF6: =TRUNC(IF(M6<0,0,M6),0) | AG6: =TRUNC(IF(N6<0,0,N6),0) | AH6: =TRUNC(IF(O6<0,0,O6),0) | ... AO6: =TRUNC(IF(V6<0,0,V6),0) | AS6: 2 | AT6: 1298 | AU6: 1064 | AV6: 932 | AW6: 894 | AX6: 1709 | AY6: 1509 | AZ6: 1176 | BA6: 1176 | BB6: 1182 | BC6: 1164 | BD6: 434 | BE6: 1040 | BF6: 1243 | BG6: 1319 | BH6: 1715
G7: 3 | H7: =TRUNC((_xlfn.NORM.INV((RAND()),$E$5,$E$6)),2) | I7: =TRUNC((_xlfn.NORM.INV((RAND()),$E$5,$E$6)),2) | J7: =TRUNC((_xlfn.NORM.INV((RAND()),$E$5,$E$6)),2) | K7: =TRUNC((_xlfn.NORM.INV((RAND()),$E$5,$E$6)),2) | L7: =TRUNC((_xlfn.NORM.INV((RAND()),$E$5,$E$6)),2) | M7: =TRUNC((_xlfn.NORM.INV((RAND()),$E$5,$E$6)),2) | N7: =TRUNC((_xlfn.NORM.INV((RAND()),$E$5,$E$6)),2) | O7: =TRUNC((_xlfn.NORM.INV((RAND()),$E$5,$E$6)),2) | ... V7: =TRUNC((_xlfn.NORM.INV((RAND()),$E$5,$E$6)),2) | Z7: 3 | AA7: =TRUNC(IF(H7<0,0,H7),0) | AB7: =TRUNC(IF(I7<0,0,I7),0) | AC7: =TRUNC(IF(J7<0,0,J7),0) | AD7: =TRUNC(IF(K7<0,0,K7),0) | AE7: =TRUNC(IF(L7<0,0,L7),0) | AF7: =TRUNC(IF(M7<0,0,M7),0) | AG7: =TRUNC(IF(N7<0,0,N7),0) | AH7: =TRUNC(IF(O7<0,0,O7),0) | ... AO7: =TRUNC(IF(V7<0,0,V7),0) | AS7: 3 | AT7: 1476 | AU7: 795 | AV7: 836 | AW7: 1505 | AX7: 1423 | AY7: 1525 | AZ7: 1114 | BA7: 401 | BB7: 2463 | BC7: 700 | BD7: 620 | BE7: 1302 | BF7: 1635 | BG7: 1288 | BH7: 1398
AS12: FACTORIES
AT13: máximo | AU13: =MAX(FactoriesBegStock) | AW13: mínimo | AX13: =MIN(FactoriesBegStock)
H14: 16 | I14: 17 | J14: 18 | L14: Soma | AA14: 16 | AB14: 17 | AC14: 18 | AS14: Ei (p) | AT14: 16 | AU14: 17 | AV14: 18
A15: =MIN(H15:J19) | B15: =MAX(H15:J19) | C15: prod/dia | D15: Avarege | E15: =Demand!E12 | G15: 4 | H15: =TRUNC((_xlfn.NORM.INV((RAND()),$E$15,$E$16)),2) | I15: =TRUNC((_xlfn.NORM.INV((RAND()),$E$15,$E$16)),2) | J15: =TRUNC((_xlfn.NORM.INV((RAND()),$E$15,$E$16)),2) | L15: =SUM(H15:J17) | Z15: 4 | AA15: =TRUNC(IF(H15<0,0,H15),0) | AB15: =TRUNC(IF(I15<0,0,I15),0) | AC15: =TRUNC(IF(J15<0,0,J15),0) | AR15: FacBegStock | AS15: 4 | AT15: 332 | AU15: 413 | AV15: 301
D16: Std Devition | E16: =E15*0.2 | G16: 5 | H16: =TRUNC((_xlfn.NORM.INV((RAND()),$E$15,$E$16)),2) | I16: =TRUNC((_xlfn.NORM.INV((RAND()),$E$15,$E$16)),2) | J16: =TRUNC((_xlfn.NORM.INV((RAND()),$E$15,$E$16)),2) | Z16: 5 | AA16: =TRUNC(IF(H16<0,0,H16),0) | AB16: =TRUNC(IF(I16<0,0,I16),0) | AC16: =TRUNC(IF(J16<0,0,J16),0) | AS16: 5 | AT16: 387 | AU16: 243 | AV16: 344
G17: 6 | H17: =TRUNC((_xlfn.NORM.INV((RAND()),$E$15,$E$16)),2) | I17: =TRUNC((_xlfn.NORM.INV((RAND()),$E$15,$E$16)),2) | J17: =TRUNC((_xlfn.NORM.INV((RAND()),$E$15,$E$16)),2) | Z17: 6 | AA17: =TRUNC(IF(H17<0,0,H17),0) | AB17: =TRUNC(IF(I17<0,0,I17),0) | AC17: =TRUNC(IF(J17<0,0,J17),0) | AS17: 6 | AT17: 320 | AU17: 300 | AV17: 308
AS22: DISTRIBUTORS
AT23: máximo | AU23: =MAX(DistributorsBegStock) | AW23: mínimo | AX23: =MIN(DistributorsBegStock)
H24: 19 | I24: 20 | J24: 21 | AA24: 19 | AB24: 20 | AC24: 21 | AS24: Ei (p) | AT24: 19 | AU24: 20 | AV24: 21
A25: =MIN(H25:J26) | B25: =MAX(H25:J26) | C25: prod/dia | D25: Avarege | E25: =Demand!E20 | G25: 7 | H25: =TRUNC((_xlfn.NORM.INV((RAND()),$E$25,$E$26)),2) | I25: =TRUNC((_xlfn.NORM.INV((RAND()),$E$25,$E$26)),2) | J25: =TRUNC((_xlfn.NORM.INV((RAND()),$E$25,$E$26)),2) | L25: =SUM(H25:J26) | Z25: 7 | AA25: =TRUNC(IF(H25<0,0,H25),0) | AB25: =TRUNC(IF(I25<0,0,I25),0) | AC25: =TRUNC(IF(J25<0,0,J25),0) | AR25: DistBegStock | AS25: 7 | AT25: 316 | AU25: 472 | AV25: 641
D26: Std Devition | E26: =E25*0.2 | G26: 8 | H26: =TRUNC((_xlfn.NORM.INV((RAND()),$E$25,$E$26)),2) | I26: =TRUNC((_xlfn.NORM.INV((RAND()),$E$25,$E$26)),2) | J26: =TRUNC((_xlfn.NORM.INV((RAND()),$E$25,$E$26)),2) | Z26: 8 | AA26: =TRUNC(IF(H26<0,0,H26),0) | AB26: =TRUNC(IF(I26<0,0,I26),0) | AC26: =TRUNC(IF(J26<0,0,J26),0) | AS26: 8 | AT26: 448 | AU26: 762 | AV26: 307
AS32: RETAILERS
AT33: máximo | AU33: =MAX(RetailersBegStock) | AW33: mínimo | AX33: =MIN(RetailersBegStock)
H34: 22 | I34: 23 | J34: 24 | AA34: 22 | AB34: 23 | AC34: 24 | AS34: Ei (p) | AT34: 22 | AU34: 23 | AV34: 24
A35: =MIN(H35:J224) | B35: =MAX(H35:J224) | C35: prod/dia | D35: Avarege | E35: =Demand!E25 | F35: SigmarDem | G35: 9 | H35: =TRUNC((_xlfn.NORM.INV((RAND()),$E$35,$E$36)),2) | I35: =TRUNC((_xlfn.NORM.INV((RAND()),$E$35,$E$36)),2) | J35: =TRUNC((_xlfn.NORM.INV((RAND()),$E$35,$E$36)),2) | L35: =SUM(H35:J224) | Z35: 9 | AA35: =TRUNC(IF(H35<0,0,H35),0) | AB35: =TRUNC(IF(I35<0,0,I35),0) | AC35: =TRUNC(IF(J35<0,0,J35),0) | AR35: RetBegStock | AS35: 9 | AT35: 4 | AU35: 5 | AV35: 3
D36: Std Devition | E36: =E35*0.25 | G36: 10 | H36: =TRUNC((_xlfn.NORM.INV((RAND()),$E$35,$E$36)),2) | I36: =TRUNC((_xlfn.NORM.INV((RAND()),$E$35,$E$36)),2) | J36: =TRUNC((_xlfn.NORM.INV((RAND()),$E$35,$E$36)),2) | Z36: 10 | AA36: =TRUNC(IF(H36<0,0,H36),0) | AB36: =TRUNC(IF(I36<0,0,I36),0) | AC36: =TRUNC(IF(J36<0,0,J36),0) | AS36: 10 | AT36: 4 | AU36: 5 | AV36: 7
G37: 11 | H37: =TRUNC((_xlfn.NORM.INV((RAND()),$E$35,$E$36)),2) | I37: =TRUNC((_xlfn.NORM.INV((RAND()),$E$35,$E$36)),2) | J37: =TRUNC((_xlfn.NORM.INV((RAND()),$E$35,$E$36)),2) | Z37: 11 | AA37: =TRUNC(IF(H37<0,0,H37),0) | AB37: =TRUNC(IF(I37<0,0,I37),0) | AC37: =TRUNC(IF(J37<0,0,J37),0) | AS37: 11 | AT37: 4 | AU37: 5 | AV37: 4
G38: 12 | H38: =TRUNC((_xlfn.NORM.INV((RAND()),$E$35,$E$36)),2) | I38: =TRUNC((_xlfn.NORM.INV((RAND()),$E$35,$E$36)),2) | J38: =TRUNC((_xlfn.NORM.INV((RAND()),$E$35,$E$36)),2) | Z38: 12 | AA38: =TRUNC(IF(H38<0,0,H38),0) | AB38: =TRUNC(IF(I38<0,0,I38),0) | AC38: =TRUNC(IF(J38<0,0,J38),0) | AS38: 12 | AT38: 4 | AU38: 7 | AV38: 6
G39: 13 | H39: =TRUNC((_xlfn.NORM.INV((RAND()),$E$35,$E$36)),2) | I39: =TRUNC((_xlfn.NORM.INV((RAND()),$E$35,$E$36)),2) | J39: =TRUNC((_xlfn.NORM.INV((RAND()),$E$35,$E$36)),2) | Z39: 13 | AA39: =TRUNC(IF(H39<0,0,H39),0) | AB39: =TRUNC(IF(I39<0,0,I39),0) | AC39: =TRUNC(IF(J39<0,0,J39),0) | AS39: 13 | AT39: 3 | AU39: 3 | AV39: 5
G40: 14 | H40: =TRUNC((_xlfn.NORM.INV((RAND()),$E$35,$E$36)),2) | I40: =TRUNC((_xlfn.NORM.INV((RAND()),$E$35,$E$36)),2) | J40: =TRUNC((_xlfn.NORM.INV((RAND()),$E$35,$E$36)),2) | Z40: 14 | AA40: =TRUNC(IF(H40<0,0,H40),0) | AB40: =TRUNC(IF(I40<0,0,I40),0) | AC40: =TRUNC(IF(J40<0,0,J40),0) | AS40: 14 | AT40: 6 | AU40: 4 | AV40: 5
G41: 15 | H41: =TRUNC((_xlfn.NORM.INV((RAND()),$E$35,$E$36)),2) | I41: =TRUNC((_xlfn.NORM.INV((RAND()),$E$35,$E$36)),2) | J41: =TRUNC((_xlfn.NORM.INV((RAND()),$E$35,$E$36)),2) | Z41: 15 | AA41: =TRUNC(IF(H41<0,0,H41),0) | AB41: =TRUNC(IF(I41<0,0,I41),0) | AC41: =TRUNC(IF(J41<0,0,J41),0) | AS41: 15 | AT41: 6 | AU41: 5 | AV41: 3
G42: 16 | H42: =TRUNC((_xlfn.NORM.INV((RAND()),$E$35,$E$36)),2) | I42: =TRUNC((_xlfn.NORM.INV((RAND()),$E$35,$E$36)),2) | J42: =TRUNC((_xlfn.NORM.INV((RAND()),$E$35,$E$36)),2) | Z42: 16 | AA42: =TRUNC(IF(H42<0,0,H42),0) | AB42: =TRUNC(IF(I42<0,0,I42),0) | AC42: =TRUNC(IF(J42<0,0,J42),0) | AS42: 16 | AT42: 4 | AU42: 2 | AV42: 6
G43: 17 | H43: =TRUNC((_xlfn.NORM.INV((RAND()),$E$35,$E$36)),2) | I43: =TRUNC((_xlfn.NORM.INV((RAND()),$E$35,$E$36)),2) | J43: =TRUNC((_xlfn.NORM.INV((RAND()),$E$35,$E$36)),2) | Z43: 17 | AA43: =TRUNC(IF(H43<0,0,H43),0) | AB43: =TRUNC(IF(I43<0,0,I43),0) | AC43: =TRUNC(IF(J43<0,0,J43),0) | AS43: 17 | AT43: 4 | AU43: 4 | AV43: 5
G44: 18 | H44: =TRUNC((_xlfn.NORM.INV((RAND()),$E$35,$E$36)),2) | I44: =TRUNC((_xlfn.NORM.INV((RAND()),$E$35,$E$36)),2) | J44: =TRUNC((_xlfn.NORM.INV((RAND()),$E$35,$E$36)),2) | Z44: 18 | AA44: =TRUNC(IF(H44<0,0,H44),0) | AB44: =TRUNC(IF(I44<0,0,I44),0) | AC44: =TRUNC(IF(J44<0,0,J44),0) | AS44: 18 | AT44: 1 | AU44: 4 | AV44: 5
G45: 19 | H45: =TRUNC((_xlfn.NORM.INV((RAND()),$E$35,$E$36)),2) | I45: =TRUNC((_xlfn.NORM.INV((RAND()),$E$35,$E$36)),2) | J45: =TRUNC((_xlfn.NORM.INV((RAND()),$E$35,$E$36)),2) | Z45: 19 | AA45: =TRUNC(IF(H45<0,0,H45),0) | AB45: =TRUNC(IF(I45<0,0,I45),0) | AC45: =TRUNC(IF(J45<0,0,J45),0) | AS45: 19 | AT45: 5 | AU45: 2 | AV45: 4
G46: 20 | H46: =TRUNC((_xlfn.NORM.INV((RAND()),$E$35,$E$36)),2) | I46: =TRUNC((_xlfn.NORM.INV((RAND()),$E$35,$E$36)),2) | J46: =TRUNC((_xlfn.NORM.INV((RAND()),$E$35,$E$36)),2) | Z46: 20 | AA46: =TRUNC(IF(H46<0,0,H46),0) | AB46: =TRUNC(IF(I46<0,0,I46),0) | AC46: =TRUNC(IF(J46<0,0,J46),0) | AS46: 20 | AT46: 5 | AU46: 6 | AV46: 3
G47: 21 | H47: =TRUNC((_xlfn.NORM.INV((RAND()),$E$35,$E$36)),2) | I47: =TRUNC((_xlfn.NORM.INV((RAND()),$E$35,$E$36)),2) | J47: =TRUNC((_xlfn.NORM.INV((RAND()),$E$35,$E$36)),2) | Z47: 21 | AA47: =TRUNC(IF(H47<0,0,H47),0) | AB47: =TRUNC(IF(I47<0,0,I47),0) | AC47: =TRUNC(IF(J47<0,0,J47),0) | AS47: 21 | AT47: 3 | AU47: 3 | AV47: 3
G48: 22 | H48: =TRUNC((_xlfn.NORM.INV((RAND()),$E$35,$E$36)),2) | I48: =TRUNC((_xlfn.NORM.INV((RAND()),$E$35,$E$36)),2) | J48: =TRUNC((_xlfn.NORM.INV((RAND()),$E$35,$E$36)),2) | Z48: 22 | AA48: =TRUNC(IF(H48<0,0,H48),0) | AB48: =TRUNC(IF(I48<0,0,I48),0) | AC48: =TRUNC(IF(J48<0,0,J48),0) | AS48: 22 | AT48: 7 | AU48: 4 | AV48: 6
... G224: 198 | H224: =TRUNC((_xlfn.NORM.INV((RAND()),$E$35,$E$36)),2) | I224: =TRUNC((_xlfn.NORM.INV((RAND()),$E$35,$E$36)),2) | J224: =TRUNC((_xlfn.NORM.INV((RAND()),$E$35,$E$36)),2) | Z224: 198 | AA224: =TRUNC(IF(H224<0,0,H224),0) | AB224: =TRUNC(IF(I224<0,0,I224),0) | AC224: =TRUNC(IF(J224<0,0,J224),0) | AS224: 198 | AT224: 7 | AU224: 6 | AV224: 6

Sheet Suppliers_stock_balance
C3: ELTw | D3: 1 | E3: 2 | F3: 3 | G3: 4 | H3: 5 | I3: 6 | J3: 7 | K3: 8 | L3: 9 | M3: 10 | N3: 11 | O3: 12 | P3: 13 | Q3: 14 | R3: 15
C4: 1 | D4: =Suppliers!I22 | E4: =Suppliers!J22 | F4: =Suppliers!K22 | G4: =Suppliers!L22 | H4: =Suppliers!M22 | I4: =Suppliers!N22 | J4: =Suppliers!O22 | K4: =Suppliers!P22 | ... R4: =Suppliers!W22
C5: 2 | D5: =Suppliers!I23 | E5: =Suppliers!J23 | F5: =Suppliers!K23 | G5: =Suppliers!L23 | H5: =Suppliers!M23 | I5: =Suppliers!N23 | J5: =Suppliers!O23 | K5: =Suppliers!P23 | ... R5: =Suppliers!W23
C6: 3 | D6: =Suppliers!I24 | E6: =Suppliers!J24 | F6: =Suppliers!K24 | G6: =Suppliers!L24 | H6: =Suppliers!M24 | I6: =Suppliers!N24 | J6: =Suppliers!O24 | K6: =Suppliers!P24 | ... R6: =Suppliers!W24
AL8: COMPARAÇÃO
C9: S0+RLTw-vSw | D9: 1 | E9: 2 | F9: 3 | G9: 4 | H9: 5 | I9: 6 | J9: 7 | K9: 8 | L9: 9 | M9: 10 | N9: 11 | O9: 12 | P9: 13 | Q9: 14 | R9: 15 | T9: S0+RLTw-vSw | U9: 1 | V9: 2 | W9: 3 | X9: 4 | Y9: 5 | Z9: 6 | AA9: 7 | AB9: 8 | AC9: 9 | AD9: 10 | AE9: 11 | AF9: 12 | AG9: 13 | AH9: 14 | AI9: 15 | AL9: S0+RLTw-vSw | AM9: 1 | AN9: 2 | AO9: 3 | AP9: 4 | AQ9: 5 | AR9: 6 | AS9: 7 | AT9: 8 | AU9: 9 | AV9: 10 | AW9: 11 | AX9: 12 | AY9: 13 | AZ9: 14 | BA9: 15
C10: 1 | D10: =Suppliers_Cap!D33+D22-Results!D5 | E10: =Suppliers_Cap!E33+E22-Results!E5 | F10: =Suppliers_Cap!F33+F22-Results!F5 | G10: =Suppliers_Cap!G33+G22-Results!G5 | H10: =Suppliers_Cap!H33+H22-Results!H5 | I10: =Suppliers_Cap!I33+I22-Results!I5 | J10: =Suppliers_Cap!J33+J22-Results!J5 | K10: =Suppliers_Cap!K33+K22-Results!K5 | ... R10: =Suppliers_Cap!R33+R22-Results!R5 | T10: 1 | U10: 0 | V10: 0 | W10: 0 | X10: 0 | Y10: 14.526467 | Z10: 21.197941 | AA10: 0 | AB10: 12.708561 | AC10: 8.1445719 | AD10: 0 | AE10: -2.1348967e-10 | AF10: 0 | AG10: 7.5268395 | AH10: 20.702938 | AI10: 21.85592 | AL10: 1 | AM10: =D10-U10 | AN10: =E10-V10 | AO10: =F10-W10 | AP10: =G10-X10 | AQ10: =H10-Y10 | AR10: =I10-Z10 | AS10: =J10-AA10 | AT10: =K10-AB10 | ... BA10: =R10-AI10
C11: 2 | D11: =Suppliers_Cap!D34+D23-Results!D6 | E11: =Suppliers_Cap!E34+E23-Results!E6 | F11: =Suppliers_Cap!F34+F23-Results!F6 | G11: =Suppliers_Cap!G34+G23-Results!G6 | H11: =Suppliers_Cap!H34+H23-Results!H6 | I11: =Suppliers_Cap!I34+I23-Results!I6 | J11: =Suppliers_Cap!J34+J23-Results!J6 | K11: =Suppliers_Cap!K34+K23-Results!K6 | ... R11: =Suppliers_Cap!R34+R23-Results!R6 | T11: 2 | U11: 7.7483905 | V11: 15.71758 | W11: 0 | X11: 0 | Y11: -8.2488327e-10 | Z11: 11.365102 | AA11: -9.2214236e-10 | AB11: 0 | AC11: 0 | AD11: 9.8294544 | AE11: 0 | AF11: 17.341213 | AG11: 19.48 | AH11: 11.633676 | AI11: 7.2722489 | AL11: 2 | AM11: =D11-U11 | AN11: =E11-V11 | AO11: =F11-W11 | AP11: =G11-X11 | AQ11: =H11-Y11 | AR11: =I11-Z11 | AS11: =J11-AA11 | AT11: =K11-AB11 | ... BA11: =R11-AI11
C12: 3 | D12: =Suppliers_Cap!D35+D24-Results!D7 | E12: =Suppliers_Cap!E35+E24-Results!E7 | F12: =Suppliers_Cap!F35+F24-Results!F7 | G12: =Suppliers_Cap!G35+G24-Results!G7 | H12: =Suppliers_Cap!H35+H24-Results!H7 | I12: =Suppliers_Cap!I35+I24-Results!I7 | J12: =Suppliers_Cap!J35+J24-Results!J7 | K12: =Suppliers_Cap!K35+K24-Results!K7 | ... R12: =Suppliers_Cap!R35+R24-Results!R7 | T12: 3 | U12: 27.585916 | V12: 0 | W12: 0 | X12: 12.673212 | Y12: 0 | Z12: 27.560485 | AA12: 18.881066 | AB12: 0 | AC12: 0 | AD12: 0 | AE12: 15.97619 | AF12: -8.1023188e-10 | AG12: 0 | AH12: 0 | AI12: 7.7718251 | AL12: 3 | AM12: =D12-U12 | AN12: =E12-V12 | AO12: =F12-W12 | AP12: =G12-X12 | AQ12: =H12-Y12 | AR12: =I12-Z12 | AS12: =J12-AA12 | AT12: =K12-AB12 | ... BA12: =R12-AI12
C15: vSw | D15: 1 | E15: 2 | F15: 3 | G15: 4 | H15: 5 | I15: 6 | J15: 7 | K15: 8 | L15: 9 | M15: 10 | N15: 11 | O15: 12 | P15: 13 | Q15: 14 | R15: 15 | T15: vSw | U15: 1 | V15: 2 | W15: 3 | X15: 4 | Y15: 5 | Z15: 6 | AA15: 7 | AB15: 8 | AC15: 9 | AD15: 10 | AE15: 11 | AF15: 12 | AG15: 13 | AH15: 14 | AI15: 15 | AL15: vSw | AM15: 1 | AN15: 2 | AO15: 3 | AP15: 4 | AQ15: 5 | AR15: 6 | AS15: 7 | AT15: 8 | AU15: 9 | AV15: 10 | AW15: 11 | AX15: 12 | AY15: 13 | AZ15: 14 | BA15: 15
C16: 1 | D16: =Results!D5 | E16: =Results!E5 | F16: =Results!F5 | G16: =Results!G5 | H16: =Results!H5 | I16: =Results!I5 | J16: =Results!J5 | K16: =Results!K5 | ... R16: =Results!R5 | S16: =MAX(D16:R16) | T16: 1 | U16: 0 | V16: 0 | W16: 0 | X16: 0 | Y16: 0 | Z16: -3.5390222e-10 | AA16: 0 | AB16: 0 | AC16: 0 | AD16: 0 | AE16: -56.04966 | AF16: 0 | AG16: 0 | AH16: 3.9115623e-10 | AI16: 2.6076719e-10 | AL16: 1 | AM16: =D16-U16 | AN16: =E16-V16 | AO16: =F16-W16 | AP16: =G16-X16 | AQ16: =H16-Y16 | AR16: =I16-Z16 | AS16: =J16-AA16 | AT16: =K16-AB16 | ... BA16: =R16-AI16
