Workbook
Name Distributors_Stock_Begining: Distributors_stock_balance!$D$10:$F$11
Name Distributors_Stock_Demand: Distributors_stock_balance!$D$16:$F$17
Name Distributors_Stock_Replenishment: Distributors_stock_balance!$D$5:$F$6
Name DistributorsBegStock: Beginning_stock!$AT$25:$AV$26
Name DistributorsCap: Distributors_Cap!$D$13:$F$14
Name DistributorsCost: Distributors!$P$6:$R$7
Name DistributorsDem: Demand!$AU$19:$AW$20
Name DistributorsLeadTime: Distributors!$P$16:$R$17
Name DistributorsNumberBinaryVarY: Distributors_Cap!$D$29:$F$30
Name DistributorsSafetyFactor: Distributors!$P$21:$R$22
Name DistributorsStdDev: Distributors!$P$11:$R$12
Name DistributorsUpperBound: Distributors_Cap!$D$22:$F$23
Name Fac_Qtd_LB: Matlab_Data!$D$98:$F$100
Name Factories_Actual_Min_Stock: Factories_stock_balance!$D$278:$F$280
Name Factories_Actual_RunOutTime: Factories_stock_balance!$D$284:$F$286
Name Factories_Backlog: Factories_stock_balance!$D$254:$F$256
Name Factories_Cap_StdDev: Factories_Cap!$D$9:$F$11
Name Factories_Capacity_Coefficient: Factories_stock_balance!$D$266:$F$268
Name Factories_Coverage_Time: Factories_stock_balance!$D$28:$F$30
Name Factories_Delta: Factories_stock_balance!$D$34:$F$36
Name Factories_Gamma: Factories_stock_balance!$D$45:$F$47
Name Factories_Gross_Base_Stock: Factories_stock_balance!$D$212:$F$214
Name Factories_Max_NumberofCycles: Factories_stock_balance!$D$290:$F$292
Name Factories_Net_Demand: Factories_stock_balance!$D$200:$F$202
Name Factories_Omega: Factories_stock_balance!$D$57:$F$59
Name Factories_Omega1: Factories_stock_balance!$D$110:$F$112
Name Factories_Omega2: Factories_stock_balance!$D$116:$F$118
Name Factories_Omega3: Factories_stock_balance!$D$122:$F$124
Name Factories_Omega4: Factories_stock_balance!$D$140:$F$142
Name Factories_Omega5: Factories_stock_balance!$D$146:$F$148
Name Factories_Omega6: Factories_stock_balance!$D$152:$F$154
Name Factories_Replenishment_Time: Factories_stock_balance!$D$22:$F$24
Name Factories_Rho: Factories_stock_balance!$D$51:$F$53
Name Factories_Runout_Time: Factories_stock_balance!$D$63:$F$65
Name Factories_Safety_Stock: Factories_stock_balance!$D$230:$F$232
Name Factories_Squared_root: Factories_stock_balance!$D$182:$F$184
Name Factories_Stock_Consumption: Factories_stock_balance!$D$248:$F$250
Name Factories_Stock_Recovery: Factories_stock_balance!$D$260:$F$262
Name Factories_Variance_NetDemand_Rate: Factories_stock_balance!$D$218:$F$220
Name Factories_Work_in_process: Factories_WIP!$D$8:$F$10
Name Factories_Zeta: Factories_stock_balance!$D$39:$F$41
Name FactoriesBegStock: Beginning_stock!$AT$15:$AV$17
Name FactoriesCap: Factories_Cap!$D$14:$F$16
Name FactoriesCost: Factories!$I$6:$K$8
Name FactoriesDem: Demand!$AU$11:$AW$13
Name FactoriesLeadTime: Factories!$I$22:$K$24
Name FactoriesLeadTimeStdDev: Factories!$I$27:$K$29
Name FactoriesNumberBinaryVarY: Factories_Cap!$D$61:$F$63
Name FactoriesPlanStock: 'Planned_Beginning_stock '!$AT$15:$AV$17
Name FactoriesStdDev: Factories!$I$17:$K$19
Name FactoriesStdDevVarVar: Fac_Fourth_central_moment_5var!$D$41:$F$43
Name FactoriesUpperBound: Factories_Cap!#REF!
Name InboundServiceTimef: Factories_Cap!$D$39:$F$41
Name InboundServiceTimew: Suppliers_Cap!$D$39:$R$41
Name Maxd: Distributors_Cap!$D$35
Name Maxf: Factories_Cap!#REF!
Name Maxr: Retailers_Cap!$AN$9
Name MaxStkOutd: Distributors_Cap!$R$47
Name MaxStkOutf: Factories_Cap!#REF!
Name MaxStkOutr: Retailers_Cap!$CQ$7

Sheet Matlab_Data_VALOR
C1: SUPPLIERS
C2: demand | D2: 1 | E2: 2 | F2: 3 | G2: 4 | H2: 5 | I2: 6 | J2: 7 | K2: 8 | L2: 9 | M2: 10 | N2: 11 | O2: 12 | P2: 13 | Q2: 14 | R2: 15
C3: 1 | D3: 231.5 | E3: 297.34 | F3: 217.82 | G3: 222.62 | H3: 453.86 | I3: 315.98 | J3: 216.18 | K3: 463.97 | L3: 404.65 | M3: 334.69 | N3: 440.61 | O3: 225.39 | P3: 314.98 | Q3: 305.23 | R3: 541.84
C4: 2 | D4: 358.95 | E4: 308.97 | F4: 264.61 | G4: 343.62 | H4: 399.3 | I4: 433.24 | J4: 310.82 | K4: 234.15 | L4: 302.73 | M4: 304.23 | N4: 278.95 | O4: 403.93 | P4: 327.87 | Q4: 462.67 | R4: 445.18
C5: 3 | D5: 492.88 | E5: 260.36 | F5: 232.33 | G5: 514.32 | H5: 271.63 | I5: 506.16 | J5: 393.21 | K5: 346.58 | L5: 267.82 | M5: 272.81 | N5: 372.8 | O5: 326.64 | P5: 338.03 | Q5: 348.46 | R5: 405.85
B7: Parâmetro p/ μy | C7: Média(E(RLT)) | D7: 1 | E7: 2 | F7: 3 | G7: 4 | H7: 5 | I7: 6 | J7: 7 | K7: 8 | L7: 9 | M7: 10 | N7: 11 | O7: 12 | P7: 13 | Q7: 14 | R7: 15
B8: LB e DesvPad(ND*RLT) | C8: 1 | D8: 9.45 | E8: 14.92 | F8: 14.79 | G8: 17.69 | H8: 14.79 | I8: 14.31 | J8: 10.15 | K8: 14.45 | L8: 12.52 | M8: 11.45 | N8: 13.36 | O8: 13.38 | P8: 14.59 | Q8: 14.28 | R8: 16.04
B9: LB e DesvPad(ND*RLT) | C9: 2 | D9: 13.11 | E9: 17.64 | F9: 11.65 | G9: 20.06 | H9: 11.73 | I9: 15.92 | J9: 12.08 | K9: 15.93 | L9: 10.8 | M9: 13.12 | N9: 12.44 | O9: 15.71 | P9: 19.48 | Q9: 17.94 | R9: 13.48
B10: LB e DesvPad(ND*RLT) | C10: 3 | D10: 18.26 | E10: 19.27 | F10: 20.64 | G10: 13.97 | H10: 13.78 | I10: 17.6 | J10: 12.66 | K10: 13.15 | L10: 16.36 | M10: 15.94 | N10: 10.35 | O10: 14.02 | P10: 14.06 | Q10: 12.12 | R10: 12.77
C12: Cap | D12: 1 | E12: 2 | F12: 3 | G12: 4 | H12: 5 | I12: 6 | J12: 7 | K12: 8 | L12: 9 | M12: 10 | N12: 11 | O12: 12 | P12: 13 | Q12: 14 | R12: 15
C13: 1 | D13: 304.6 | E13: 336.22 | F13: 367.37 | G13: 330.6 | H13: 407.16 | I13: 209.81 | J13: 353.15 | K13: 325.44 | L13: 303.38 | M13: 363.91 | N13: 423.84 | O13: 250.7 | P13: 253.28 | Q13: 216.52 | R13: 388.77
C14: 2 | D14: 288.68 | E14: 254.58 | F14: 333.83 | G14: 569.96 | H14: 363.61 | I14: 359.54 | J14: 304.66 | K14: 312.17 | L14: 379.11 | M14: 233.3 | N14: 387.92 | O14: 330.06 | P14: 266.36 | Q14: 408.27 | R14: 358.07
C15: 3 | D15: 327.67 | E15: 359.24 | F15: 403.54 | G15: 415.74 | H15: 368.14 | I15: 306.54 | J15: 220.2 | K15: 408.05 | L15: 398.03 | M15: 305.5 | N15: 241.55 | O15: 315.53 | P15: 436.88 | Q15: 393.14 | R15: 327.17
B17: Parâmetro p/ μx | C17: Var(d-cap) | D17: 1 | E17: 2 | F17: 3 | G17: 4 | H17: 5 | I17: 6 | J17: 7 | K17: 8 | L17: 9 | M17: 10 | N17: 11 | O17: 12 | P17: 13 | Q17: 14 | R17: 15
B18: LB | C18: 1 | H18: 495,6908 | I18: 191.8181 | K18: 428.2391 | L18: 341.0413 | N18: 498.37 | P18: 217.8175 | Q18: 186.7283 | R18: 592.9769
B19: LB | C19: 2 | D19: 282,9083 | E19: 213,6979 | H19: 388,8702 | I19: 422.6212 | J19: 252.569 | M19: 195.9797 | O19: 362.7987 | P19: 237.9285 | Q19: 507.6638 | R19: 435.1991
B20: LB | C20: 3 | D20: 467,0644 | G20: 583,1530 | I20: 466.8862 | J20: 270.8028 | N20: 263.1016 | O20: 275.0038 | R20: 362.3392
B22: Parâmetro p/ σx | C22: Desvpad(Var(S2nd)) | D22: 1 | E22: 2 | F22: 3 | G22: 4 | H22: 5 | I22: 6 | J22: 7 | K22: 8 | L22: 9 | M22: 10 | N22: 11 | O22: 12 | P22: 13 | Q22: 14 | R22: 15
B23: LB | C23: 1 | H23: 277.3852 | I23: 114.4701 | K23: 251.6818 | L23: 197.052 | N23: 277.4759 | P23: 123.9421 | Q23: 109.4126 | R23: 346.4116
B24: LB | C24: 2 | D24: 160.9752 | E24: 121.0452 | H24: 217.2882 | I24: 239.086 | J24: 140.5445 | M24: 112.6414 | O24: 205.8108 | P24: 135.1195 | Q24: 284.6164 | R24: 247.6234
B25: LB | C25: 3 | D25: 278.6301 | G25: 331.4884 | I25: 286.2747 | J25: 169.9887 | N25: 158.1255 | O25: 153.0895 | R25: 206.0767
B27: Parâmetro p/ σy | C27: DesvPad(Var(E(RLT))) | D27: 1 | E27: 2 | F27: 3 | G27: 4 | H27: 5 | I27: 6 | J27: 7 | K27: 8 | L27: 9 | M27: 10 | N27: 11 | O27: 12 | P27: 13 | Q27: 14 | R27: 15
B28: LB e DesvPad(ND*RLT) | C28: 1 | D28: 0.3449 | E28: 0.5447 | F28: 0.54 | G28: 0.6459 | H28: 0.54 | I28: 0.5224 | J28: 0.3705 | K28: 0.5276 | L28: 0.4571 | M28: 0.418 | N28: 0.4877 | O28: 0.4884 | P28: 0.5327 | Q28: 0.5213 | R28: 0.5856
B29: LB e DesvPad(ND*RLT) | C29: 2 | D29: 0.4786 | E29: 0.644 | F29: 0.4253 | G29: 0.7324 | H29: 0.4282 | I29: 0.5812 | J29: 0.441 | K29: 0.5816 | L29: 0.3943 | M29: 0.479 | N29: 0.4542 | O29: 0.5735 | P29: 0.7112 | Q29: 0.655 | R29: 0.4921
B30: LB e DesvPad(ND*RLT) | C30: 3 | D30: 0.6667 | E30: 0.7036 | F30: 0.7536 | G30: 0.51 | H30: 0.503 | I30: 0.6426 | J30: 0.4622 | K30: 0.4801 | L30: 0.5973 | M30: 0.5819 | N30: 0.3778 | O30: 0.5118 | P30: 0.5133 | Q30: 0.4424 | R30: 0.4662
B32: Parâmetro p/ μx | C32: Média(d-Cap) | D32: 1 | E32: 2 | F32: 3 | G32: 4 | H32: 5 | I32: 6 | J32: 7 | K32: 8 | L32: 9 | M32: 10 | N32: 11 | O32: 12 | P32: 13 | Q32: 14 | R32: 15
B33: DesvPad(ND*RLT) | C33: 1 | D33: -73.1 | E33: -38.88 | F33: -149.55 | G33: -107.98 | H33: 46.7 | I33: 106.17 | J33: -136.97 | K33: 138.53 | L33: 101.27 | M33: -29.22 | N33: 16.77 | O33: -25.31 | P33: 61.7 | Q33: 88.71 | R33: 153.07
B34: DesvPad(ND*RLT) | C34: 2 | D34: 70.27 | E34: 54.39 | F34: -69.22 | G34: -226.34 | H34: 35.69 | I34: 73.7 | J34: 6.16 | K34: -78.02 | L34: -76.38 | M34: 70.93 | N34: -108.97 | O34: 73.87 | P34: 61.51 | Q34: 54.4 | R34: 87.11
B35: DesvPad(ND*RLT) | C35: 3 | D35: 165.21 | E35: -98.88 | F35: -171.21 | G35: 98.58 | H35: -96.51 | I35: 199.62 | J35: 173.01 | K35: -61.47 | L35: -130.21 | M35: -32.69 | N35: 131.25 | O35: 11.11 | P35: -98.85 | Q35: -44.68 | R35: 78.68
B37: Parâmetro p/ σx | C37: DesvPad(Var(d-cap)) | D37: 1 | E37: 2 | F37: 3 | G37: 4 | H37: 5 | I37: 6 | J37: 7 | K37: 8 | L37: 9 | M37: 10 | N37: 11 | O37: 12 | P37: 13 | Q37: 14 | R37: 15
B38: DesvPad(ND*RLT) | C38: 1 | D38: 0 | E38: 0 | F38: 0 | G38: 0 | H38: 22.264115 | I38: 13.849841 | J38: 0 | K38: 20.693939 | L38: 18.467304 | M38: 0 | N38: 22.324202 | O38: 0 | P38: 14.758642 | Q38: 13.664856 | R38: 24.351117
B39: DesvPad(ND*RLT) | C39: 2 | D39: 16.819878 | E39: 14.61841 | F39: 0 | G39: 0 | H39: 19.719792 | I39: 20.557753 | J39: 15.89242 | K39: 0 | L39: 0 | M39: 13.999275 | N39: 0 | O39: 19.047275 | P39: 15.424931 | Q39: 22.531396 | R39: 20.861426
B40: DesvPad(ND*RLT) | C40: 3 | D40: 21.611673 | E40: 0 | F40: 0 | G40: 24.148561 | H40: 0 | I40: 21.60755 | J40: 16.456087 | K40: 0 | L40: 0 | M40: 0 | N40: 16.220407 | O40: 16.583239 | P40: 0 | Q40: 0 | R40: 19.035209
C42: Prob1 | D42: 0.98
C44: LB | D44: 1 | E44: 2 | F44: 3 | G44: 4 | H44: 5 | I44: 6 | J44: 7 | K44: 8 | L44: 9 | M44: 10 | N44: 11 | O44: 12 | P44: 13 | Q44: 14 | R44: 15
C45: 1 | D45: -40028922 | E45: 0 | F45: -40028922 | G45: 0 | H45: 15818.302 | I45: 6132.0093 | J45: 0 | K45: 13708.849 | L45: 9372.3396 | M45: 0 | N45: -40028922 | O45: 0 | P45: 6918.3969 | Q45: 5897.5627 | R45: 21002.39
C46: 2 | D46: 8074.1812 | E46: 8186.4463 | F46: 0 | G46: 0 | H46: 9834.2635 | I46: 14601.568 | J46: 6563.4316 | K46: 0 | L46: 0 | M46: 5627.9126 | N46: 0 | O46: 12387.656 | P46: 10079.393 | Q46: 19670.323 | R46: 12770.938
C47: 3 | D47: 19048.847 | E47: 0 | F47: 0 | G47: 17725.552 | H47: 0 | I47: 18633.411 | J47: 7876.7163 | K47: 0 | L47: 0 | M47: 0 | N47: 6106.9843 | O47: 8295.8778 | P47: 0 | Q47: 0 | R47: 10070.459
C49: DesvPad(ND*ELT) | D49: 1 | E49: 2 | F49: 3 | G49: 4 | H49: 5 | I49: 6 | J49: 7 | K49: 8 | L49: 9 | M49: 10 | N49: 11 | O49: 12 | P49: 13 | Q49: 14 | R49: 15
C50: 1 | D50: -40028922 | E50: 0 | F50: -40028922 | G50: 0 | H50: 89.3519 | I50: 58.127 | J50: 0 | K50: 86.0169 | L50: 70.3036 | M50: 0 | N50: 84.7408 | O50: 0 | P50: 59.7737 | Q50: 56.3029 | R50: 106.0337
...

Sheet Estado da arte_VALOR
C1: SUPPLIERS
B2: Parâmetros p/ | C2: demand | D2: 1 | E2: 2 | F2: 3 | G2: 4 | H2: 5 | I2: 6 | J2: 7 | K2: 8 | L2: 9 | M2: 10 | N2: 11 | O2: 12 | P2: 13 | Q2: 14 | R2: 15
B3: Prob(D*ELT) | C3: 1 | D3: 231.5 | E3: 297.34 | F3: 217.82 | G3: 222.62 | H3: 453.86 | I3: 315.98 | J3: 216.18 | K3: 463.97 | L3: 404.65 | M3: 334.69 | N3: 440.61 | O3: 225.39 | P3: 314.98 | Q3: 305.23 | R3: 541.84
B4: Prob(D*ELT) | C4: 2 | D4: 358.95 | E4: 308.97 | F4: 264.61 | G4: 343.62 | H4: 399.3 | I4: 433.24 | J4: 310.82 | K4: 234.15 | L4: 302.73 | M4: 304.23 | N4: 278.95 | O4: 403.93 | P4: 327.87 | Q4: 462.67 | R4: 445.18
B5: Prob(D*ELT) | C5: 3 | D5: 492.88 | E5: 260.36 | F5: 232.33 | G5: 514.32 | H5: 271.63 | I5: 506.16 | J5: 393.21 | K5: 346.58 | L5: 267.82 | M5: 272.81 | N5: 372.8 | O5: 326.64 | P5: 338.03 | Q5: 348.46 | R5: 405.85
A6: CV
A7: 0.2 | B7: Parâmetros | C7: DesvPad(demand) | D7: 1 | E7: 2 | F7: 3 | G7: 4 | H7: 5 | I7: 6 | J7: 7 | K7: 8 | L7: 9 | M7: 10 | N7: 11 | O7: 12 | P7: 13 | Q7: 14 | R7: 15
B8: Prob(D*ELT) | C8: 1 | D8: 46.3 | E8: 59.468 | F8: 43.564 | G8: 44.524 | H8: 90.772 | I8: 63.196 | J8: 43.236 | K8: 92.794 | L8: 80.93 | M8: 66.938 | N8: 88.122 | O8: 45.078 | P8: 62.996 | Q8: 61.046 | R8: 108.368
B9: Prob(D*ELT) | C9: 2 | D9: 71.79 | E9: 61.794 | F9: 52.922 | G9: 68.724 | H9: 79.86 | I9: 86.648 | J9: 62.164 | K9: 46.83 | L9: 60.546 | M9: 60.846 | N9: 55.79 | O9: 80.786 | P9: 65.574 | Q9: 92.534 | R9: 89.036
B10: Prob(D*ELT) | C10: 3 | D10: 98.576 | E10: 52.072 | F10: 46.466 | G10: 102.864 | H10: 54.326 | I10: 101.232 | J10: 78.642 | K10: 69.316 | L10: 53.564 | M10: 54.562 | N10: 74.56 | O10: 65.328 | P10: 67.606 | Q10: 69.692 | R10: 81.17
B12: Parâmetros | C12: Média(E(RLT)) | D12: 1 | E12: 2 | F12: 3 | G12: 4 | H12: 5 | I12: 6 | J12: 7 | K12: 8 | L12: 9 | M12: 10 | N12: 11 | O12: 12 | P12: 13 | Q12: 14 | R12: 15
B13: Prob(D*ELT) | C13: 1 | D13: 9.45 | E13: 14.92 | F13: 14.79 | G13: 17.69 | H13: 14.79 | I13: 14.31 | J13: 10.15 | K13: 14.45 | L13: 12.52 | M13: 11.45 | N13: 13.36 | O13: 13.38 | P13: 14.59 | Q13: 14.28 | R13: 16.04
B14: Prob(D*ELT) | C14: 2 | D14: 13.11 | E14: 17.64 | F14: 11.65 | G14: 20.06 | H14: 11.73 | I14: 15.92 | J14: 12.08 | K14: 15.93 | L14: 10.8 | M14: 13.12 | N14: 12.44 | O14: 15.71 | P14: 19.48 | Q14: 17.94 | R14: 13.48
B15: Prob(D*ELT) | C15: 3 | D15: 18.26 | E15: 19.27 | F15: 20.64 | G15: 13.97 | H15: 13.78 | I15: 17.6 | J15: 12.66 | K15: 13.15 | L15: 16.36 | M15: 15.94 | N15: 10.35 | O15: 14.02 | P15: 14.06 | Q15: 12.12 | R15: 12.77
A17: CV | B17: Parâmetros | C17: DesvPad(E(RLT)) | D17: 1 | E17: 2 | F17: 3 | G17: 4 | H17: 5 | I17: 6 | J17: 7 | K17: 8 | L17: 9 | M17: 10 | N17: 11 | O17: 12 | P17: 13 | Q17: 14 | R17: 15
A18: 0.2 | B18: Prob(D*ELT) | C18: 1 | D18: 1.89 | E18: 2.984 | F18: 2.958 | G18: 3.538 | H18: 2.958 | I18: 2.862 | J18: 2.03 | K18: 2.89 | L18: 2.504 | M18: 2.29 | N18: 2.672 | O18: 2.676 | P18: 2.918 | Q18: 2.856 | R18: 3.208
B19: Prob(D*ELT) | C19: 2 | D19: 2.622 | E19: 3.528 | F19: 2.33 | G19: 4.012 | H19: 2.346 | I19: 3.184 | J19: 2.416 | K19: 3.186 | L19: 2.16 | M19: 2.624 | N19: 2.488 | O19: 3.142 | P19: 3.896 | Q19: 3.588 | R19: 2.696
B20: Prob(D*ELT) | C20: 3 | D20: 3.652 | E20: 3.854 | F20: 4.128 | G20: 2.794 | H20: 2.756 | I20: 3.52 | J20: 2.532 | K20: 2.63 | L20: 3.272 | M20: 3.188 | N20: 2.07 | O20: 2.804 | P20: 2.812 | Q20: 2.424 | R20: 2.554
C23: z | D23: 2.06
C25: DesvPad | D25: 1 | E25: 2 | F25: 3 | G25: 4 | H25: 5 | I25: 6 | J25: 7 | K25: 8 | L25: 9 | M25: 10 | N25: 11 | O25: 12 | P25: 13 | Q25: 14 | R25: 15
C26: 1 | D26: 460.10297 | E26: 916.51436 | F26: 665.73732 | G26: 809.58554 | H26: 1387.1616 | I26: 935.39922 | J26: 459.95566 | K26: 1386.4942 | L26: 1052.9313 | M26: 799.2086 | N26: 1220.5759 | O26: 625.27655 | P26: 950.08766 | Q26: 901.74344 | R26: 1791.5875
C27: 2 | D27: 976.40233 | E27: 1120.5173 | F27: 642.4576 | G27: 1412.5476 | H27: 975.87123 | I27: 1422.1004 | J27: 781.40519 | K27: 769.06053 | L27: 683.49972 | M27: 828.16391 | N27: 721.38347 | O27: 1308.9179 | P27: 1309.7582 | Q27: 1705.6996 | R27: 1243.9269
C28: 3 | D28: 1848.6288 | E28: 1029.1342 | F28: 982.01645 | G28: 1487.5532 | H28: 775.29959 | I28: 1831.6 | J28: 1034.1815 | K28: 945.52843 | L28: 902.69183 | M28: 896.58433 | N28: 808.11656 | O28: 948 | P28: 983.76278 | Q28: 878.82248 | R28: 1076.361
C30: Média(Demand*ELT) | D30: 1 | E30: 2 | F30: 3 | G30: 4 | H30: 5 | I30: 6 | J30: 7 | K30: 8 | L30: 9 | M30: 10 | N30: 11 | O30: 12 | P30: 13 | Q30: 14 | R30: 15
C31: 1 | D31: 2187.675 | E31: 4436.3128 | F31: 3221.5578 | G31: 3938.1478 | H31: 6712.5894 | I31: 4521.6738 | J31: 2194.227 | K31: 6704.3665 | L31: 5066.218 | M31: 3832.2005 | N31: 5886.5496 | O31: 3015.7182 | P31: 4595.5582 | Q31: 4358.6844 | R31: 8691.1136
C32: 2 | D32: 4705.8345 | E32: 5450.2308 | F32: 3082.7065 | G32: 6893.0172 | H32: 4683.789 | I32: 6897.1808 | J32: 3754.7056 | K32: 3730.0095 | L32: 3269.484 | M32: 3991.4976 | N32: 3470.138 | O32: 6345.7403 | P32: 6386.9076 | Q32: 8300.2998 | R32: 6001.0264
C33: 3 | D33: 8999.9888 | E33: 5017.1372 | F33: 4795.2912 | G33: 7185.0504 | H33: 3743.0614 | I33: 8908.416 | J33: 4978.0386 | K33: 4557.527 | L33: 4381.5352 | M33: 4348.5914 | N33: 3858.48 | O33: 4579.4928 | P33: 4752.7018 | Q33: 4223.3352 | R33: 5182.7045
B35: Parâmetro p/ c | C35: Reposição | D35: 1 | E35: 2 | F35: 3 | G35: 4 | H35: 5 | I35: 6 | J35: 7 | K35: 8 | L35: 9 | M35: 10 | N35: 11 | O35: 12 | P35: 13 | Q35: 14 | R35: 15
B36: Prob(D*ELT) | C36: 1 | D36: 3135.4871 | E36: 6324.3324 | F36: 4592.9767 | G36: 5605.894 | H36: 9570.1423 | I36: 6448.5962 | J36: 3141.7356 | K36: 9560.5446 | L36: 7235.2566 | M36: 5478.5702 | N36: 8400.936 | O36: 4303.7879 | P36: 6552.7388 | Q36: 6216.2759 | R36: 12381.784
B37: Prob(D*ELT) | C37: 2 | D37: 6717.2233 | E37: 7758.4964 | F37: 4406.1692 | G37: 9802.8652 | H37: 6694.0837 | I37: 9826.7076 | J37: 5364.4003 | K37: 5314.2742 | L37: 4677.4934 | M37: 5697.5152 | N37: 4956.1879 | O37: 9042.1113 | P37: 9085.0095 | Q37: 11814.041 | R37: 8563.5159
B38: Prob(D*ELT) | C38: 3 | D38: 12808.164 | E38: 7137.1536 | F38: 6818.2451 | G38: 10249.41 | H38: 5340.1786 | I38: 12681.512 | J38: 7108.4524 | K38: 6505.3156 | L38: 6241.0804 | M38: 6195.5551 | N38: 5523.2001 | O38: 6532.3728 | P38: 6779.2531 | Q38: 6033.7095 | R38: 7400.0082
C40: P(Reposição) | D40: 1 | E40: 2 | F40: 3 | G40: 4 | H40: 5 | I40: 6 | J40: 7 | K40: 8 | L40: 9 | M40: 10 | N40: 11 | O40: 12 | P40: 13 | Q40: 14 | R40: 15
C41: 1
C42: 2
C43: 3
C45: Factories
B46: Parâmetros p/ | C46: demand | D46: 16 | E46: 17 | F46: 18
B47: Prob(D*ELT) | C47: 4 | D47: 1894.6 | E47: 1607.87 | F47: 1829.53
B48: Prob(D*ELT) | C48: 5 | D48: 1303.06 | E48: 1484.38 | F48: 1783.87
B49: Prob(D*ELT) | C49: 6 | D49: 1377.91 | E49: 1520.56 | F49: 1301.6
...

Sheet Main_variables_VALOR
C1: SUPPLIERS | D1: Objective | E1: 3543387.1
C2: P(Reorder) | D2: 1 | E2: 2 | F2: 3 | G2: 4 | H2: 5 | I2: 6 | J2: 7 | K2: 8 | L2: 9 | M2: 10 | N2: 11 | O2: 12 | P2: 13 | Q2: 14 | R2: 15
C3: 1
C4: 2
C5: 3
C7: Reorder | D7: 1 | E7: 2 | F7: 3 | G7: 4 | H7: 5 | I7: 6 | J7: 7 | K7: 8 | L7: 9 | M7: 10 | N7: 11 | O7: 12 | P7: 13 | Q7: 14 | R7: 15
C8: 1 | D8: 0 | E8: 0 | F8: 0 | G8: 0 | H8: 1168.693 | I8: 1817.2927 | J8: 0 | K8: 2446.7585 | L8: 1635.9004 | M8: 0 | N8: 0 | O8: 0 | P8: 1216.203 | Q8: 1558.7788 | R8: 3007.2428
C9: 2 | D9: 1262.2397 | E9: 1303.4396 | F9: 0 | G9: 0 | H9: 0 | I9: 1632.304 | J9: 0 | K9: 0 | L9: 0 | M9: 1215.6016 | N9: 0 | O9: 1583.4977 | P9: 1579.2148 | Q9: 1508.936 | R9: 1603.2428
C10: 3 | D10: 3540.7346 | E10: 0 | F10: 0 | G10: 1883.1626 | H10: 0 | I10: 4031.312 | J10: 2527.3066 | K10: 0 | L10: 0 | M10: 0 | N10: 1655.4375 | O10: 0 | P10: 0 | Q10: 0 | R10: 1385.7436
C12: Var(Var(d)) | D12: 1 | E12: 2 | F12: 3 | G12: 4 | H12: 5 | I12: 6 | J12: 7 | K12: 8 | L12: 9 | M12: 10 | N12: 11 | O12: 12 | P12: 13 | Q12: 14 | R12: 15
C13: 1 | D13: 2844775.6 | E13: 7742075.2 | F13: 2229641.4 | G13: 2432768.1 | H13: 42027317 | I13: 9873756.6 | J13: 2163246.7 | K13: 45899044 | L13: 26555973 | M13: 12428393 | N13: 37330296 | O13: 2556127.9 | P13: 9749356.5 | Q13: 8597118.3 | R13: 85374523
C14: 2 | D14: 16442955 | E14: 9026290 | F14: 4855892.1 | G14: 13808858 | H14: 25179163 | I14: 34894600 | J14: 9244423.7 | K14: 2977286.9 | L14: 8318899.5 | M14: 8485006.6 | N14: 5997213.4 | O14: 26367470 | P14: 11445921 | Q14: 45386782 | R14: 38903315
C15: 3 | D15: 58453271 | E15: 4551358.7 | F15: 2885793.1 | G15: 69307093 | H15: 5392062.9 | I15: 65012269 | J15: 23677849 | K15: 14290849 | L15: 5095842.9 | M15: 5486371 | N15: 19131440 | O15: 11275128 | P15: 12931980 | Q15: 14603460 | R15: 26872387
C17: Var(Var(Cap)) | D17: 1 | E17: 2 | F17: 3 | G17: 4 | H17: 5 | I17: 6 | J17: 7 | K17: 8 | L17: 9 | M17: 10 | N17: 11 | O17: 12 | P17: 13 | Q17: 14 | R17: 15
C18: 1 | D18: 8526359.4 | E18: 12657216 | F18: 18040924 | G18: 11831926 | H18: 27221024 | I18: 1919326 | J18: 15405680 | K18: 11110350 | L18: 8390576.7 | M18: 17370807 | N18: 31963314 | O18: 3912563.3 | P18: 4076126.2 | Q18: 2176888.1 | R18: 22626377
C19: 2 | D19: 6878770.2 | E19: 4160458.1 | F19: 12301143 | G19: 1.0452533e+08 | H19: 17313597 | I19: 16551330 | J19: 8533079.4 | K19: 9406080.4 | L19: 20459970 | M19: 2934289.7 | N19: 22429145 | O19: 11754810 | P19: 4985629.9 | Q19: 27519080 | R19: 16282301
C20: 3 | D20: 11418019 | E20: 16496157 | F20: 26265785 | G20: 29589068 | H20: 18192654 | I20: 8745661 | J20: 2328698.7 | K20: 27459813 | L20: 24860351 | M20: 8627578.1 | N20: 3371880.8 | O20: 9817630 | P20: 36082173 | Q20: 23660993 | R20: 11348486
C22: CV | D22: 1 | E22: 2 | F22: 3 | G22: 4 | H22: 5 | I22: 6 | J22: 7 | K22: 8 | L22: 9 | M22: 10 | N22: 11 | O22: 12 | P22: 13 | Q22: 14 | R22: 15
C23: 1 | D23: 0.2 | E23: 0.2 | F23: 0.2 | G23: 0.2 | H23: 0.2 | I23: 0.2 | J23: 0.2 | K23: 0.2 | L23: 0.2 | M23: 0.2 | N23: 0.2 | O23: 0.2 | P23: 0.2 | Q23: 0.2 | R23: 0.2
C24: 2 | D24: 0.2 | E24: 0.2 | F24: 0.2 | G24: 0.2 | H24: 0.2 | I24: 0.2 | J24: 0.2 | K24: 0.2 | L24: 0.2 | M24: 0.2 | N24: 0.2 | O24: 0.2 | P24: 0.2 | Q24: 0.2 | R24: 0.2
C25: 3 | D25: 0.2 | E25: 0.2 | F25: 0.2 | G25: 0.2 | H25: 0.2 | I25: 0.2 | J25: 0.2 | K25: 0.2 | L25: 0.2 | M25: 0.2 | N25: 0.2 | O25: 0.2 | P25: 0.2 | Q25: 0.2 | R25: 0.2
C27: Planned Stock | D27: 1 | E27: 2 | F27: 3 | G27: 4 | H27: 5 | I27: 6 | J27: 7 | K27: 8 | L27: 9 | M27: 10 | N27: 11 | O27: 12 | P27: 13 | Q27: 14 | R27: 15
C28: 1 | D28: 1 | E28: 1 | F28: 1 | G28: 1 | H28: 1 | I28: 1 | J28: 1 | K28: 1 | L28: 1 | M28: 1 | N28: 1 | O28: 1 | P28: 1 | Q28: 1 | R28: 1
C29: 2 | D29: 1 | E29: 1 | F29: 1 | G29: 1 | H29: 1 | I29: 1 | J29: 1 | K29: 1 | L29: 1 | M29: 1 | N29: 1 | O29: 1 | P29: 1 | Q29: 1 | R29: 1
C30: 3 | D30: 1 | E30: 1 | F30: 1 | G30: 1 | H30: 1 | I30: 1 | J30: 1 | K30: 1 | L30: 1 | M30: 1 | N30: 1 | O30: 1 | P30: 1 | Q30: 1 | R30: 1
C32: Variance coeff - z(S2nd) | D32: 1 | E32: 2 | F32: 3 | G32: 4 | H32: 5 | I32: 6 | J32: 7 | K32: 8 | L32: 9 | M32: 10 | N32: 11 | O32: 12 | P32: 13 | Q32: 14 | R32: 15
C33: 1 | D33: 1.7057377 | E33: 1.7057377 | F33: 1.7057377 | G33: 1.7057377 | H33: 1.7057377 | I33: 1.7057377 | J33: 1.7057377 | K33: 1.7057377 | L33: 1.7057377 | M33: 1.7057377 | N33: 1.7057377 | O33: 1.7057377 | P33: 1.7057377 | Q33: 1.7057377 | R33: 1.7057377
C34: 2 | D34: 1.7057377 | E34: 1.7057377 | F34: 1.7057377 | G34: 1.7057377 | H34: 1.7057377 | I34: 1.7057377 | J34: 1.7057377 | K34: 1.7057377 | L34: 1.7057377 | M34: 1.7057377 | N34: 1.7057377 | O34: 1.7057377 | P34: 1.7057377 | Q34: 1.7057377 | R34: 1.7057377
C35: 3 | D35: 1.7057377 | E35: 1.7057377 | F35: 1.7057377 | G35: 1.7057377 | H35: 1.7057377 | I35: 1.7057377 | J35: 1.7057377 | K35: 1.7057377 | L35: 1.7057377 | M35: 1.7057377 | N35: 1.7057377 | O35: 1.7057377 | P35: 1.7057377 | Q35: 1.7057377 | R35: 1.7057377
C37: demand | D37: 1 | E37: 2 | F37: 3 | G37: 4 | H37: 5 | I37: 6 | J37: 7 | K37: 8 | L37: 9 | M37: 10 | N37: 11 | O37: 12 | P37: 13 | Q37: 14 | R37: 15
C38: 1 | D38: 231.5 | E38: 297.34 | F38: 217.82 | G38: 222.62 | H38: 453.86 | I38: 315.98 | J38: 216.18 | K38: 463.97 | L38: 404.65 | M38: 334.69 | N38: 440.61 | O38: 225.39 | P38: 314.98 | Q38: 305.23 | R38: 541.84
C39: 2 | D39: 358.95 | E39: 308.97 | F39: 264.61 | G39: 343.62 | H39: 399.3 | I39: 433.24 | J39: 310.82 | K39: 234.15 | L39: 302.73 | M39: 304.23 | N39: 278.95 | O39: 403.93 | P39: 327.87 | Q39: 462.67 | R39: 445.18
C40: 3 | D40: 492.88 | E40: 260.36 | F40: 232.33 | G40: 514.32 | H40: 271.63 | I40: 506.16 | J40: 393.21 | K40: 346.58 | L40: 267.82 | M40: 272.81 | N40: 372.8 | O40: 326.64 | P40: 338.03 | Q40: 348.46 | R40: 405.85
B42: Parâmetros p/ μy | C42: Média(E(RLT)) | D42: 1 | E42: 2 | F42: 3 | G42: 4 | H42: 5 | I42: 6 | J42: 7 | K42: 8 | L42: 9 | M42: 10 | N42: 11 | O42: 12 | P42: 13 | Q42: 14 | R42: 15
B43: ND*RLT e S2nd | C43: 1 | D43: 9.45 | E43: 14.92 | F43: 14.79 | G43: 17.69 | H43: 14.79 | I43: 14.31 | J43: 10.15 | K43: 14.45 | L43: 12.52 | M43: 11.45 | N43: 13.36 | O43: 13.38 | P43: 14.59 | Q43: 14.28 | R43: 16.04
C44: 2 | D44: 13.11 | E44: 17.64 | F44: 11.65 | G44: 20.06 | H44: 11.73 | I44: 15.92 | J44: 12.08 | K44: 15.93 | L44: 10.8 | M44: 13.12 | N44: 12.44 | O44: 15.71 | P44: 19.48 | Q44: 17.94 | R44: 13.48
C45: -40028922 | D45: -40028922 | E45: 19.27 | F45: 20.64 | G45: 13.97 | H45: 13.78 | I45: 17.6 | J45: 12.66 | K45: 13.15 | L45: 16.36 | M45: 15.94 | N45: 10.35 | O45: 14.02 | P45: 14.06 | Q45: 12.12 | R45: 12.77
C47: Cap | D47: 1 | E47: 2 | F47: 3 | G47: 4 | H47: 5 | I47: 6 | J47: 7 | K47: 8 | L47: 9 | M47: 10 | N47: 11 | O47: 12 | P47: 13 | Q47: 14 | R47: 15
C48: 1 | D48: 304.6 | E48: 336.22 | F48: 367.37 | G48: 330.6 | H48: 407.16 | I48: 209.81 | J48: 353.15 | K48: 325.44 | L48: 303.38 | M48: 363.91 | N48: 423.84 | O48: 250.7 | P48: 253.28 | Q48: 216.52 | R48: 388.77
C49: 2 | D49: 288.68 | E49: 254.58 | F49: 333.83 | G49: 569.96 | H49: 363.61 | I49: 359.54 | J49: 304.66 | K49: 312.17 | L49: 379.11 | M49: 233.3 | N49: 387.92 | O49: 330.06 | P49: 266.36 | Q49: 408.27 | R49: 358.07
...

Sheet Matlab_Data
C1: SUPPLIERS
C2: demand | D2: 1 | E2: 2 | F2: 3 | G2: 4 | H2: 5 | I2: 6 | J2: 7 | K2: 8 | L2: 9 | M2: 10 | N2: 11 | O2: 12 | P2: 13 | Q2: 14 | R2: 15
C3: 1 | D3: =Demand!AU5 | E3: =Demand!AV5 | F3: =Demand!AW5 | G3: =Demand!AX5 | H3: =Demand!AY5 | I3: =Demand!AZ5 | J3: =Demand!BA5 | K3: =Demand!BB5 | ... R3: =Demand!BI5
C4: 2 | D4: =Demand!AU6 | E4: =Demand!AV6 | F4: =Demand!AW6 | G4: =Demand!AX6 | H4: =Demand!AY6 | I4: =Demand!AZ6 | J4: =Demand!BA6 | K4: =Demand!BB6 | ... R4: =Demand!BI6
C5: 3 | D5: =Demand!AU7 | E5: =Demand!AV7 | F5: =Demand!AW7 | G5: =Demand!AX7 | H5: =Demand!AY7 | I5: =Demand!AZ7 | J5: =Demand!BA7 | K5: =Demand!BB7 | ... R5: =Demand!BI7
B7: Parâmetro p/ μy | C7: Média(E(RLT)) | D7: 1 | E7: 2 | F7: 3 | G7: 4 | H7: 5 | I7: 6 | J7: 7 | K7: 8 | L7: 9 | M7: 10 | N7: 11 | O7: 12 | P7: 13 | Q7: 14 | R7: 15
B8: LB e DesvPad(ND*RLT) | C8: 1 | D8: =Suppliers!I22 | E8: =Suppliers!J22 | F8: =Suppliers!K22 | G8: =Suppliers!L22 | H8: =Suppliers!M22 | I8: =Suppliers!N22 | J8: =Suppliers!O22 | K8: =Suppliers!P22 | ... R8: =Suppliers!W22
B9: LB e DesvPad(ND*RLT) | C9: 2 | D9: =Suppliers!I23 | E9: =Suppliers!J23 | F9: =Suppliers!K23 | G9: =Suppliers!L23 | H9: =Suppliers!M23 | I9: =Suppliers!N23 | J9: =Suppliers!O23 | K9: =Suppliers!P23 | ... R9: =Suppliers!W23
B10: LB e DesvPad(ND*RLT) | C10: 3 | D10: =Suppliers!I24 | E10: =Suppliers!J24 | F10: =Suppliers!K24 | G10: =Suppliers!L24 | H10: =Suppliers!M24 | I10: =Suppliers!N24 | J10: =Suppliers!O24 | K10: =Suppliers!P24 | ... R10: =Suppliers!W24
C12: Cap | D12: 1 | E12: 2 | F12: 3 | G12: 4 | H12: 5 | I12: 6 | J12: 7 | K12: 8 | L12: 9 | M12: 10 | N12: 11 | O12: 12 | P12: 13 | Q12: 14 | R12: 15
C13: 1 | D13: =Suppliers_Cap!D14 | E13: =Suppliers_Cap!E14 | F13: =Suppliers_Cap!F14 | G13: =Suppliers_Cap!G14 | H13: =Suppliers_Cap!H14 | I13: =Suppliers_Cap!I14 | J13: =Suppliers_Cap!J14 | K13: =Suppliers_Cap!K14 | ... R13: =Suppliers_Cap!R14
C14: 2 | D14: =Suppliers_Cap!D15 | E14: =Suppliers_Cap!E15 | F14: =Suppliers_Cap!F15 | G14: =Suppliers_Cap!G15 | H14: =Suppliers_Cap!H15 | I14: =Suppliers_Cap!I15 | J14: =Suppliers_Cap!J15 | K14: =Suppliers_Cap!K15 | ... R14: =Suppliers_Cap!R15
C15: 3 | D15: =Suppliers_Cap!D16 | E15: =Suppliers_Cap!E16 | F15: =Suppliers_Cap!F16 | G15: =Suppliers_Cap!G16 | H15: =Suppliers_Cap!H16 | I15: =Suppliers_Cap!I16 | J15: =Suppliers_Cap!J16 | K15: =Suppliers_Cap!K16 | ... R15: =Suppliers_Cap!R16
B17: Parâmetro p/ μx | C17: Var(d-cap) | D17: 1 | E17: 2 | F17: 3 | G17: 4 | H17: 5 | I17: 6 | J17: 7 | K17: 8 | L17: 9 | M17: 10 | N17: 11 | O17: 12 | P17: 13 | Q17: 14 | R17: 15
B18: LB | C18: 1 | D18: =Suppliers!I17^2 | E18: =Suppliers!J17^2 | F18: =Suppliers!K17^2 | G18: =Suppliers!L17^2 | H18: =Suppliers!M17^2 | I18: =Suppliers!N17^2 | J18: =Suppliers!O17^2 | K18: =Suppliers!P17^2 | ... R18: =Suppliers!W17^2
B19: LB | C19: 2 | D19: =Suppliers!I18^2 | E19: =Suppliers!J18^2 | F19: =Suppliers!K18^2 | G19: =Suppliers!L18^2 | H19: =Suppliers!M18^2 | I19: =Suppliers!N18^2 | J19: =Suppliers!O18^2 | K19: =Suppliers!P18^2 | ... R19: =Suppliers!W18^2
B20: LB | C20: 3 | D20: =Suppliers!I19^2 | E20: =Suppliers!J19^2 | F20: =Suppliers!K19^2 | G20: =Suppliers!L19^2 | H20: =Suppliers!M19^2 | I20: =Suppliers!N19^2 | J20: =Suppliers!O19^2 | K20: =Suppliers!P19^2 | ... R20: =Suppliers!W19^2
B22: Parâmetro p/ σx | C22: Desvpad(Var(S2nd)) | D22: 1 | E22: 2 | F22: 3 | G22: 4 | H22: 5 | I22: 6 | J22: 7 | K22: 8 | L22: 9 | M22: 10 | N22: 11 | O22: 12 | P22: 13 | Q22: 14 | R22: 15
B23: LB | C23: 1 | D23: =Supp_Fourth_central_moment_5var!D35 | E23: =Supp_Fourth_central_moment_5var!E35 | F23: =Supp_Fourth_central_moment_5var!F35 | G23: =Supp_Fourth_central_moment_5var!G35 | H23: =Supp_Fourth_central_moment_5var!H35 | I23: =Supp_Fourth_central_moment_5var!I35 | J23: =Supp_Fourth_central_moment_5var!J35 | K23: =Supp_Fourth_central_moment_5var!K35 | ... R23: =Supp_Fourth_central_moment_5var!R35
B24: LB | C24: 2 | D24: =Supp_Fourth_central_moment_5var!D36 | E24: =Supp_Fourth_central_moment_5var!E36 | F24: =Supp_Fourth_central_moment_5var!F36 | G24: =Supp_Fourth_central_moment_5var!G36 | H24: =Supp_Fourth_central_moment_5var!H36 | I24: =Supp_Fourth_central_moment_5var!I36 | J24: =Supp_Fourth_central_moment_5var!J36 | K24: =Supp_Fourth_central_moment_5var!K36 | ... R24: =Supp_Fourth_central_moment_5var!R36
B25: LB | C25: 3 | D25: =Supp_Fourth_central_moment_5var!D37 | E25: =Supp_Fourth_central_moment_5var!E37 | F25: =Supp_Fourth_central_moment_5var!F37 | G25: =Supp_Fourth_central_moment_5var!G37 | H25: =Supp_Fourth_central_moment_5var!H37 | I25: =Supp_Fourth_central_moment_5var!I37 | J25: =Supp_Fourth_central_moment_5var!J37 | K25: =Supp_Fourth_central_moment_5var!K37 | ... R25: =Supp_Fourth_central_moment_5var!R37
B27: Parâmetro p/ σy | C27: DesvPad(Var(E(RLT))) | D27: 1 | E27: 2 | F27: 3 | G27: 4 | H27: 5 | I27: 6 | J27: 7 | K27: 8 | L27: 9 | M27: 10 | N27: 11 | O27: 12 | P27: 13 | Q27: 14 | R27: 15
B28: LB e DesvPad(ND*RLT) | C28: 1 | D28: =Suppliers!I27 | E28: =Suppliers!J27 | F28: =Suppliers!K27 | G28: =Suppliers!L27 | H28: =Suppliers!M27 | I28: =Suppliers!N27 | J28: =Suppliers!O27 | K28: =Suppliers!P27 | ... R28: =Suppliers!W27
B29: LB e DesvPad(ND*RLT) | C29: 2 | D29: =Suppliers!I28 | E29: =Suppliers!J28 | F29: =Suppliers!K28 | G29: =Suppliers!L28 | H29: =Suppliers!M28 | I29: =Suppliers!N28 | J29: =Suppliers!O28 | K29: =Suppliers!P28 | ... R29: =Suppliers!W28
B30: LB e DesvPad(ND*RLT) | C30: 3 | D30: =Suppliers!I29 | E30: =Suppliers!J29 | F30: =Suppliers!K29 | G30: =Suppliers!L29 | H30: =Suppliers!M29 | I30: =Suppliers!N29 | J30: =Suppliers!O29 | K30: =Suppliers!P29 | ... R30: =Suppliers!W29
B32: Parâmetro p/ μx | C32: Média(d-Cap) | D32: 1 | E32: 2 | F32: 3 | G32: 4 | H32: 5 | I32: 6 | J32: 7 | K32: 8 | L32: 9 | M32: 10 | N32: 11 | O32: 12 | P32: 13 | Q32: 14 | R32: 15
B33: DesvPad(ND*RLT) | C33: 1 | D33: =D3-D13 | E33: =E3-E13 | F33: =F3-F13 | G33: =G3-G13 | H33: =H3-H13 | I33: =I3-I13 | J33: =J3-J13 | K33: =K3-K13 | ... R33: =R3-R13
B34: DesvPad(ND*RLT) | C34: 2 | D34: =D4-D14 | E34: =E4-E14 | F34: =F4-F14 | G34: =G4-G14 | H34: =H4-H14 | I34: =I4-I14 | J34: =J4-J14 | K34: =K4-K14 | ... R34: =R4-R14
B35: DesvPad(ND*RLT) | C35: 3 | D35: =D5-D15 | E35: =E5-E15 | F35: =F5-F15 | G35: =G5-G15 | H35: =H5-H15 | I35: =I5-I15 | J35: =J5-J15 | K35: =K5-K15 | ... R35: =R5-R15
B37: Parâmetro p/ σx | C37: DesvPad(Var(d-cap)) | D37: 1 | E37: 2 | F37: 3 | G37: 4 | H37: 5 | I37: 6 | J37: 7 | K37: 8 | L37: 9 | M37: 10 | N37: 11 | O37: 12 | P37: 13 | Q37: 14 | R37: 15
B38: DesvPad(ND*RLT) | C38: 1 | D38: =Suppliers!I17 | E38: =Suppliers!J17 | F38: =Suppliers!K17 | G38: =Suppliers!L17 | H38: =Suppliers!M17 | I38: =Suppliers!N17 | J38: =Suppliers!O17 | K38: =Suppliers!P17 | ... R38: =Suppliers!W17
B39: DesvPad(ND*RLT) | C39: 2 | D39: =Suppliers!I18 | E39: =Suppliers!J18 | F39: =Suppliers!K18 | G39: =Suppliers!L18 | H39: =Suppliers!M18 | I39: =Suppliers!N18 | J39: =Suppliers!O18 | K39: =Suppliers!P18 | ... R39: =Suppliers!W18
B40: DesvPad(ND*RLT) | C40: 3 | D40: =Suppliers!I19 | E40: =Suppliers!J19 | F40: =Suppliers!K19 | G40: =Suppliers!L19 | H40: =Suppliers!M19 | I40: =Suppliers!N19 | J40: =Suppliers!O19 | K40: =Suppliers!P19 | ... R40: =Suppliers!W19
C42: Prob1 | D42: 0.98
C44: LB | D44: 1 | E44: 2 | F44: 3 | G44: 4 | H44: 5 | I44: 6 | J44: 7 | K44: 8 | L44: 9 | M44: 10 | N44: 11 | O44: 12 | P44: 13 | Q44: 14 | R44: 15
C45: 1 | D45: 0 | E45: 0 | F45: 0 | G45: 0 | H45: 15818.302 | I45: 6132.0093 | J45: 0 | K45: 13708.849 | L45: 9372.3396 | M45: 0 | N45: 14327.465 | O45: 0 | P45: 6918.3969 | Q45: 5897.5627 | R45: 21002.39
C46: 2 | D46: 8074.1812 | E46: 8186.4463 | F46: 0 | G46: 0 | H46: 9834.2635 | I46: 14601.568 | J46: 6563.4316 | K46: 0 | L46: 0 | M46: 5627.9126 | N46: 0 | O46: 12387.656 | P46: 10079.393 | Q46: 19670.323 | R46: 12770.938
C47: 3 | D47: 19048.847 | E47: 0 | F47: 0 | G47: 17725.552 | H47: 0 | I47: 18633.411 | J47: 7876.7163 | K47: 0 | L47: 0 | M47: 0 | N47: 6106.9843 | O47: 8295.8778 | P47: 0 | Q47: 0 | R47: 10070.459
C49: DesvPad(ND*ELT) | D49: 1 | E49: 2 | F49: 3 | G49: 4 | H49: 5 | I49: 6 | J49: 7 | K49: 8 | L49: 9 | M49: 10 | N49: 11 | O49: 12 | P49: 13 | Q49: 14 | R49: 15
C50: 1 | D50: 0 | E50: 0 | F50: 0 | G50: 0 | H50: 89.3519 | I50: 58.127 | J50: 0 | K50: 86.0169 | L50: 70.3036 | M50: 0 | N50: 84.7408 | O50: 0 | P50: 59.7737 | Q50: 56.3029 | R50: 106.0337
...

Sheet Estado da arte
C1: SUPPLIERS
B2: Parâmetros p/ | C2: demand | D2: 1 | E2: 2 | F2: 3 | G2: 4 | H2: 5 | I2: 6 | J2: 7 | K2: 8 | L2: 9 | M2: 10 | N2: 11 | O2: 12 | P2: 13 | Q2: 14 | R2: 15
B3: Prob(D*ELT) | C3: 1 | D3: =Demand!AU5 | E3: =Demand!AV5 | F3: =Demand!AW5 | G3: =Demand!AX5 | H3: =Demand!AY5 | I3: =Demand!AZ5 | J3: =Demand!BA5 | K3: =Demand!BB5 | ... R3: =Demand!BI5
B4: Prob(D*ELT) | C4: 2 | D4: =Demand!AU6 | E4: =Demand!AV6 | F4: =Demand!AW6 | G4: =Demand!AX6 | H4: =Demand!AY6 | I4: =Demand!AZ6 | J4: =Demand!BA6 | K4: =Demand!BB6 | ... R4: =Demand!BI6
B5: Prob(D*ELT) | C5: 3 | D5: =Demand!AU7 | E5: =Demand!AV7 | F5: =Demand!AW7 | G5: =Demand!AX7 | H5: =Demand!AY7 | I5: =Demand!AZ7 | J5: =Demand!BA7 | K5: =Demand!BB7 | ... R5: =Demand!BI7
A6: CV
A7: 0.2 | B7: Parâmetros | C7: DesvPad(demand) | D7: 1 | E7: 2 | F7: 3 | G7: 4 | H7: 5 | I7: 6 | J7: 7 | K7: 8 | L7: 9 | M7: 10 | N7: 11 | O7: 12 | P7: 13 | Q7: 14 | R7: 15
B8: Prob(D*ELT) | C8: 1 | D8: =D3*0.2 | E8: =E3*0.2 | F8: =F3*0.2 | G8: =G3*0.2 | H8: =H3*0.2 | I8: =I3*0.2 | J8: =J3*0.2 | K8: =K3*0.2 | ... R8: =R3*0.2
B9: Prob(D*ELT) | C9: 2 | D9: =D4*0.2 | E9: =E4*0.2 | F9: =F4*0.2 | G9: =G4*0.2 | H9: =H4*0.2 | I9: =I4*0.2 | J9: =J4*0.2 | K9: =K4*0.2 | ... R9: =R4*0.2
B10: Prob(D*ELT) | C10: 3 | D10: =D5*0.2 | E10: =E5*0.2 | F10: =F5*0.2 | G10: =G5*0.2 | H10: =H5*0.2 | I10: =I5*0.2 | J10: =J5*0.2 | K10: =K5*0.2 | ... R10: =R5*0.2
B12: Parâmetros | C12: Média(E(RLT)) | D12: 1 | E12: 2 | F12: 3 | G12: 4 | H12: 5 | I12: 6 | J12: 7 | K12: 8 | L12: 9 | M12: 10 | N12: 11 | O12: 12 | P12: 13 | Q12: 14 | R12: 15
B13: Prob(D*ELT) | C13: 1 | D13: =Suppliers!I22 | E13: =Suppliers!J22 | F13: =Suppliers!K22 | G13: =Suppliers!L22 | H13: =Suppliers!M22 | I13: =Suppliers!N22 | J13: =Suppliers!O22 | K13: =Suppliers!P22 | ... R13: =Suppliers!W22
B14: Prob(D*ELT) | C14: 2 | D14: =Suppliers!I23 | E14: =Suppliers!J23 | F14: =Suppliers!K23 | G14: =Suppliers!L23 | H14: =Suppliers!M23 | I14: =Suppliers!N23 | J14: =Suppliers!O23 | K14: =Suppliers!P23 | ... R14: =Suppliers!W23
B15: Prob(D*ELT) | C15: 3 | D15: =Suppliers!I24 | E15: =Suppliers!J24 | F15: =Suppliers!K24 | G15: =Suppliers!L24 | H15: =Suppliers!M24 | I15: =Suppliers!N24 | J15: =Suppliers!O24 | K15: =Suppliers!P24 | ... R15: =Suppliers!W24
A17: CV | B17: Parâmetros | C17: DesvPad(E(RLT)) | D17: 1 | E17: 2 | F17: 3 | G17: 4 | H17: 5 | I17: 6 | J17: 7 | K17: 8 | L17: 9 | M17: 10 | N17: 11 | O17: 12 | P17: 13 | Q17: 14 | R17: 15
A18: 0.2 | B18: Prob(D*ELT) | C18: 1 | D18: =D13*0.2 | E18: =E13*0.2 | F18: =F13*0.2 | G18: =G13*0.2 | H18: =H13*0.2 | I18: =I13*0.2 | J18: =J13*0.2 | K18: =K13*0.2 | ... R18: =R13*0.2
B19: Prob(D*ELT) | C19: 2 | D19: =D14*0.2 | E19: =E14*0.2 | F19: =F14*0.2 | G19: =G14*0.2 | H19: =H14*0.2 | I19: =I14*0.2 | J19: =J14*0.2 | K19: =K14*0.2 | ... R19: =R14*0.2
B20: Prob(D*ELT) | C20: 3 | D20: =D15*0.2 | E20: =E15*0.2 | F20: =F15*0.2 | G20: =G15*0.2 | H20: =H15*0.2 | I20: =I15*0.2 | J20: =J15*0.2 | K20: =K15*0.2 | ... R20: =R15*0.2
C23: z | D23: 2.06
C25: DesvPad | D25: 1 | E25: 2 | F25: 3 | G25: 4 | H25: 5 | I25: 6 | J25: 7 | K25: 8 | L25: 9 | M25: 10 | N25: 11 | O25: 12 | P25: 13 | Q25: 14 | R25: 15
C26: 1 | D26: =(D13*(D8^2)+(D3^2)*(D18^2))^0.5 | E26: =(E13*(E8^2)+(E3^2)*(E18^2))^0.5 | F26: =(F13*(F8^2)+(F3^2)*(F18^2))^0.5 | G26: =(G13*(G8^2)+(G3^2)*(G18^2))^0.5 | H26: =(H13*(H8^2)+(H3^2)*(H18^2))^0.5 | I26: =(I13*(I8^2)+(I3^2)*(I18^2))^0.5 | J26: =(J13*(J8^2)+(J3^2)*(J18^2))^0.5 | K26: =(K13*(K8^2)+(K3^2)*(K18^2))^0.5 | ... R26: =(R13*(R8^2)+(R3^2)*(R18^2))^0.5
C27: 2 | D27: =(D14*(D9^2)+(D4^2)*(D19^2))^0.5 | E27: =(E14*(E9^2)+(E4^2)*(E19^2))^0.5 | F27: =(F14*(F9^2)+(F4^2)*(F19^2))^0.5 | G27: =(G14*(G9^2)+(G4^2)*(G19^2))^0.5 | H27: =(H14*(H9^2)+(H4^2)*(H19^2))^0.5 | I27: =(I14*(I9^2)+(I4^2)*(I19^2))^0.5 | J27: =(J14*(J9^2)+(J4^2)*(J19^2))^0.5 | K27: =(K14*(K9^2)+(K4^2)*(K19^2))^0.5 | ... R27: =(R14*(R9^2)+(R4^2)*(R19^2))^0.5
C28: 3 | D28: =(D15*(D10^2)+(D5^2)*(D20^2))^0.5 | E28: =(E15*(E10^2)+(E5^2)*(E20^2))^0.5 | F28: =(F15*(F10^2)+(F5^2)*(F20^2))^0.5 | G28: =(G15*(G10^2)+(G5^2)*(G20^2))^0.5 | H28: =(H15*(H10^2)+(H5^2)*(H20^2))^0.5 | I28: =(I15*(I10^2)+(I5^2)*(I20^2))^0.5 | J28: =(J15*(J10^2)+(J5^2)*(J20^2))^0.5 | K28: =(K15*(K10^2)+(K5^2)*(K20^2))^0.5 | ... R28: =(R15*(R10^2)+(R5^2)*(R20^2))^0.5
C30: Média(Demand*ELT) | D30: 1 | E30: 2 | F30: 3 | G30: 4 | H30: 5 | I30: 6 | J30: 7 | K30: 8 | L30: 9 | M30: 10 | N30: 11 | O30: 12 | P30: 13 | Q30: 14 | R30: 15
C31: 1 | D31: =D3*D13 | E31: =E3*E13 | F31: =F3*F13 | G31: =G3*G13 | H31: =H3*H13 | I31: =I3*I13 | J31: =J3*J13 | K31: =K3*K13 | ... R31: =R3*R13
C32: 2 | D32: =D4*D14 | E32: =E4*E14 | F32: =F4*F14 | G32: =G4*G14 | H32: =H4*H14 | I32: =I4*I14 | J32: =J4*J14 | K32: =K4*K14 | ... R32: =R4*R14
C33: 3 | D33: =D5*D15 | E33: =E5*E15 | F33: =F5*F15 | G33: =G5*G15 | H33: =H5*H15 | I33: =I5*I15 | J33: =J5*J15 | K33: =K5*K15 | ... R33: =R5*R15
B35: Parâmetro p/ c | C35: Reposição | D35: 1 | E35: 2 | F35: 3 | G35: 4 | H35: 5 | I35: 6 | J35: 7 | K35: 8 | L35: 9 | M35: 10 | N35: 11 | O35: 12 | P35: 13 | Q35: 14 | R35: 15
B36: Prob(D*ELT) | C36: 1 | D36: =D31+$D$23*D26 | E36: =E31+$D$23*E26 | F36: =F31+$D$23*F26 | G36: =G31+$D$23*G26 | H36: =H31+$D$23*H26 | I36: =I31+$D$23*I26 | J36: =J31+$D$23*J26 | K36: =K31+$D$23*K26 | ... R36: =R31+$D$23*R26
B37: Prob(D*ELT) | C37: 2 | D37: =D32+$D$23*D27 | E37: =E32+$D$23*E27 | F37: =F32+$D$23*F27 | G37: =G32+$D$23*G27 | H37: =H32+$D$23*H27 | I37: =I32+$D$23*I27 | J37: =J32+$D$23*J27 | K37: =K32+$D$23*K27 | ... R37: =R32+$D$23*R27
B38: Prob(D*ELT) | C38: 3 | D38: =D33+$D$23*D28 | E38: =E33+$D$23*E28 | F38: =F33+$D$23*F28 | G38: =G33+$D$23*G28 | H38: =H33+$D$23*H28 | I38: =I33+$D$23*I28 | J38: =J33+$D$23*J28 | K38: =K33+$D$23*K28 | ... R38: =R33+$D$23*R28
C40: P(Reposição) | D40: 1 | E40: 2 | F40: 3 | G40: 4 | H40: 5 | I40: 6 | J40: 7 | K40: 8 | L40: 9 | M40: 10 | N40: 11 | O40: 12 | P40: 13 | Q40: 14 | R40: 15
C41: 1
C42: 2
C43: 3
C45: Factories
B46: Parâmetros p/ | C46: demand | D46: 16 | E46: 17 | F46: 18
B47: Prob(D*ELT) | C47: 4 | D47: =Demand!AU11 | E47: =Demand!AV11 | F47: =Demand!AW11
B48: Prob(D*ELT) | C48: 5 | D48: =Demand!AU12 | E48: =Demand!AV12 | F48: =Demand!AW12
B49: Prob(D*ELT) | C49: 6 | D49: =Demand!AU13 | E49: =Demand!AV13 | F49: =Demand!AW13
...

Sheet Main_variables
B1: SUPPLIERS | C1: Planilha mãe | V1: =SUM(V13:V135) | Y1: 1 | Z1: SUPPLIERS | AU1: 2 | AV1: SUPPLIERS | BQ1: 3 | BR1: SUPPLIERS | CM1: 4 | CN1: SUPPLIERS | DI1: 5 | DJ1: SUPPLIERS | EE1: 6 | EF1: SUPPLIERS | FA1: 7 | FB1: SUPPLIERS | FW1: 8 | FX1: SUPPLIERS | GS1: 9 | GT1: SUPPLIERS
B2: Objective | C2: P(Reorder) | D2: 1 | E2: 2 | F2: 3 | G2: 4 | H2: 5 | I2: 6 | J2: 7 | K2: 8 | L2: 9 | M2: 10 | N2: 11 | O2: 12 | P2: 13 | Q2: 14 | R2: 15 | S2: Objective | Z2: Objective | AA2: P(Reorder) | AB2: 1 | AC2: 2 | AD2: 3 | AE2: 4 | AF2: 5 | AG2: 6 | AH2: 7 | AI2: 8 | AJ2: 9 | AK2: 10 | AL2: 11 | AM2: 12 | AN2: 13 | AO2: 14 | AP2: 15 | AV2: Objective | AW2: P(Reorder) | AX2: 1 | AY2: 2 | AZ2: 3 | BA2: 4 | BB2: 5 | BC2: 6 | BD2: 7 | BE2: 8 | BF2: 9 | BG2: 10 | BH2: 11 | BI2: 12 | BJ2: 13 | BK2: 14 | BL2: 15 | BR2: Objective | BS2: P(Reorder) | BT2: 1 | BU2: 2 | BV2: 3 | BW2: 4 | BX2: 5 | BY2: 6 | BZ2: 7 | CA2: 8 | CB2: 9 | CC2: 10 | CD2: 11 | CE2: 12 | CF2: 13 | CG2: 14 | CH2: 15 | CN2: Objective | CO2: P(Reorder) | CP2: 1 | CQ2: 2 | CR2: 3 | CS2: 4 | CT2: 5 | CU2: 6 | CV2: 7 | CW2: 8 | CX2: 9 | CY2: 10 | CZ2: 11 | DA2: 12 | DB2: 13 | DC2: 14 | DD2: 15 | DJ2: Objective | DK2: P(Reorder) | DL2: 1 | DM2: 2 | DN2: 3 | DO2: 4 | DP2: 5 | DQ2: 6 | DR2: 7 | DS2: 8 | DT2: 9 | DU2: 10 | DV2: 11 | DW2: 12 | DX2: 13 | DY2: 14 | DZ2: 15 | EF2: Objective | EG2: P(Reorder) | EH2: 1 | EI2: 2 | EJ2: 3 | EK2: 4 | EL2: 5 | EM2: 6 | EN2: 7 | EO2: 8 | EP2: 9 | EQ2: 10 | ER2: 11 | ES2: 12 | ET2: 13 | EU2: 14 | EV2: 15 | FB2: Objective | FC2: P(Reorder) | FD2: 1 | FE2: 2 | FF2: 3 | FG2: 4 | FH2: 5 | FI2: 6 | FJ2: 7 | FK2: 8 | FL2: 9 | FM2: 10 | FN2: 11 | FO2: 12 | FP2: 13 | FQ2: 14 | FR2: 15 | FX2: Objective | FY2: P(Reorder) | FZ2: 1 | GA2: 2 | GB2: 3 | GC2: 4 | GD2: 5 | GE2: 6 | GF2: 7 | GG2: 8 | GH2: 9 | GI2: 10 | GJ2: 11 | GK2: 12 | GL2: 13 | GM2: 14 | GN2: 15 | GT2: Objective | GU2: P(Reorder) | GV2: 1 | GW2: 2 | GX2: 3 | GY2: 4 | GZ2: 5 | HA2: 6 | HB2: 7 | HC2: 8 | HD2: 9 | HE2: 10 | HF2: 11 | HG2: 12 | HH2: 13 | HI2: 14 | HJ2: 15
B3: =Optimal_solutionw | C3: 1 | S3: 5778156.3 | Z3: 5778156.3 | AA3: 1 | AV3: 5653943.2 | AW3: 1 | BR3: 5710823.4 | BS3: 1 | CN3: 5778123.9 | CO3: 1 | DJ3: 5653943.2 | DK3: 1 | EF3: 5710823.4 | EG3: 1 | FB3: 5778123.9 | FC3: 1 | FX3: 5653943.2 | FY3: 1 | GT3: 5710823.4 | GU3: 1
C4: 2 | S4: DIFERENÇA | AA4: 2 | AW4: 2 | BS4: 2 | CO4: 2 | DK4: 2 | EG4: 2 | FC4: 2 | FY4: 2 | GU4: 2
C5: 3 | S5: =B3-S3 | AA5: 3 | AW5: 3 | BS5: 3 | CO5: 3 | DK5: 3 | EG5: 3 | FC5: 3 | FY5: 3 | GU5: 3
B7: NOVA | C7: P(Estado da arte) | D7: 1 | E7: 2 | F7: 3 | G7: 4 | H7: 5 | I7: 6 | J7: 7 | K7: 8 | L7: 9 | M7: 10 | N7: 11 | O7: 12 | P7: 13 | Q7: 14 | R7: 15 | AA7: P(Estado da arte) | AB7: 1 | AC7: 2 | AD7: 3 | AE7: 4 | AF7: 5 | AG7: 6 | AH7: 7 | AI7: 8 | AJ7: 9 | AK7: 10 | AL7: 11 | AM7: 12 | AN7: 13 | AO7: 14 | AP7: 15 | AW7: P(Estado da arte) | AX7: 1 | AY7: 2 | AZ7: 3 | BA7: 4 | BB7: 5 | BC7: 6 | BD7: 7 | BE7: 8 | BF7: 9 | BG7: 10 | BH7: 11 | BI7: 12 | BJ7: 13 | BK7: 14 | BL7: 15 | BS7: P(Estado da arte) | BT7: 1 | BU7: 2 | BV7: 3 | BW7: 4 | BX7: 5 | BY7: 6 | BZ7: 7 | CA7: 8 | CB7: 9 | CC7: 10 | CD7: 11 | CE7: 12 | CF7: 13 | CG7: 14 | CH7: 15 | CO7: P(Estado da arte) | CP7: 1 | CQ7: 2 | CR7: 3 | CS7: 4 | CT7: 5 | CU7: 6 | CV7: 7 | CW7: 8 | CX7: 9 | CY7: 10 | CZ7: 11 | DA7: 12 | DB7: 13 | DC7: 14 | DD7: 15 | DK7: P(Estado da arte) | DL7: 1 | DM7: 2 | DN7: 3 | DO7: 4 | DP7: 5 | DQ7: 6 | DR7: 7 | DS7: 8 | DT7: 9 | DU7: 10 | DV7: 11 | DW7: 12 | DX7: 13 | DY7: 14 | DZ7: 15 | EG7: P(Estado da arte) | EH7: 1 | EI7: 2 | EJ7: 3 | EK7: 4 | EL7: 5 | EM7: 6 | EN7: 7 | EO7: 8 | EP7: 9 | EQ7: 10 | ER7: 11 | ES7: 12 | ET7: 13 | EU7: 14 | EV7: 15 | FC7: P(Estado da arte) | FD7: 1 | FE7: 2 | FF7: 3 | FG7: 4 | FH7: 5 | FI7: 6 | FJ7: 7 | FK7: 8 | FL7: 9 | FM7: 10 | FN7: 11 | FO7: 12 | FP7: 13 | FQ7: 14 | FR7: 15 | FY7: P(Estado da arte) | FZ7: 1 | GA7: 2 | GB7: 3 | GC7: 4 | GD7: 5 | GE7: 6 | GF7: 7 | GG7: 8 | GH7: 9 | GI7: 10 | GJ7: 11 | GK7: 12 | GL7: 13 | GM7: 14 | GN7: 15 | GU7: P(Estado da arte) | GV7: 1 | GW7: 2 | GX7: 3 | GY7: 4 | GZ7: 5 | HA7: 6 | HB7: 7 | HC7: 8 | HD7: 9 | HE7: 10 | HF7: 11 | HG7: 12 | HH7: 13 | HI7: 14 | HJ7: 15
C8: 1 | D8: ='Estado da arte'!D41 | E8: ='Estado da arte'!E41 | F8: ='Estado da arte'!F41 | G8: ='Estado da arte'!G41 | H8: ='Estado da arte'!H41 | I8: ='Estado da arte'!I41 | J8: ='Estado da arte'!J41 | K8: ='Estado da arte'!K41 | ... R8: ='Estado da arte'!R41 | AA8: 1 | AB8: 0 | AC8: 0 | AD8: 0 | AE8: 0 | AF8: 0 | AG8: 0 | AH8: 0 | AI8: 0 | AJ8: 0 | AK8: 0 | AL8: 0 | AM8: 0 | AN8: 0 | AO8: 0 | AP8: 0 | AW8: 1 | AX8: 0 | AY8: 0 | AZ8: 0 | BA8: 0 | BB8: 0 | BC8: 0 | BD8: 0 | BE8: 0 | BF8: 0 | BG8: 0 | BH8: 0 | BI8: 0 | BJ8: 0 | BK8: 0 | BL8: 0 | BS8: 1 | BT8: 0 | BU8: 0 | BV8: 0 | BW8: 0 | BX8: 0 | BY8: 0 | BZ8: 0 | CA8: 0 | CB8: 0 | CC8: 0 | CD8: 0 | CE8: 0 | CF8: 0 | CG8: 0 | CH8: 0 | CO8: 1 | CP8: 0 | CQ8: 0 | CR8: 0 | CS8: 0 | CT8: 0 | CU8: 0 | CV8: 0 | CW8: 0 | CX8: 0 | CY8: 0 | CZ8: 0 | DA8: 0 | DB8: 0 | DC8: 0 | DD8: 0 | DK8: 1 | DL8: 0 | DM8: 0 | DN8: 0 | DO8: 0 | DP8: 0 | DQ8: 0 | DR8: 0 | DS8: 0 | DT8: 0 | DU8: 0 | DV8: 0 | DW8: 0 | DX8: 0 | DY8: 0 | DZ8: 0 | EG8: 1 | EH8: 0 | EI8: 0 | EJ8: 0 | EK8: 0 | EL8: 0 | EM8: 0 | EN8: 0 | EO8: 0 | EP8: 0 | EQ8: 0 | ER8: 0 | ES8: 0 | ET8: 0 | EU8: 0 | EV8: 0 | FC8: 1 | FD8: 0 | FE8: 0 | FF8: 0 | FG8: 0 | FH8: 0 | FI8: 0 | FJ8: 0 | FK8: 0 | FL8: 0 | FM8: 0 | FN8: 0 | FO8: 0 | FP8: 0 | FQ8: 0 | FR8: 0 | FY8: 1 | FZ8: 0 | GA8: 0 | GB8: 0 | GC8: 0 | GD8: 0 | GE8: 0 | GF8: 0 | GG8: 0 | GH8: 0 | GI8: 0 | GJ8: 0 | GK8: 0 | GL8: 0 | GM8: 0 | GN8: 0 | GU8: 1 | GV8: 0 | GW8: 0 | GX8: 0 | GY8: 0 | GZ8: 0 | HA8: 0 | HB8: 0 | HC8: 0 | HD8: 0 | HE8: 0 | HF8: 0 | HG8: 0 | HH8: 0 | HI8: 0 | HJ8: 0
C9: 2 | D9: ='Estado da arte'!D42 | E9: ='Estado da arte'!E42 | F9: ='Estado da arte'!F42 | G9: ='Estado da arte'!G42 | H9: ='Estado da arte'!H42 | I9: ='Estado da arte'!I42 | J9: ='Estado da arte'!J42 | K9: ='Estado da arte'!K42 | ... R9: ='Estado da arte'!R42 | AA9: 2 | AB9: 0 | AC9: 0 | AD9: 0 | AE9: 0 | AF9: 0 | AG9: 0 | AH9: 0 | AI9: 0 | AJ9: 0 | AK9: 0 | AL9: 0 | AM9: 0 | AN9: 0 | AO9: 0 | AP9: 0 | AW9: 2 | AX9: 0 | AY9: 0 | AZ9: 0 | BA9: 0 | BB9: 0 | BC9: 0 | BD9: 0 | BE9: 0 | BF9: 0 | BG9: 0 | BH9: 0 | BI9: 0 | BJ9: 0 | BK9: 0 | BL9: 0 | BS9: 2 | BT9: 0 | BU9: 0 | BV9: 0 | BW9: 0 | BX9: 0 | BY9: 0 | BZ9: 0 | CA9: 0 | CB9: 0 | CC9: 0 | CD9: 0 | CE9: 0 | CF9: 0 | CG9: 0 | CH9: 0 | CO9: 2 | CP9: 0 | CQ9: 0 | CR9: 0 | CS9: 0 | CT9: 0 | CU9: 0 | CV9: 0 | CW9: 0 | CX9: 0 | CY9: 0 | CZ9: 0 | DA9: 0 | DB9: 0 | DC9: 0 | DD9: 0 | DK9: 2 | DL9: 0 | DM9: 0 | DN9: 0 | DO9: 0 | DP9: 0 | DQ9: 0 | DR9: 0 | DS9: 0 | DT9: 0 | DU9: 0 | DV9: 0 | DW9: 0 | DX9: 0 | DY9: 0 | DZ9: 0 | EG9: 2 | EH9: 0 | EI9: 0 | EJ9: 0 | EK9: 0 | EL9: 0 | EM9: 0 | EN9: 0 | EO9: 0 | EP9: 0 | EQ9: 0 | ER9: 0 | ES9: 0 | ET9: 0 | EU9: 0 | EV9: 0 | FC9: 2 | FD9: 0 | FE9: 0 | FF9: 0 | FG9: 0 | FH9: 0 | FI9: 0 | FJ9: 0 | FK9: 0 | FL9: 0 | FM9: 0 | FN9: 0 | FO9: 0 | FP9: 0 | FQ9: 0 | FR9: 0 | FY9: 2 | FZ9: 0 | GA9: 0 | GB9: 0 | GC9: 0 | GD9: 0 | GE9: 0 | GF9: 0 | GG9: 0 | GH9: 0 | GI9: 0 | GJ9: 0 | GK9: 0 | GL9: 0 | GM9: 0 | GN9: 0 | GU9: 2 | GV9: 0 | GW9: 0 | GX9: 0 | GY9: 0 | GZ9: 0 | HA9: 0 | HB9: 0 | HC9: 0 | HD9: 0 | HE9: 0 | HF9: 0 | HG9: 0 | HH9: 0 | HI9: 0 | HJ9: 0
C10: 3 | D10: ='Estado da arte'!D43 | E10: ='Estado da arte'!E43 | F10: ='Estado da arte'!F43 | G10: ='Estado da arte'!G43 | H10: ='Estado da arte'!H43 | I10: ='Estado da arte'!I43 | J10: ='Estado da arte'!J43 | K10: ='Estado da arte'!K43 | ... R10: ='Estado da arte'!R43 | AA10: 3 | AB10: 0 | AC10: 0 | AD10: 0 | AE10: 0 | AF10: 0 | AG10: 0 | AH10: 0 | AI10: 0 | AJ10: 0 | AK10: 0 | AL10: 0 | AM10: 0 | AN10: 0 | AO10: 0 | AP10: 0 | AW10: 3 | AX10: 0 | AY10: 0 | AZ10: 0 | BA10: 0 | BB10: 0 | BC10: 0 | BD10: 0 | BE10: 0 | BF10: 0 | BG10: 0 | BH10: 0 | BI10: 0 | BJ10: 0 | BK10: 0 | BL10: 0 | BS10: 3 | BT10: 0 | BU10: 0 | BV10: 0 | BW10: 0 | BX10: 0 | BY10: 0 | BZ10: 0 | CA10: 0 | CB10: 0 | CC10: 0 | CD10: 0 | CE10: 0 | CF10: 0 | CG10: 0 | CH10: 0 | CO10: 3 | CP10: 0 | CQ10: 0 | CR10: 0 | CS10: 0 | CT10: 0 | CU10: 0 | CV10: 0 | CW10: 0 | CX10: 0 | CY10: 0 | CZ10: 0 | DA10: 0 | DB10: 0 | DC10: 0 | DD10: 0 | DK10: 3 | DL10: 0 | DM10: 0 | DN10: 0 | DO10: 0 | DP10: 0 | DQ10: 0 | DR10: 0 | DS10: 0 | DT10: 0 | DU10: 0 | DV10: 0 | DW10: 0 | DX10: 0 | DY10: 0 | DZ10: 0 | EG10: 3 | EH10: 0 | EI10: 0 | EJ10: 0 | EK10: 0 | EL10: 0 | EM10: 0 | EN10: 0 | EO10: 0 | EP10: 0 | EQ10: 0 | ER10: 0 | ES10: 0 | ET10: 0 | EU10: 0 | EV10: 0 | FC10: 3 | FD10: 0 | FE10: 0 | FF10: 0 | FG10: 0 | FH10: 0 | FI10: 0 | FJ10: 0 | FK10: 0 | FL10: 0 | FM10: 0 | FN10: 0 | FO10: 0 | FP10: 0 | FQ10: 0 | FR10: 0 | FY10: 3 | FZ10: 0 | GA10: 0 | GB10: 0 | GC10: 0 | GD10: 0 | GE10: 0 | GF10: 0 | GG10: 0 | GH10: 0 | GI10: 0 | GJ10: 0 | GK10: 0 | GL10: 0 | GM10: 0 | GN10: 0 | GU10: 3 | GV10: 0 | GW10: 0 | GX10: 0 | GY10: 0 | GZ10: 0 | HA10: 0 | HB10: 0 | HC10: 0 | HD10: 0 | HE10: 0 | HF10: 0 | HG10: 0 | HH10: 0 | HI10: 0 | HJ10: 0
C12: Reorder | D12: 1 | E12: 2 | F12: 3 | G12: 4 | H12: 5 | I12: 6 | J12: 7 | K12: 8 | L12: 9 | M12: 10 | N12: 11 | O12: 12 | P12: 13 | Q12: 14 | R12: 15 | AA12: Reorder | AB12: 1 | AC12: 2 | AD12: 3 | AE12: 4 | AF12: 5 | AG12: 6 | AH12: 7 | AI12: 8 | AJ12: 9 | AK12: 10 | AL12: 11 | AM12: 12 | AN12: 13 | AO12: 14 | AP12: 15 | AW12: Reorder | AX12: 1 | AY12: 2 | AZ12: 3 | BA12: 4 | BB12: 5 | BC12: 6 | BD12: 7 | BE12: 8 | BF12: 9 | BG12: 10 | BH12: 11 | BI12: 12 | BJ12: 13 | BK12: 14 | BL12: 15 | BS12: Reorder | BT12: 1 | BU12: 2 | BV12: 3 | BW12: 4 | BX12: 5 | BY12: 6 | BZ12: 7 | CA12: 8 | CB12: 9 | CC12: 10 | CD12: 11 | CE12: 12 | CF12: 13 | CG12: 14 | CH12: 15 | CO12: Reorder | CP12: 1 | CQ12: 2 | CR12: 3 | CS12: 4 | CT12: 5 | CU12: 6 | CV12: 7 | CW12: 8 | CX12: 9 | CY12: 10 | CZ12: 11 | DA12: 12 | DB12: 13 | DC12: 14 | DD12: 15 | DK12: Reorder | DL12: 1 | DM12: 2 | DN12: 3 | DO12: 4 | DP12: 5 | DQ12: 6 | DR12: 7 | DS12: 8 | DT12: 9 | DU12: 10 | DV12: 11 | DW12: 12 | DX12: 13 | DY12: 14 | DZ12: 15 | EG12: Reorder | EH12: 1 | EI12: 2 | EJ12: 3 | EK12: 4 | EL12: 5 | EM12: 6 | EN12: 7 | EO12: 8 | EP12: 9 | EQ12: 10 | ER12: 11 | ES12: 12 | ET12: 13 | EU12: 14 | EV12: 15 | FC12: Reorder | FD12: 1 | FE12: 2 | FF12: 3 | FG12: 4 | FH12: 5 | FI12: 6 | FJ12: 7 | FK12: 8 | FL12: 9 | FM12: 10 | FN12: 11 | FO12: 12 | FP12: 13 | FQ12: 14 | FR12: 15 | FY12: Reorder | FZ12: 1 | GA12: 2 | GB12: 3 | GC12: 4 | GD12: 5 | GE12: 6 | GF12: 7 | GG12: 8 | GH12: 9 | GI12: 10 | GJ12: 11 | GK12: 12 | GL12: 13 | GM12: 14 | GN12: 15 | GU12: Reorder | GV12: 1 | GW12: 2 | GX12: 3 | GY12: 4 | GZ12: 5 | HA12: 6 | HB12: 7 | HC12: 8 | HD12: 9 | HE12: 10 | HF12: 11 | HG12: 12 | HH12: 13 | HI12: 14 | HJ12: 15
C13: 1 | D13: =Suppliers_stock_balance!D212 | E13: =Suppliers_stock_balance!E212 | F13: =Suppliers_stock_balance!F212 | G13: =Suppliers_stock_balance!G212 | H13: =Suppliers_stock_balance!H212 | I13: =Suppliers_stock_balance!I212 | J13: =Suppliers_stock_balance!J212 | K13: =Suppliers_stock_balance!K212 | ... R13: =Suppliers_stock_balance!R212 | T13: =SUM(D13:R15) | U13: 39562.042 | V13: =T13-U13 | AA13: 1 | AB13: 0 | AC13: 0 | AD13: 0 | AE13: 0 | AF13: 1168.693 | AG13: 1817.2927 | AH13: 0 | AI13: 2446.7585 | AJ13: 1635.9004 | AK13: 0 | AL13: 0 | AM13: 0 | AN13: 1216.203 | AO13: 1558.7788 | AP13: 3006.2428 | AW13: 1 | AX13: 0 | AY13: 0 | AZ13: 0 | BA13: 0 | BB13: 1168.693 | BC13: 1817.2927 | BD13: 0 | BE13: 2446.7585 | BF13: 1635.9004 | BG13: 0 | BH13: 0 | BI13: 0 | BJ13: 1216.203 | BK13: 1558.7788 | BL13: 3005.2428 | BS13: 1 | BT13: 0 | BU13: 0 | BV13: 0 | BW13: 0 | BX13: 1222.693 | BY13: 1852.2927 | BZ13: 0 | CA13: 2498.7585 | CB13: 1677.9004 | CC13: 0 | CD13: 0 | CE13: 0 | CF13: 1252.203 | CG13: 1592.7788 | CH13: 3070.2428 | CO13: 1 | CP13: 0 | CQ13: 0 | CR13: 0 | CS13: 0 | CT13: 1168.693 | CU13: 1817.2927 | CV13: 0 | CW13: 2446.7585 | CX13: 1635.9004 | CY13: 0 | CZ13: 0 | DA13: 0 | DB13: 1216.203 | DC13: 1558.7788 | DD13: 3005.2428 | DK13: 1 | DL13: 0 | DM13: 0 | DN13: 0 | DO13: 0 | DP13: 1168.693 | DQ13: 1817.2927 | DR13: 0 | DS13: 2446.7585 | DT13: 1635.9004 | DU13: 0 | DV13: 0 | DW13: 0 | DX13: 1216.203 | DY13: 1558.7788 | DZ13: 3005.2428 | EG13: 1 | EH13: 0 | EI13: 0 | EJ13: 0 | EK13: 0 | EL13: 1222.693 | EM13: 1852.2927 | EN13: 0 | EO13: 2498.7585 | EP13: 1677.9004 | EQ13: 0 | ER13: 0 | ES13: 0 | ET13: 1252.203 | EU13: 1592.7788 | EV13: 3070.2428 | FC13: 1 | FD13: 0 | FE13: 0 | FF13: 0 | FG13: 0 | FH13: 1168.693 | FI13: 1817.2927 | FJ13: 0 | FK13: 2446.7585 | FL13: 1635.9004 | FM13: 0 | FN13: 0 | FO13: 0 | FP13: 1216.203 | FQ13: 1558.7788 | FR13: 3005.2428 | FY13: 1 | FZ13: 0 | GA13: 0 | GB13: 0 | GC13: 0 | GD13: 1168.693 | GE13: 1817.2927 | GF13: 0 | GG13: 2446.7585 | GH13: 1635.9004 | GI13: 0 | GJ13: 0 | GK13: 0 | GL13: 1216.203 | GM13: 1558.7788 | GN13: 3005.2428 | GU13: 1 | GV13: 0 | GW13: 0 | GX13: 0 | GY13: 0 | GZ13: 1222.693 | HA13: 1852.2927 | HB13: 0 | HC13: 2498.7585 | HD13: 1677.9004 | HE13: 0 | HF13: 0 | HG13: 0 | HH13: 1252.203 | HI13: 1592.7788 | HJ13: 3070.2428
C14: 2 | D14: =Suppliers_stock_balance!D213 | E14: =Suppliers_stock_balance!E213 | F14: =Suppliers_stock_balance!F213 | G14: =Suppliers_stock_balance!G213 | H14: =Suppliers_stock_balance!H213 | I14: =Suppliers_stock_balance!I213 | J14: =Suppliers_stock_balance!J213 | K14: =Suppliers_stock_balance!K213 | ... R14: =Suppliers_stock_balance!R213 | AA14: 2 | AB14: 1262.2397 | AC14: 1303.4396 | AD14: 0 | AE14: 0 | AF14: 0 | AG14: 1632.304 | AH14: 0 | AI14: 0 | AJ14: 0 | AK14: 1215.6016 | AL14: 0 | AM14: 1583.4977 | AN14: 1579.2148 | AO14: 1508.936 | AP14: 1603.2428 | AW14: 2 | AX14: 1262.2397 | AY14: 1303.4396 | AZ14: 0 | BA14: 0 | BB14: 0 | BC14: 1632.304 | BD14: 0 | BE14: 0 | BF14: 0 | BG14: 1215.6016 | BH14: 0 | BI14: 1583.4977 | BJ14: 1579.2148 | BK14: 1508.936 | BL14: 1603.2428 | BS14: 2 | BT14: 1302.2397 | BU14: 1342.4396 | BV14: 0 | BW14: 0 | BX14: 0 | BY14: 1685.304 | BZ14: 0 | CA14: 0 | CB14: 0 | CC14: 1248.6016 | CD14: 0 | CE14: 1631.4977 | CF14: 1623.2148 | CG14: 1569.936 | CH14: 1653.2428 | CO14: 2 | CP14: 1262.2397 | CQ14: 1303.4396 | CR14: 0 | CS14: 0 | CT14: 0 | CU14: 1632.304 | CV14: 0 | CW14: 0 | CX14: 0 | CY14: 1215.6016 | CZ14: 0 | DA14: 1583.4977 | DB14: 1579.2148 | DC14: 1508.936 | DD14: 1603.2428 | DK14: 2 | DL14: 1262.2397 | DM14: 1303.4396 | DN14: 0 | DO14: 0 | DP14: 0 | DQ14: 1632.304 | DR14: 0 | DS14: 0 | DT14: 0 | DU14: 1215.6016 | DV14: 0 | DW14: 1583.4977 | DX14: 1579.2148 | DY14: 1508.936 | DZ14: 1603.2428 | EG14: 2 | EH14: 1302.2397 | EI14: 1342.4396 | EJ14: 0 | EK14: 0 | EL14: 0 | EM14: 1685.304 | EN14: 0 | EO14: 0 | EP14: 0 | EQ14: 1248.6016 | ER14: 0 | ES14: 1631.4977 | ET14: 1623.2148 | EU14: 1569.936 | EV14: 1653.2428 | FC14: 2 | FD14: 1262.2397 | FE14: 1303.4396 | FF14: 0 | FG14: 0 | FH14: 0 | FI14: 1632.304 | FJ14: 0 | FK14: 0 | FL14: 0 | FM14: 1215.6016 | FN14: 0 | FO14: 1583.4977 | FP14: 1579.2148 | FQ14: 1508.936 | FR14: 1603.2428 | FY14: 2 | FZ14: 1262.2397 | GA14: 1303.4396 | GB14: 0 | GC14: 0 | GD14: 0 | GE14: 1632.304 | GF14: 0 | GG14: 0 | GH14: 0 | GI14: 1215.6016 | GJ14: 0 | GK14: 1583.4977 | GL14: 1579.2148 | GM14: 1508.936 | GN14: 1603.2428 | GU14: 2 | GV14: 1302.2397 | GW14: 1342.4396 | GX14: 0 | GY14: 0 | GZ14: 0 | HA14: 1685.304 | HB14: 0 | HC14: 0 | HD14: 0 | HE14: 1248.6016 | HF14: 0 | HG14: 1631.4977 | HH14: 1623.2148 | HI14: 1569.936 | HJ14: 1653.2428
C15: 3 | D15: =Suppliers_stock_balance!D214 | E15: =Suppliers_stock_balance!E214 | F15: =Suppliers_stock_balance!F214 | G15: =Suppliers_stock_balance!G214 | H15: =Suppliers_stock_balance!H214 | I15: =Suppliers_stock_balance!I214 | J15: =Suppliers_stock_balance!J214 | K15: =Suppliers_stock_balance!K214 | ... R15: =Suppliers_stock_balance!R214 | AA15: 3 | AB15: 3540.7346 | AC15: 0 | AD15: 0 | AE15: 1883.1626 | AF15: 0 | AG15: 4031.312 | AH15: 2527.3066 | AI15: 0 | AJ15: 0 | AK15: 0 | AL15: 1655.4375 | AM15: 0 | AN15: 0 | AO15: 0 | AP15: 1385.7436 | AW15: 3 | AX15: 3540.7346 | AY15: 0 | AZ15: 0 | BA15: 1883.1626 | BB15: 0 | BC15: 4031.312 | BD15: 2527.3066 | BE15: 0 | BF15: 0 | BG15: 0 | BH15: 1655.4375 | BI15: 0 | BJ15: 0 | BK15: 0 | BL15: 1385.7436 | BS15: 3 | BT15: 3602.7346 | BU15: 0 | BV15: 0 | BW15: 1941.1626 | BX15: 0 | BY15: 4093.312 | BZ15: 2568.3066 | CA15: 0 | CB15: 0 | CC15: 0 | CD15: 1690.4375 | CE15: 0 | CF15: 0 | CG15: 0 | CH15: 1429.7436 | CO15: 3 | CP15: 3540.7346 | CQ15: 0 | CR15: 0 | CS15: 1883.1626 | CT15: 0 | CU15: 4031.312 | CV15: 2527.3066 | CW15: 0 | CX15: 0 | CY15: 0 | CZ15: 1655.4375 | DA15: 0 | DB15: 0 | DC15: 0 | DD15: 1385.7436 | DK15: 3 | DL15: 3540.7346 | DM15: 0 | DN15: 0 | DO15: 1883.1626 | DP15: 0 | DQ15: 4031.312 | DR15: 2527.3066 | DS15: 0 | DT15: 0 | DU15: 0 | DV15: 1655.4375 | DW15: 0 | DX15: 0 | DY15: 0 | DZ15: 1385.7436 | EG15: 3 | EH15: 3602.7346 | EI15: 0 | EJ15: 0 | EK15: 1941.1626 | EL15: 0 | EM15: 4093.312 | EN15: 2568.3066 | EO15: 0 | EP15: 0 | EQ15: 0 | ER15: 1690.4375 | ES15: 0 | ET15: 0 | EU15: 0 | EV15: 1429.7436 | FC15: 3 | FD15: 3540.7346 | FE15: 0 | FF15: 0 | FG15: 1883.1626 | FH15: 0 | FI15: 4031.312 | FJ15: 2527.3066 | FK15: 0 | FL15: 0 | FM15: 0 | FN15: 1655.4375 | FO15: 0 | FP15: 0 | FQ15: 0 | FR15: 1385.7436 | FY15: 3 | FZ15: 3540.7346 | GA15: 0 | GB15: 0 | GC15: 1883.1626 | GD15: 0 | GE15: 4031.312 | GF15: 2527.3066 | GG15: 0 | GH15: 0 | GI15: 0 | GJ15: 1655.4375 | GK15: 0 | GL15: 0 | GM15: 0 | GN15: 1385.7436 | GU15: 3 | GV15: 3602.7346 | GW15: 0 | GX15: 0 | GY15: 1941.1626 | GZ15: 0 | HA15: 4093.312 | HB15: 2568.3066 | HC15: 0 | HD15: 0 | HE15: 0 | HF15: 1690.4375 | HG15: 0 | HH15: 0 | HI15: 0 | HJ15: 1429.7436
C17: Var(Var(d)) | D17: 1 | E17: 2 | F17: 3 | G17: 4 | H17: 5 | I17: 6 | J17: 7 | K17: 8 | L17: 9 | M17: 10 | N17: 11 | O17: 12 | P17: 13 | Q17: 14 | R17: 15 | AA17: Var(Var(d)) | AB17: 1 | AC17: 2 | AD17: 3 | AE17: 4 | AF17: 5 | AG17: 6 | AH17: 7 | AI17: 8 | AJ17: 9 | AK17: 10 | AL17: 11 | AM17: 12 | AN17: 13 | AO17: 14 | AP17: 15 | AW17: Var(Var(d)) | AX17: 1 | AY17: 2 | AZ17: 3 | BA17: 4 | BB17: 5 | BC17: 6 | BD17: 7 | BE17: 8 | BF17: 9 | BG17: 10 | BH17: 11 | BI17: 12 | BJ17: 13 | BK17: 14 | BL17: 15 | BS17: Var(Var(d)) | BT17: 1 | BU17: 2 | BV17: 3 | BW17: 4 | BX17: 5 | BY17: 6 | BZ17: 7 | CA17: 8 | CB17: 9 | CC17: 10 | CD17: 11 | CE17: 12 | CF17: 13 | CG17: 14 | CH17: 15 | CO17: Var(Var(d)) | CP17: 1 | CQ17: 2 | CR17: 3 | CS17: 4 | CT17: 5 | CU17: 6 | CV17: 7 | CW17: 8 | CX17: 9 | CY17: 10 | CZ17: 11 | DA17: 12 | DB17: 13 | DC17: 14 | DD17: 15 | DK17: Var(Var(d)) | DL17: 1 | DM17: 2 | DN17: 3 | DO17: 4 | DP17: 5 | DQ17: 6 | DR17: 7 | DS17: 8 | DT17: 9 | DU17: 10 | DV17: 11 | DW17: 12 | DX17: 13 | DY17: 14 | DZ17: 15 | EG17: Var(Var(d)) | EH17: 1 | EI17: 2 | EJ17: 3 | EK17: 4 | EL17: 5 | EM17: 6 | EN17: 7 | EO17: 8 | EP17: 9 | EQ17: 10 | ER17: 11 | ES17: 12 | ET17: 13 | EU17: 14 | EV17: 15 | FC17: Var(Var(d)) | FD17: 1 | FE17: 2 | FF17: 3 | FG17: 4 | FH17: 5 | FI17: 6 | FJ17: 7 | FK17: 8 | FL17: 9 | FM17: 10 | FN17: 11 | FO17: 12 | FP17: 13 | FQ17: 14 | FR17: 15 | FY17: Var(Var(d)) | FZ17: 1 | GA17: 2 | GB17: 3 | GC17: 4 | GD17: 5 | GE17: 6 | GF17: 7 | GG17: 8 | GH17: 9 | GI17: 10 | GJ17: 11 | GK17: 12 | GL17: 13 | GM17: 14 | GN17: 15 | GU17: Var(Var(d)) | GV17: 1 | GW17: 2 | GX17: 3 | GY17: 4 | GZ17: 5 | HA17: 6 | HB17: 7 | HC17: 8 | HD17: 9 | HE17: 10 | HF17: 11 | HG17: 12 | HH17: 13 | HI17: 14 | HJ17: 15
